Workbook

Sheet Output
B2: 10 LOWER SPADINA CONDOS — RENTAL COMP SUMMARY (Condos view) | G2: Unit Mix Adjusted
B3: Building | C3: First Occupancy | D3: Avg.Lease Date | E3: Vacancy | F3: Transaction Count | G3: Avg Suite Size | H3: Adj. Avg. Rent | I3: Avg. Net Rent PSF
B5: Lower Spadina / CityPlace Waterfront
B6: Concord Canada House | C6: ='Building Summary'!E4 | D6: =IFERROR(AVERAGEIFS('RD Condos'!$J:$J,'RD Condos'!$K:$K,$B6,'RD Condos'!$A:$A,1),"") | F6: ='Building Summary'!J4 | G6: ='Building Summary'!K4 | H6: =IFERROR(AVERAGEIFS('RD Condos'!$D:$D,'RD Condos'!$K:$K,$B6,'RD Condos'!$A:$A,1),"") | I6: =IFERROR(AVERAGEIFS('RD Condos'!$F:$F,'RD Condos'!$K:$K,$B6,'RD Condos'!$A:$A,1),"")
B7: Nobu Residences | C7: ='Building Summary'!E5 | D7: =IFERROR(AVERAGEIFS('RD Condos'!$J:$J,'RD Condos'!$K:$K,$B7,'RD Condos'!$A:$A,1),"") | F7: ='Building Summary'!J5 | G7: ='Building Summary'!K5 | H7: =IFERROR(AVERAGEIFS('RD Condos'!$D:$D,'RD Condos'!$K:$K,$B7,'RD Condos'!$A:$A,1),"") | I7: =IFERROR(AVERAGEIFS('RD Condos'!$F:$F,'RD Condos'!$K:$K,$B7,'RD Condos'!$A:$A,1),"")
B8: The Well | C8: ='Building Summary'!E6 | D8: =IFERROR(AVERAGEIFS('RD Condos'!$J:$J,'RD Condos'!$K:$K,$B8,'RD Condos'!$A:$A,1),"") | F8: ='Building Summary'!J6 | G8: ='Building Summary'!K6 | H8: =IFERROR(AVERAGEIFS('RD Condos'!$D:$D,'RD Condos'!$K:$K,$B8,'RD Condos'!$A:$A,1),"") | I8: =IFERROR(AVERAGEIFS('RD Condos'!$F:$F,'RD Condos'!$K:$K,$B8,'RD Condos'!$A:$A,1),"")
B9: Ten York | C9: ='Building Summary'!E7 | D9: =IFERROR(AVERAGEIFS('RD Condos'!$J:$J,'RD Condos'!$K:$K,$B9,'RD Condos'!$A:$A,1),"") | F9: ='Building Summary'!J7 | G9: ='Building Summary'!K7 | H9: =IFERROR(AVERAGEIFS('RD Condos'!$D:$D,'RD Condos'!$K:$K,$B9,'RD Condos'!$A:$A,1),"") | I9: =IFERROR(AVERAGEIFS('RD Condos'!$F:$F,'RD Condos'!$K:$K,$B9,'RD Condos'!$A:$A,1),"")
B10: Forward Condos | C10: ='Building Summary'!E8 | D10: =IFERROR(AVERAGEIFS('RD Condos'!$J:$J,'RD Condos'!$K:$K,$B10,'RD Condos'!$A:$A,1),"") | F10: ='Building Summary'!J8 | G10: ='Building Summary'!K8 | H10: =IFERROR(AVERAGEIFS('RD Condos'!$D:$D,'RD Condos'!$K:$K,$B10,'RD Condos'!$A:$A,1),"") | I10: =IFERROR(AVERAGEIFS('RD Condos'!$F:$F,'RD Condos'!$K:$K,$B10,'RD Condos'!$A:$A,1),"")
B11: Quartz/Spectra | C11: ='Building Summary'!E9 | D11: =IFERROR(AVERAGEIFS('RD Condos'!$J:$J,'RD Condos'!$K:$K,$B11,'RD Condos'!$A:$A,1),"") | F11: ='Building Summary'!J9 | G11: ='Building Summary'!K9 | H11: =IFERROR(AVERAGEIFS('RD Condos'!$D:$D,'RD Condos'!$K:$K,$B11,'RD Condos'!$A:$A,1),"") | I11: =IFERROR(AVERAGEIFS('RD Condos'!$F:$F,'RD Condos'!$K:$K,$B11,'RD Condos'!$A:$A,1),"")
B12: Library District | C12: ='Building Summary'!E10 | D12: =IFERROR(AVERAGEIFS('RD Condos'!$J:$J,'RD Condos'!$K:$K,$B12,'RD Condos'!$A:$A,1),"") | F12: ='Building Summary'!J10 | G12: ='Building Summary'!K10 | H12: =IFERROR(AVERAGEIFS('RD Condos'!$D:$D,'RD Condos'!$K:$K,$B12,'RD Condos'!$A:$A,1),"") | I12: =IFERROR(AVERAGEIFS('RD Condos'!$F:$F,'RD Condos'!$K:$K,$B12,'RD Condos'!$A:$A,1),"")
B13: N1 | N2 - CityPlace | C13: ='Building Summary'!E11 | D13: =IFERROR(AVERAGEIFS('RD Condos'!$J:$J,'RD Condos'!$K:$K,$B13,'RD Condos'!$A:$A,1),"") | F13: ='Building Summary'!J11 | G13: ='Building Summary'!K11 | H13: =IFERROR(AVERAGEIFS('RD Condos'!$D:$D,'RD Condos'!$K:$K,$B13,'RD Condos'!$A:$A,1),"") | I13: =IFERROR(AVERAGEIFS('RD Condos'!$F:$F,'RD Condos'!$K:$K,$B13,'RD Condos'!$A:$A,1),"")
B14: Aqua | C14: ='Building Summary'!E12 | D14: =IFERROR(AVERAGEIFS('RD Condos'!$J:$J,'RD Condos'!$K:$K,$B14,'RD Condos'!$A:$A,1),"") | F14: ='Building Summary'!J12 | G14: ='Building Summary'!K12 | H14: =IFERROR(AVERAGEIFS('RD Condos'!$D:$D,'RD Condos'!$K:$K,$B14,'RD Condos'!$A:$A,1),"") | I14: =IFERROR(AVERAGEIFS('RD Condos'!$F:$F,'RD Condos'!$K:$K,$B14,'RD Condos'!$A:$A,1),"")
B15: Average | F15: =COUNTIFS('RD Condos'!$A:$A,1) | G15: =IFERROR(AVERAGEIFS('RD Condos'!$B:$B,'RD Condos'!$A:$A,1),"") | H15: =IFERROR(AVERAGEIFS('RD Condos'!$D:$D,'RD Condos'!$A:$A,1),"") | I15: =IFERROR(AVERAGEIFS('RD Condos'!$F:$F,'RD Condos'!$A:$A,1),"")
B16: PBR Premium | H16: =Data_Summary!C4 | I16: =Data_Summary!C4
B17: Implied Untrended Rent | G17: =G15 | H17: =IFERROR(H15*(1+H16),"") | I17: =IFERROR(I15*(1+I16),"")
B19: Subject Site (Untrended Rent) | G19: =G17 | H19: =H17 | I19: =I17
B21: Other Excluded
B22: User selected all 9 shortlisted buildings (2026-06-16) — no shortlisted-but-rejected comps pulled.
B23: Evaluated & excluded (different micro-market / farther): Sugar Wharf (95-85 Lake Shore E, 2023), Lighthouse & Aquabella/Aqualuna (East Bayfront, ~2.5km), Bisha / King Blue / Theatre Park (Entertainment District). Older CityPlace redundant with floor: Optima, Apex, Montage, Neo, Luna, Parade, West One, Harbour View I/III.
B25: Weighted Average (all comps) | F25: =COUNTIFS('RD Condos'!$A:$A,1) | G25: =IFERROR(AVERAGEIFS('RD Condos'!$B:$B,'RD Condos'!$A:$A,1),"") | H25: =IFERROR(AVERAGEIFS('RD Condos'!$D:$D,'RD Condos'!$A:$A,1),"") | I25: =IFERROR(AVERAGEIFS('RD Condos'!$F:$F,'RD Condos'!$A:$A,1),"")
B26: PBR Premium | H26: =Data_Summary!C4 | I26: =Data_Summary!C4
B27: Implied Untrended Rent | H27: =IFERROR(H25*(1+H26),"") | I27: =IFERROR(I25*(1+I26),"") | L27: 1-Bedroom Units | P27: 1-Bedroom + Den Units | T27: 2-Bedroom Units | X27: 3-Bedroom Units
K28: Building | L28: Transaction Count | M28: Avg. Suite Size | N28: Adj. Avg. Rent | O28: Avg. Net Rent PSF | P28: Transaction Count | Q28: Avg. Suite Size | R28: Adj. Avg. Rent | S28: Avg. Net Rent PSF | T28: Transaction Count | U28: Avg. Suite Size | V28: Adj. Avg. Rent | W28: Avg. Net Rent PSF | X28: Transaction Count | Y28: Avg. Suite Size | Z28: Adj. Avg. Rent | AA28: Avg. Net Rent PSF
K29: Concord Canada House | L29: =COUNTIFS('RD Condos'!$Q:$Q,"1",'RD Condos'!$A:$A,1,'RD Condos'!$K:$K,"Concord Canada House") | M29: =IFERROR(AVERAGEIFS('RD Condos'!$B:$B,'RD Condos'!$Q:$Q,"1",'RD Condos'!$A:$A,1,'RD Condos'!$K:$K,"Concord Canada House"),"") | N29: =IFERROR(AVERAGEIFS('RD Condos'!$D:$D,'RD Condos'!$Q:$Q,"1",'RD Condos'!$A:$A,1,'RD Condos'!$K:$K,"Concord Canada House"),"") | O29: =IFERROR(AVERAGEIFS('RD Condos'!$F:$F,'RD Condos'!$Q:$Q,"1",'RD Condos'!$A:$A,1,'RD Condos'!$K:$K,"Concord Canada House"),"") | P29: =COUNTIFS('RD Condos'!$Q:$Q,"1+1",'RD Condos'!$A:$A,1,'RD Condos'!$K:$K,"Concord Canada House") | Q29: =IFERROR(AVERAGEIFS('RD Condos'!$B:$B,'RD Condos'!$Q:$Q,"1+1",'RD Condos'!$A:$A,1,'RD Condos'!$K:$K,"Concord Canada House"),"") | R29: =IFERROR(AVERAGEIFS('RD Condos'!$D:$D,'RD Condos'!$Q:$Q,"1+1",'RD Condos'!$A:$A,1,'RD Condos'!$K:$K,"Concord Canada House"),"") | S29: =IFERROR(AVERAGEIFS('RD Condos'!$F:$F,'RD Condos'!$Q:$Q,"1+1",'RD Condos'!$A:$A,1,'RD Condos'!$K:$K,"Concord Canada House"),"") | T29: =COUNTIFS('RD Condos'!$H:$H,"2",'RD Condos'!$A:$A,1,'RD Condos'!$K:$K,"Concord Canada House") | U29: =IFERROR(AVERAGEIFS('RD Condos'!$B:$B,'RD Condos'!$H:$H,"2",'RD Condos'!$A:$A,1,'RD Condos'!$K:$K,"Concord Canada House"),"") | V29: =IFERROR(AVERAGEIFS('RD Condos'!$D:$D,'RD Condos'!$H:$H,"2",'RD Condos'!$A:$A,1,'RD Condos'!$K:$K,"Concord Canada House"),"") | W29: =IFERROR(AVERAGEIFS('RD Condos'!$F:$F,'RD Condos'!$H:$H,"2",'RD Condos'!$A:$A,1,'RD Condos'!$K:$K,"Concord Canada House"),"") | X29: =COUNTIFS('RD Condos'!$H:$H,"3",'RD Condos'!$A:$A,1,'RD Condos'!$K:$K,"Concord Canada House") | Y29: =IFERROR(AVERAGEIFS('RD Condos'!$B:$B,'RD Condos'!$H:$H,"3",'RD Condos'!$A:$A,1,'RD Condos'!$K:$K,"Concord Canada House"),"") | Z29: =IFERROR(AVERAGEIFS('RD Condos'!$D:$D,'RD Condos'!$H:$H,"3",'RD Condos'!$A:$A,1,'RD Condos'!$K:$K,"Concord Canada House"),"") | AA29: =IFERROR(AVERAGEIFS('RD Condos'!$F:$F,'RD Condos'!$H:$H,"3",'RD Condos'!$A:$A,1,'RD Condos'!$K:$K,"Concord Canada House"),"")
B30: RECOMMENDATION (mirror of Subject & Conclusion) | K30: Nobu Residences | L30: =COUNTIFS('RD Condos'!$Q:$Q,"1",'RD Condos'!$A:$A,1,'RD Condos'!$K:$K,"Nobu Residences") | M30: =IFERROR(AVERAGEIFS('RD Condos'!$B:$B,'RD Condos'!$Q:$Q,"1",'RD Condos'!$A:$A,1,'RD Condos'!$K:$K,"Nobu Residences"),"") | N30: =IFERROR(AVERAGEIFS('RD Condos'!$D:$D,'RD Condos'!$Q:$Q,"1",'RD Condos'!$A:$A,1,'RD Condos'!$K:$K,"Nobu Residences"),"") | O30: =IFERROR(AVERAGEIFS('RD Condos'!$F:$F,'RD Condos'!$Q:$Q,"1",'RD Condos'!$A:$A,1,'RD Condos'!$K:$K,"Nobu Residences"),"") | P30: =COUNTIFS('RD Condos'!$Q:$Q,"1+1",'RD Condos'!$A:$A,1,'RD Condos'!$K:$K,"Nobu Residences") | Q30: =IFERROR(AVERAGEIFS('RD Condos'!$B:$B,'RD Condos'!$Q:$Q,"1+1",'RD Condos'!$A:$A,1,'RD Condos'!$K:$K,"Nobu Residences"),"") | R30: =IFERROR(AVERAGEIFS('RD Condos'!$D:$D,'RD Condos'!$Q:$Q,"1+1",'RD Condos'!$A:$A,1,'RD Condos'!$K:$K,"Nobu Residences"),"") | S30: =IFERROR(AVERAGEIFS('RD Condos'!$F:$F,'RD Condos'!$Q:$Q,"1+1",'RD Condos'!$A:$A,1,'RD Condos'!$K:$K,"Nobu Residences"),"") | T30: =COUNTIFS('RD Condos'!$H:$H,"2",'RD Condos'!$A:$A,1,'RD Condos'!$K:$K,"Nobu Residences") | U30: =IFERROR(AVERAGEIFS('RD Condos'!$B:$B,'RD Condos'!$H:$H,"2",'RD Condos'!$A:$A,1,'RD Condos'!$K:$K,"Nobu Residences"),"") | V30: =IFERROR(AVERAGEIFS('RD Condos'!$D:$D,'RD Condos'!$H:$H,"2",'RD Condos'!$A:$A,1,'RD Condos'!$K:$K,"Nobu Residences"),"") | W30: =IFERROR(AVERAGEIFS('RD Condos'!$F:$F,'RD Condos'!$H:$H,"2",'RD Condos'!$A:$A,1,'RD Condos'!$K:$K,"Nobu Residences"),"") | X30: =COUNTIFS('RD Condos'!$H:$H,"3",'RD Condos'!$A:$A,1,'RD Condos'!$K:$K,"Nobu Residences") | Y30: =IFERROR(AVERAGEIFS('RD Condos'!$B:$B,'RD Condos'!$H:$H,"3",'RD Condos'!$A:$A,1,'RD Condos'!$K:$K,"Nobu Residences"),"") | Z30: =IFERROR(AVERAGEIFS('RD Condos'!$D:$D,'RD Condos'!$H:$H,"3",'RD Condos'!$A:$A,1,'RD Condos'!$K:$K,"Nobu Residences"),"") | AA30: =IFERROR(AVERAGEIFS('RD Condos'!$F:$F,'RD Condos'!$H:$H,"3",'RD Condos'!$A:$A,1,'RD Condos'!$K:$K,"Nobu Residences"),"")
B31: Recommended subject $/SF | D31: =Data_Summary!$C$34 | K31: The Well | L31: =COUNTIFS('RD Condos'!$Q:$Q,"1",'RD Condos'!$A:$A,1,'RD Condos'!$K:$K,"The Well") | M31: =IFERROR(AVERAGEIFS('RD Condos'!$B:$B,'RD Condos'!$Q:$Q,"1",'RD Condos'!$A:$A,1,'RD Condos'!$K:$K,"The Well"),"") | N31: =IFERROR(AVERAGEIFS('RD Condos'!$D:$D,'RD Condos'!$Q:$Q,"1",'RD Condos'!$A:$A,1,'RD Condos'!$K:$K,"The Well"),"") | O31: =IFERROR(AVERAGEIFS('RD Condos'!$F:$F,'RD Condos'!$Q:$Q,"1",'RD Condos'!$A:$A,1,'RD Condos'!$K:$K,"The Well"),"") | P31: =COUNTIFS('RD Condos'!$Q:$Q,"1+1",'RD Condos'!$A:$A,1,'RD Condos'!$K:$K,"The Well") | Q31: =IFERROR(AVERAGEIFS('RD Condos'!$B:$B,'RD Condos'!$Q:$Q,"1+1",'RD Condos'!$A:$A,1,'RD Condos'!$K:$K,"The Well"),"") | R31: =IFERROR(AVERAGEIFS('RD Condos'!$D:$D,'RD Condos'!$Q:$Q,"1+1",'RD Condos'!$A:$A,1,'RD Condos'!$K:$K,"The Well"),"") | S31: =IFERROR(AVERAGEIFS('RD Condos'!$F:$F,'RD Condos'!$Q:$Q,"1+1",'RD Condos'!$A:$A,1,'RD Condos'!$K:$K,"The Well"),"") | T31: =COUNTIFS('RD Condos'!$H:$H,"2",'RD Condos'!$A:$A,1,'RD Condos'!$K:$K,"The Well") | U31: =IFERROR(AVERAGEIFS('RD Condos'!$B:$B,'RD Condos'!$H:$H,"2",'RD Condos'!$A:$A,1,'RD Condos'!$K:$K,"The Well"),"") | V31: =IFERROR(AVERAGEIFS('RD Condos'!$D:$D,'RD Condos'!$H:$H,"2",'RD Condos'!$A:$A,1,'RD Condos'!$K:$K,"The Well"),"") | W31: =IFERROR(AVERAGEIFS('RD Condos'!$F:$F,'RD Condos'!$H:$H,"2",'RD Condos'!$A:$A,1,'RD Condos'!$K:$K,"The Well"),"") | X31: =COUNTIFS('RD Condos'!$H:$H,"3",'RD Condos'!$A:$A,1,'RD Condos'!$K:$K,"The Well") | Y31: =IFERROR(AVERAGEIFS('RD Condos'!$B:$B,'RD Condos'!$H:$H,"3",'RD Condos'!$A:$A,1,'RD Condos'!$K:$K,"The Well"),"") | Z31: =IFERROR(AVERAGEIFS('RD Condos'!$D:$D,'RD Condos'!$H:$H,"3",'RD Condos'!$A:$A,1,'RD Condos'!$K:$K,"The Well"),"") | AA31: =IFERROR(AVERAGEIFS('RD Condos'!$F:$F,'RD Condos'!$H:$H,"3",'RD Condos'!$A:$A,1,'RD Condos'!$K:$K,"The Well"),"")
B32: Conservative (all-comp + premium) $/SF | D32: =Data_Summary!$C$35 | K32: Ten York | L32: =COUNTIFS('RD Condos'!$Q:$Q,"1",'RD Condos'!$A:$A,1,'RD Condos'!$K:$K,"Ten York") | M32: =IFERROR(AVERAGEIFS('RD Condos'!$B:$B,'RD Condos'!$Q:$Q,"1",'RD Condos'!$A:$A,1,'RD Condos'!$K:$K,"Ten York"),"") | N32: =IFERROR(AVERAGEIFS('RD Condos'!$D:$D,'RD Condos'!$Q:$Q,"1",'RD Condos'!$A:$A,1,'RD Condos'!$K:$K,"Ten York"),"") | O32: =IFERROR(AVERAGEIFS('RD Condos'!$F:$F,'RD Condos'!$Q:$Q,"1",'RD Condos'!$A:$A,1,'RD Condos'!$K:$K,"Ten York"),"") | P32: =COUNTIFS('RD Condos'!$Q:$Q,"1+1",'RD Condos'!$A:$A,1,'RD Condos'!$K:$K,"Ten York") | Q32: =IFERROR(AVERAGEIFS('RD Condos'!$B:$B,'RD Condos'!$Q:$Q,"1+1",'RD Condos'!$A:$A,1,'RD Condos'!$K:$K,"Ten York"),"") | R32: =IFERROR(AVERAGEIFS('RD Condos'!$D:$D,'RD Condos'!$Q:$Q,"1+1",'RD Condos'!$A:$A,1,'RD Condos'!$K:$K,"Ten York"),"") | S32: =IFERROR(AVERAGEIFS('RD Condos'!$F:$F,'RD Condos'!$Q:$Q,"1+1",'RD Condos'!$A:$A,1,'RD Condos'!$K:$K,"Ten York"),"") | T32: =COUNTIFS('RD Condos'!$H:$H,"2",'RD Condos'!$A:$A,1,'RD Condos'!$K:$K,"Ten York") | U32: =IFERROR(AVERAGEIFS('RD Condos'!$B:$B,'RD Condos'!$H:$H,"2",'RD Condos'!$A:$A,1,'RD Condos'!$K:$K,"Ten York"),"") | V32: =IFERROR(AVERAGEIFS('RD Condos'!$D:$D,'RD Condos'!$H:$H,"2",'RD Condos'!$A:$A,1,'RD Condos'!$K:$K,"Ten York"),"") | W32: =IFERROR(AVERAGEIFS('RD Condos'!$F:$F,'RD Condos'!$H:$H,"2",'RD Condos'!$A:$A,1,'RD Condos'!$K:$K,"Ten York"),"") | X32: =COUNTIFS('RD Condos'!$H:$H,"3",'RD Condos'!$A:$A,1,'RD Condos'!$K:$K,"Ten York") | Y32: =IFERROR(AVERAGEIFS('RD Condos'!$B:$B,'RD Condos'!$H:$H,"3",'RD Condos'!$A:$A,1,'RD Condos'!$K:$K,"Ten York"),"") | Z32: =IFERROR(AVERAGEIFS('RD Condos'!$D:$D,'RD Condos'!$H:$H,"3",'RD Condos'!$A:$A,1,'RD Condos'!$K:$K,"Ten York"),"") | AA32: =IFERROR(AVERAGEIFS('RD Condos'!$F:$F,'RD Condos'!$H:$H,"3",'RD Condos'!$A:$A,1,'RD Condos'!$K:$K,"Ten York"),"")
B33: Raw comp $/SF (Concord, no premium) | D33: =Data_Summary!$C$31 | K33: Forward Condos | L33: =COUNTIFS('RD Condos'!$Q:$Q,"1",'RD Condos'!$A:$A,1,'RD Condos'!$K:$K,"Forward Condos") | M33: =IFERROR(AVERAGEIFS('RD Condos'!$B:$B,'RD Condos'!$Q:$Q,"1",'RD Condos'!$A:$A,1,'RD Condos'!$K:$K,"Forward Condos"),"") | N33: =IFERROR(AVERAGEIFS('RD Condos'!$D:$D,'RD Condos'!$Q:$Q,"1",'RD Condos'!$A:$A,1,'RD Condos'!$K:$K,"Forward Condos"),"") | O33: =IFERROR(AVERAGEIFS('RD Condos'!$F:$F,'RD Condos'!$Q:$Q,"1",'RD Condos'!$A:$A,1,'RD Condos'!$K:$K,"Forward Condos"),"") | P33: =COUNTIFS('RD Condos'!$Q:$Q,"1+1",'RD Condos'!$A:$A,1,'RD Condos'!$K:$K,"Forward Condos") | Q33: =IFERROR(AVERAGEIFS('RD Condos'!$B:$B,'RD Condos'!$Q:$Q,"1+1",'RD Condos'!$A:$A,1,'RD Condos'!$K:$K,"Forward Condos"),"") | R33: =IFERROR(AVERAGEIFS('RD Condos'!$D:$D,'RD Condos'!$Q:$Q,"1+1",'RD Condos'!$A:$A,1,'RD Condos'!$K:$K,"Forward Condos"),"") | S33: =IFERROR(AVERAGEIFS('RD Condos'!$F:$F,'RD Condos'!$Q:$Q,"1+1",'RD Condos'!$A:$A,1,'RD Condos'!$K:$K,"Forward Condos"),"") | T33: =COUNTIFS('RD Condos'!$H:$H,"2",'RD Condos'!$A:$A,1,'RD Condos'!$K:$K,"Forward Condos") | U33: =IFERROR(AVERAGEIFS('RD Condos'!$B:$B,'RD Condos'!$H:$H,"2",'RD Condos'!$A:$A,1,'RD Condos'!$K:$K,"Forward Condos"),"") | V33: =IFERROR(AVERAGEIFS('RD Condos'!$D:$D,'RD Condos'!$H:$H,"2",'RD Condos'!$A:$A,1,'RD Condos'!$K:$K,"Forward Condos"),"") | W33: =IFERROR(AVERAGEIFS('RD Condos'!$F:$F,'RD Condos'!$H:$H,"2",'RD Condos'!$A:$A,1,'RD Condos'!$K:$K,"Forward Condos"),"") | X33: =COUNTIFS('RD Condos'!$H:$H,"3",'RD Condos'!$A:$A,1,'RD Condos'!$K:$K,"Forward Condos") | Y33: =IFERROR(AVERAGEIFS('RD Condos'!$B:$B,'RD Condos'!$H:$H,"3",'RD Condos'!$A:$A,1,'RD Condos'!$K:$K,"Forward Condos"),"") | Z33: =IFERROR(AVERAGEIFS('RD Condos'!$D:$D,'RD Condos'!$H:$H,"3",'RD Condos'!$A:$A,1,'RD Condos'!$K:$K,"Forward Condos"),"") | AA33: =IFERROR(AVERAGEIFS('RD Condos'!$F:$F,'RD Condos'!$H:$H,"3",'RD Condos'!$A:$A,1,'RD Condos'!$K:$K,"Forward Condos"),"")
B34: Plus — new-build / lease-up premium | D34: =Data_Summary!$C$4 | K34: Quartz/Spectra | L34: =COUNTIFS('RD Condos'!$Q:$Q,"1",'RD Condos'!$A:$A,1,'RD Condos'!$K:$K,"Quartz/Spectra") | M34: =IFERROR(AVERAGEIFS('RD Condos'!$B:$B,'RD Condos'!$Q:$Q,"1",'RD Condos'!$A:$A,1,'RD Condos'!$K:$K,"Quartz/Spectra"),"") | N34: =IFERROR(AVERAGEIFS('RD Condos'!$D:$D,'RD Condos'!$Q:$Q,"1",'RD Condos'!$A:$A,1,'RD Condos'!$K:$K,"Quartz/Spectra"),"") | O34: =IFERROR(AVERAGEIFS('RD Condos'!$F:$F,'RD Condos'!$Q:$Q,"1",'RD Condos'!$A:$A,1,'RD Condos'!$K:$K,"Quartz/Spectra"),"") | P34: =COUNTIFS('RD Condos'!$Q:$Q,"1+1",'RD Condos'!$A:$A,1,'RD Condos'!$K:$K,"Quartz/Spectra") | Q34: =IFERROR(AVERAGEIFS('RD Condos'!$B:$B,'RD Condos'!$Q:$Q,"1+1",'RD Condos'!$A:$A,1,'RD Condos'!$K:$K,"Quartz/Spectra"),"") | R34: =IFERROR(AVERAGEIFS('RD Condos'!$D:$D,'RD Condos'!$Q:$Q,"1+1",'RD Condos'!$A:$A,1,'RD Condos'!$K:$K,"Quartz/Spectra"),"") | S34: =IFERROR(AVERAGEIFS('RD Condos'!$F:$F,'RD Condos'!$Q:$Q,"1+1",'RD Condos'!$A:$A,1,'RD Condos'!$K:$K,"Quartz/Spectra"),"") | T34: =COUNTIFS('RD Condos'!$H:$H,"2",'RD Condos'!$A:$A,1,'RD Condos'!$K:$K,"Quartz/Spectra") | U34: =IFERROR(AVERAGEIFS('RD Condos'!$B:$B,'RD Condos'!$H:$H,"2",'RD Condos'!$A:$A,1,'RD Condos'!$K:$K,"Quartz/Spectra"),"") | V34: =IFERROR(AVERAGEIFS('RD Condos'!$D:$D,'RD Condos'!$H:$H,"2",'RD Condos'!$A:$A,1,'RD Condos'!$K:$K,"Quartz/Spectra"),"") | W34: =IFERROR(AVERAGEIFS('RD Condos'!$F:$F,'RD Condos'!$H:$H,"2",'RD Condos'!$A:$A,1,'RD Condos'!$K:$K,"Quartz/Spectra"),"") | X34: =COUNTIFS('RD Condos'!$H:$H,"3",'RD Condos'!$A:$A,1,'RD Condos'!$K:$K,"Quartz/Spectra") | Y34: =IFERROR(AVERAGEIFS('RD Condos'!$B:$B,'RD Condos'!$H:$H,"3",'RD Condos'!$A:$A,1,'RD Condos'!$K:$K,"Quartz/Spectra"),"") | Z34: =IFERROR(AVERAGEIFS('RD Condos'!$D:$D,'RD Condos'!$H:$H,"3",'RD Condos'!$A:$A,1,'RD Condos'!$K:$K,"Quartz/Spectra"),"") | AA34: =IFERROR(AVERAGEIFS('RD Condos'!$F:$F,'RD Condos'!$H:$H,"3",'RD Condos'!$A:$A,1,'RD Condos'!$K:$K,"Quartz/Spectra"),"")
K35: Library District | L35: =COUNTIFS('RD Condos'!$Q:$Q,"1",'RD Condos'!$A:$A,1,'RD Condos'!$K:$K,"Library District") | M35: =IFERROR(AVERAGEIFS('RD Condos'!$B:$B,'RD Condos'!$Q:$Q,"1",'RD Condos'!$A:$A,1,'RD Condos'!$K:$K,"Library District"),"") | N35: =IFERROR(AVERAGEIFS('RD Condos'!$D:$D,'RD Condos'!$Q:$Q,"1",'RD Condos'!$A:$A,1,'RD Condos'!$K:$K,"Library District"),"") | O35: =IFERROR(AVERAGEIFS('RD Condos'!$F:$F,'RD Condos'!$Q:$Q,"1",'RD Condos'!$A:$A,1,'RD Condos'!$K:$K,"Library District"),"") | P35: =COUNTIFS('RD Condos'!$Q:$Q,"1+1",'RD Condos'!$A:$A,1,'RD Condos'!$K:$K,"Library District") | Q35: =IFERROR(AVERAGEIFS('RD Condos'!$B:$B,'RD Condos'!$Q:$Q,"1+1",'RD Condos'!$A:$A,1,'RD Condos'!$K:$K,"Library District"),"") | R35: =IFERROR(AVERAGEIFS('RD Condos'!$D:$D,'RD Condos'!$Q:$Q,"1+1",'RD Condos'!$A:$A,1,'RD Condos'!$K:$K,"Library District"),"") | S35: =IFERROR(AVERAGEIFS('RD Condos'!$F:$F,'RD Condos'!$Q:$Q,"1+1",'RD Condos'!$A:$A,1,'RD Condos'!$K:$K,"Library District"),"") | T35: =COUNTIFS('RD Condos'!$H:$H,"2",'RD Condos'!$A:$A,1,'RD Condos'!$K:$K,"Library District") | U35: =IFERROR(AVERAGEIFS('RD Condos'!$B:$B,'RD Condos'!$H:$H,"2",'RD Condos'!$A:$A,1,'RD Condos'!$K:$K,"Library District"),"") | V35: =IFERROR(AVERAGEIFS('RD Condos'!$D:$D,'RD Condos'!$H:$H,"2",'RD Condos'!$A:$A,1,'RD Condos'!$K:$K,"Library District"),"") | W35: =IFERROR(AVERAGEIFS('RD Condos'!$F:$F,'RD Condos'!$H:$H,"2",'RD Condos'!$A:$A,1,'RD Condos'!$K:$K,"Library District"),"") | X35: =COUNTIFS('RD Condos'!$H:$H,"3",'RD Condos'!$A:$A,1,'RD Condos'!$K:$K,"Library District") | Y35: =IFERROR(AVERAGEIFS('RD Condos'!$B:$B,'RD Condos'!$H:$H,"3",'RD Condos'!$A:$A,1,'RD Condos'!$K:$K,"Library District"),"") | Z35: =IFERROR(AVERAGEIFS('RD Condos'!$D:$D,'RD Condos'!$H:$H,"3",'RD Condos'!$A:$A,1,'RD Condos'!$K:$K,"Library District"),"") | AA35: =IFERROR(AVERAGEIFS('RD Condos'!$F:$F,'RD Condos'!$H:$H,"3",'RD Condos'!$A:$A,1,'RD Condos'!$K:$K,"Library District"),"")
B36: Recommended monthly rent by suite type | K36: N1 | N2 - CityPlace | L36: =COUNTIFS('RD Condos'!$Q:$Q,"1",'RD Condos'!$A:$A,1,'RD Condos'!$K:$K,"N1 | N2 - CityPlace") | M36: =IFERROR(AVERAGEIFS('RD Condos'!$B:$B,'RD Condos'!$Q:$Q,"1",'RD Condos'!$A:$A,1,'RD Condos'!$K:$K,"N1 | N2 - CityPlace"),"") | N36: =IFERROR(AVERAGEIFS('RD Condos'!$D:$D,'RD Condos'!$Q:$Q,"1",'RD Condos'!$A:$A,1,'RD Condos'!$K:$K,"N1 | N2 - CityPlace"),"") | O36: =IFERROR(AVERAGEIFS('RD Condos'!$F:$F,'RD Condos'!$Q:$Q,"1",'RD Condos'!$A:$A,1,'RD Condos'!$K:$K,"N1 | N2 - CityPlace"),"") | P36: =COUNTIFS('RD Condos'!$Q:$Q,"1+1",'RD Condos'!$A:$A,1,'RD Condos'!$K:$K,"N1 | N2 - CityPlace") | Q36: =IFERROR(AVERAGEIFS('RD Condos'!$B:$B,'RD Condos'!$Q:$Q,"1+1",'RD Condos'!$A:$A,1,'RD Condos'!$K:$K,"N1 | N2 - CityPlace"),"") | R36: =IFERROR(AVERAGEIFS('RD Condos'!$D:$D,'RD Condos'!$Q:$Q,"1+1",'RD Condos'!$A:$A,1,'RD Condos'!$K:$K,"N1 | N2 - CityPlace"),"") | S36: =IFERROR(AVERAGEIFS('RD Condos'!$F:$F,'RD Condos'!$Q:$Q,"1+1",'RD Condos'!$A:$A,1,'RD Condos'!$K:$K,"N1 | N2 - CityPlace"),"") | T36: =COUNTIFS('RD Condos'!$H:$H,"2",'RD Condos'!$A:$A,1,'RD Condos'!$K:$K,"N1 | N2 - CityPlace") | U36: =IFERROR(AVERAGEIFS('RD Condos'!$B:$B,'RD Condos'!$H:$H,"2",'RD Condos'!$A:$A,1,'RD Condos'!$K:$K,"N1 | N2 - CityPlace"),"") | V36: =IFERROR(AVERAGEIFS('RD Condos'!$D:$D,'RD Condos'!$H:$H,"2",'RD Condos'!$A:$A,1,'RD Condos'!$K:$K,"N1 | N2 - CityPlace"),"") | W36: =IFERROR(AVERAGEIFS('RD Condos'!$F:$F,'RD Condos'!$H:$H,"2",'RD Condos'!$A:$A,1,'RD Condos'!$K:$K,"N1 | N2 - CityPlace"),"") | X36: =COUNTIFS('RD Condos'!$H:$H,"3",'RD Condos'!$A:$A,1,'RD Condos'!$K:$K,"N1 | N2 - CityPlace") | Y36: =IFERROR(AVERAGEIFS('RD Condos'!$B:$B,'RD Condos'!$H:$H,"3",'RD Condos'!$A:$A,1,'RD Condos'!$K:$K,"N1 | N2 - CityPlace"),"") | Z36: =IFERROR(AVERAGEIFS('RD Condos'!$D:$D,'RD Condos'!$H:$H,"3",'RD Condos'!$A:$A,1,'RD Condos'!$K:$K,"N1 | N2 - CityPlace"),"") | AA36: =IFERROR(AVERAGEIFS('RD Condos'!$F:$F,'RD Condos'!$H:$H,"3",'RD Condos'!$A:$A,1,'RD Condos'!$K:$K,"N1 | N2 - CityPlace"),"")
B37: Suite | C37: Avg SF | D37: Rec. Rent | K37: Aqua | L37: =COUNTIFS('RD Condos'!$Q:$Q,"1",'RD Condos'!$A:$A,1,'RD Condos'!$K:$K,"Aqua") | M37: =IFERROR(AVERAGEIFS('RD Condos'!$B:$B,'RD Condos'!$Q:$Q,"1",'RD Condos'!$A:$A,1,'RD Condos'!$K:$K,"Aqua"),"") | N37: =IFERROR(AVERAGEIFS('RD Condos'!$D:$D,'RD Condos'!$Q:$Q,"1",'RD Condos'!$A:$A,1,'RD Condos'!$K:$K,"Aqua"),"") | O37: =IFERROR(AVERAGEIFS('RD Condos'!$F:$F,'RD Condos'!$Q:$Q,"1",'RD Condos'!$A:$A,1,'RD Condos'!$K:$K,"Aqua"),"") | P37: =COUNTIFS('RD Condos'!$Q:$Q,"1+1",'RD Condos'!$A:$A,1,'RD Condos'!$K:$K,"Aqua") | Q37: =IFERROR(AVERAGEIFS('RD Condos'!$B:$B,'RD Condos'!$Q:$Q,"1+1",'RD Condos'!$A:$A,1,'RD Condos'!$K:$K,"Aqua"),"") | R37: =IFERROR(AVERAGEIFS('RD Condos'!$D:$D,'RD Condos'!$Q:$Q,"1+1",'RD Condos'!$A:$A,1,'RD Condos'!$K:$K,"Aqua"),"") | S37: =IFERROR(AVERAGEIFS('RD Condos'!$F:$F,'RD Condos'!$Q:$Q,"1+1",'RD Condos'!$A:$A,1,'RD Condos'!$K:$K,"Aqua"),"") | T37: =COUNTIFS('RD Condos'!$H:$H,"2",'RD Condos'!$A:$A,1,'RD Condos'!$K:$K,"Aqua") | U37: =IFERROR(AVERAGEIFS('RD Condos'!$B:$B,'RD Condos'!$H:$H,"2",'RD Condos'!$A:$A,1,'RD Condos'!$K:$K,"Aqua"),"") | V37: =IFERROR(AVERAGEIFS('RD Condos'!$D:$D,'RD Condos'!$H:$H,"2",'RD Condos'!$A:$A,1,'RD Condos'!$K:$K,"Aqua"),"") | W37: =IFERROR(AVERAGEIFS('RD Condos'!$F:$F,'RD Condos'!$H:$H,"2",'RD Condos'!$A:$A,1,'RD Condos'!$K:$K,"Aqua"),"") | X37: =COUNTIFS('RD Condos'!$H:$H,"3",'RD Condos'!$A:$A,1,'RD Condos'!$K:$K,"Aqua") | Y37: =IFERROR(AVERAGEIFS('RD Condos'!$B:$B,'RD Condos'!$H:$H,"3",'RD Condos'!$A:$A,1,'RD Condos'!$K:$K,"Aqua"),"") | Z37: =IFERROR(AVERAGEIFS('RD Condos'!$D:$D,'RD Condos'!$H:$H,"3",'RD Condos'!$A:$A,1,'RD Condos'!$K:$K,"Aqua"),"") | AA37: =IFERROR(AVERAGEIFS('RD Condos'!$F:$F,'RD Condos'!$H:$H,"3",'RD Condos'!$A:$A,1,'RD Condos'!$K:$K,"Aqua"),"")
B38: 1-Bed / 1+Den | C38: =Data_Summary!C26 | D38: =Data_Summary!F26
B39: 2-Bed | C39: =Data_Summary!C27 | D39: =Data_Summary!F27 | K39: Weighted Avg. | L39: =COUNTIFS('RD Condos'!$Q:$Q,"1",'RD Condos'!$A:$A,1) | M39: =IFERROR(AVERAGEIFS('RD Condos'!$B:$B,'RD Condos'!$Q:$Q,"1",'RD Condos'!$A:$A,1),"") | N39: =IFERROR(AVERAGEIFS('RD Condos'!$D:$D,'RD Condos'!$Q:$Q,"1",'RD Condos'!$A:$A,1),"") | O39: =IFERROR(AVERAGEIFS('RD Condos'!$F:$F,'RD Condos'!$Q:$Q,"1",'RD Condos'!$A:$A,1),"") | P39: =COUNTIFS('RD Condos'!$Q:$Q,"1+1",'RD Condos'!$A:$A,1) | Q39: =IFERROR(AVERAGEIFS('RD Condos'!$B:$B,'RD Condos'!$Q:$Q,"1+1",'RD Condos'!$A:$A,1),"") | R39: =IFERROR(AVERAGEIFS('RD Condos'!$D:$D,'RD Condos'!$Q:$Q,"1+1",'RD Condos'!$A:$A,1),"") | S39: =IFERROR(AVERAGEIFS('RD Condos'!$F:$F,'RD Condos'!$Q:$Q,"1+1",'RD Condos'!$A:$A,1),"") | T39: =COUNTIFS('RD Condos'!$H:$H,"2",'RD Condos'!$A:$A,1) | U39: =IFERROR(AVERAGEIFS('RD Condos'!$B:$B,'RD Condos'!$H:$H,"2",'RD Condos'!$A:$A,1),"") | V39: =IFERROR(AVERAGEIFS('RD Condos'!$D:$D,'RD Condos'!$H:$H,"2",'RD Condos'!$A:$A,1),"") | W39: =IFERROR(AVERAGEIFS('RD Condos'!$F:$F,'RD Condos'!$H:$H,"2",'RD Condos'!$A:$A,1),"") | X39: =COUNTIFS('RD Condos'!$H:$H,"3",'RD Condos'!$A:$A,1) | Y39: =IFERROR(AVERAGEIFS('RD Condos'!$B:$B,'RD Condos'!$H:$H,"3",'RD Condos'!$A:$A,1),"") | Z39: =IFERROR(AVERAGEIFS('RD Condos'!$D:$D,'RD Condos'!$H:$H,"3",'RD Condos'!$A:$A,1),"") | AA39: =IFERROR(AVERAGEIFS('RD Condos'!$F:$F,'RD Condos'!$H:$H,"3",'RD Condos'!$A:$A,1),"")
B40: 3-Bed | C40: =Data_Summary!C28 | D40: =Data_Summary!F28 | K40: Low | O40: =SUMPRODUCT(MIN(IF((('RD Condos'!$Q$2:$Q$120="1")*('RD Condos'!$A$2:$A$120=1)),'RD Condos'!$F$2:$F$120))) | S40: =SUMPRODUCT(MIN(IF((('RD Condos'!$Q$2:$Q$120="1+1")*('RD Condos'!$A$2:$A$120=1)),'RD Condos'!$F$2:$F$120))) | W40: =SUMPRODUCT(MIN(IF((('RD Condos'!$H$2:$H$120="2")*('RD Condos'!$A$2:$A$120=1)),'RD Condos'!$F$2:$F$120))) | AA40: =SUMPRODUCT(MIN(IF((('RD Condos'!$H$2:$H$120="3")*('RD Condos'!$A$2:$A$120=1)),'RD Condos'!$F$2:$F$120)))
K41: High | O41: =SUMPRODUCT(MAX(IF((('RD Condos'!$Q$2:$Q$120="1")*('RD Condos'!$A$2:$A$120=1)),'RD Condos'!$F$2:$F$120))) | S41: =SUMPRODUCT(MAX(IF((('RD Condos'!$Q$2:$Q$120="1+1")*('RD Condos'!$A$2:$A$120=1)),'RD Condos'!$F$2:$F$120))) | W41: =SUMPRODUCT(MAX(IF((('RD Condos'!$H$2:$H$120="2")*('RD Condos'!$A$2:$A$120=1)),'RD Condos'!$F$2:$F$120))) | AA41: =SUMPRODUCT(MAX(IF((('RD Condos'!$H$2:$H$120="3")*('RD Condos'!$A$2:$A$120=1)),'RD Condos'!$F$2:$F$120)))
B43: COMP-QUALITY SCORES (Claude judgment, /10 — not a source figure) | K43: PBR Premium | O43: =Data_Summary!C4 | S43: =Data_Summary!C4 | W43: =Data_Summary!C4 | AA43: =Data_Summary!C4
B44: Building | C44: Score /10 | D44: Role | E44: Why | K44: Weighted Avg. | N44: =IFERROR(N39*(1+O43),"") | O44: =IFERROR(O39*(1+O43),"") | R44: =IFERROR(R39*(1+S43),"") | S44: =IFERROR(S39*(1+S43),"") | V44: =IFERROR(V39*(1+W43),"") | W44: =IFERROR(W39*(1+W43),"") | Z44: =IFERROR(Z39*(1+AA43),"") | AA44: =IFERROR(AA39*(1+AA43),"")
B45: Concord Canada House | C45: 10 | D45: PRIMARY | E45: Newest (2025), on Spadina, deepest fresh-lease depth — ideal vintage/location match. | K45: Weighted Avg. Building Total (Comps) | L45: =IFERROR((N39*Data_Summary!$T$3+R39*Data_Summary!$T$4+V39*Data_Summary!$T$5+Z39*Data_Summary!$T$6)*Data_Summary!$T$2,"")
B46: Nobu Residences | C46: 8 | D46: secondary | E46: 2024 King West luxury condo; close vintage, slightly different micro-market.
...

Sheet Subject & Conclusion
A1: ★ TLDR — RECOMMENDED RENT · 10 Lower Spadina Condos
A2: Subject = brand-new (2029-30) waterfront condo. Recommended rent = newest-comp evidence (Concord Canada House 2025, on Spadina) grossed up by a new-build/lease-up premium. Confidence: HIGH on comps; premium is a tunable judgment.
A4: RECOMMENDED SUBJECT RENT ($/SF) | C4: =Data_Summary!$C$34
A5: Basis: Concord Canada House comp $/SF × (1 + premium Data_Summary!C4)
A6: Conservative basis (all-comp + premium) | C6: =Data_Summary!$C$35
A8: RECOMMENDED MONTHLY RENT — by suite type (subject = Concord comp + premium)
A9: Suite type | B9: Avg SF | C9: Recommended Rent
A10: 1-Bed / 1+Den | B10: =Data_Summary!C26 | C10: =Data_Summary!F26
A11: 2-Bed | B11: =Data_Summary!C27 | C11: =Data_Summary!F27
A12: 3-Bed | B12: =Data_Summary!C28 | C12: =Data_Summary!F28
A14: Custom suite — enter size (sq ft) → | D14: 700
A15: Implied rent @ recommended subject $/SF | D15: =IFERROR(D14*Data_Summary!$C$34,"")
A16: Implied rent @ raw comp $/SF (no premium) | D16: =IFERROR(D14*Data_Summary!$C$31,"")
A18: WHY / BRIDGE
A19: Current-market comp $/SF — Concord Canada House (2025/2026 leases) | C19: =Data_Summary!$C$31 | D19: market evidence today
A20: Plus — new-build / lease-up premium | C20: =Data_Summary!C4 | D20: judgment lever (tunable)
A21: Recommended subject $/SF | C21: =Data_Summary!$C$34 | D21: this workbook
A22: All-comp basis $/SF (blend of 9, 2003-2025) | C22: =Data_Summary!$C$32 | D22: conservative floor
A24: TRREB Q1-2026 context — Toronto C01 avg apt rent: 1BR $2,438 · 2BR $3,431 · 3BR $4,591 (City of Toronto 1BR $2,292; GTA YoY -4.1%/-3.2%/-2.7%).
A27: Confidence colours (Raw Data / Building Summary):
A28: High = leased in-window, SF verified per-unit
A29: Med = active/asking, older lease, or minor SF caveat
A30: Low/excluded = SF bracket-only (no registered area) or partial/outlier
A32: Comp-derived detail (raw $/SF, before premium)
A33: Benchmark | B33: Avg SF | C33: Avg Leased Rent | D33: Avg $/SF | E33: Note
A34: Concord Canada House (newest, 2025) — PRIMARY | B34: ='Building Summary'!K4 | C34: ='Building Summary'!L4 | D34: ='Building Summary'!M4 | E34: PRIMARY
A35: 1-Bed (all comps, den-incl.) | B35: =Data_Summary!C20 | C35: =Data_Summary!D20 | D35: =Data_Summary!E20
A36: 2-Bed (all comps) | B36: =Data_Summary!C21 | C36: =Data_Summary!D21 | D36: =Data_Summary!E21
A37: 3-Bed (all comps) | B37: =Data_Summary!C22 | C37: =Data_Summary!D22 | D37: =Data_Summary!E22
A39: • Subject: 10 Lower Spadina Condos — Arkfield, 49 storeys / 511 suites, 10 Lower Spadina Ave, Waterfront/C01 (Planning Phase; no plans or leases of its own yet).
A40: • All 9 comps are condos; apartment premium (C3) unused. Comp set user-confirmed 2026-06-16 (all 9).
A41: • SF verified per-unit (condos.ca registered area) for 39 leased comps. Quartz/Spectra + some The Well units are SF bracket-only on condos.ca → recorded as context (Include=0), excluded from $/SF.
A42: • Premium (Data_Summary C4) bridges current comp $/SF to the subject; proposed 10%, tunable.
A43: • Definitive SF source for the subject: developer suite-area schedule / registered declaration once published.

Sheet Building Summary
A1: Comp Building Summary — 10 Lower Spadina Condos (10 Lower Spadina Ave, Waterfront/C01)
A3: Building | B3: Address | C3: Area | D3: Developer | E3: First Occupancy | F3: Yr Built | G3: Product | H3: Storeys | I3: Units | J3: Transaction Count | K3: Avg SF | L3: Avg Rent | M3: Avg $/SF
A4: Concord Canada House | B4: 23 Spadina Ave | C4: CityPlace / Waterfront | D4: Concord Adex | E4: 2025 | F4: 2025 | G4: Condo | H4: 72 | I4: 1394 | J4: =COUNTIFS('RD Condos'!$K:$K,$A4,'RD Condos'!$A:$A,1) | K4: =IFERROR(AVERAGEIFS('RD Condos'!$B:$B,'RD Condos'!$K:$K,$A4,'RD Condos'!$A:$A,1),"") | L4: =IFERROR(AVERAGEIFS('RD Condos'!$AB:$AB,'RD Condos'!$K:$K,$A4,'RD Condos'!$A:$A,1),"") | M4: =IFERROR(AVERAGEIFS('RD Condos'!$E:$E,'RD Condos'!$K:$K,$A4,'RD Condos'!$A:$A,1),"")
A5: Nobu Residences | B5: 15 Mercer St | C5: King West | D5: Madison Group | E5: 2024 | F5: 2024 | G5: Condo | H5: 45 | I5: 657 | J5: =COUNTIFS('RD Condos'!$K:$K,$A5,'RD Condos'!$A:$A,1) | K5: =IFERROR(AVERAGEIFS('RD Condos'!$B:$B,'RD Condos'!$K:$K,$A5,'RD Condos'!$A:$A,1),"") | L5: =IFERROR(AVERAGEIFS('RD Condos'!$AB:$AB,'RD Condos'!$K:$K,$A5,'RD Condos'!$A:$A,1),"") | M5: =IFERROR(AVERAGEIFS('RD Condos'!$E:$E,'RD Condos'!$K:$K,$A5,'RD Condos'!$A:$A,1),"")
A6: The Well | B6: 470-480 Front St W | C6: King West | D6: Tridel | E6: 2024 | F6: 2024 | G6: Condo | H6: 18 | I6: 356 | J6: =COUNTIFS('RD Condos'!$K:$K,$A6,'RD Condos'!$A:$A,1) | K6: =IFERROR(AVERAGEIFS('RD Condos'!$B:$B,'RD Condos'!$K:$K,$A6,'RD Condos'!$A:$A,1),"") | L6: =IFERROR(AVERAGEIFS('RD Condos'!$AB:$AB,'RD Condos'!$K:$K,$A6,'RD Condos'!$A:$A,1),"") | M6: =IFERROR(AVERAGEIFS('RD Condos'!$E:$E,'RD Condos'!$K:$K,$A6,'RD Condos'!$A:$A,1),"")
A7: Ten York | B7: 10 York St | C7: Waterfront | D7: Tridel | E7: 2019 | F7: 2019 | G7: Condo | H7: 66 | I7: 694 | J7: =COUNTIFS('RD Condos'!$K:$K,$A7,'RD Condos'!$A:$A,1) | K7: =IFERROR(AVERAGEIFS('RD Condos'!$B:$B,'RD Condos'!$K:$K,$A7,'RD Condos'!$A:$A,1),"") | L7: =IFERROR(AVERAGEIFS('RD Condos'!$AB:$AB,'RD Condos'!$K:$K,$A7,'RD Condos'!$A:$A,1),"") | M7: =IFERROR(AVERAGEIFS('RD Condos'!$E:$E,'RD Condos'!$K:$K,$A7,'RD Condos'!$A:$A,1),"")
A8: Forward Condos | B8: 70-90 Queens Wharf Rd | C8: CityPlace | D8: Concord Adex | E8: 2018 | F8: 2018 | G8: Condo | H8: 30 | I8: 625 | J8: =COUNTIFS('RD Condos'!$K:$K,$A8,'RD Condos'!$A:$A,1) | K8: =IFERROR(AVERAGEIFS('RD Condos'!$B:$B,'RD Condos'!$K:$K,$A8,'RD Condos'!$A:$A,1),"") | L8: =IFERROR(AVERAGEIFS('RD Condos'!$AB:$AB,'RD Condos'!$K:$K,$A8,'RD Condos'!$A:$A,1),"") | M8: =IFERROR(AVERAGEIFS('RD Condos'!$E:$E,'RD Condos'!$K:$K,$A8,'RD Condos'!$A:$A,1),"")
A9: Quartz/Spectra | B9: 75-85 Queens Wharf Rd | C9: CityPlace | D9: — | E9: 2015 | F9: 2015 | G9: Condo | H9: 41 | I9: 943 | J9: =COUNTIFS('RD Condos'!$K:$K,$A9,'RD Condos'!$A:$A,1) | K9: =IFERROR(AVERAGEIFS('RD Condos'!$B:$B,'RD Condos'!$K:$K,$A9,'RD Condos'!$A:$A,1),"") | L9: =IFERROR(AVERAGEIFS('RD Condos'!$AB:$AB,'RD Condos'!$K:$K,$A9,'RD Condos'!$A:$A,1),"") | M9: =IFERROR(AVERAGEIFS('RD Condos'!$E:$E,'RD Condos'!$K:$K,$A9,'RD Condos'!$A:$A,1),"")
A10: Library District | B10: 170 Fort York Blvd | C10: CityPlace | D10: — | E10: 2014 | F10: 2014 | G10: Condo | H10: 29 | I10: 364 | J10: =COUNTIFS('RD Condos'!$K:$K,$A10,'RD Condos'!$A:$A,1) | K10: =IFERROR(AVERAGEIFS('RD Condos'!$B:$B,'RD Condos'!$K:$K,$A10,'RD Condos'!$A:$A,1),"") | L10: =IFERROR(AVERAGEIFS('RD Condos'!$AB:$AB,'RD Condos'!$K:$K,$A10,'RD Condos'!$A:$A,1),"") | M10: =IFERROR(AVERAGEIFS('RD Condos'!$E:$E,'RD Condos'!$K:$K,$A10,'RD Condos'!$A:$A,1),"")
A11: N1 | N2 - CityPlace | B11: 15 Fort York Blvd | C11: CityPlace | D11: — | E11: 2008 | F11: 2008 | G11: Condo | H11: 42 | I11: 568 | J11: =COUNTIFS('RD Condos'!$K:$K,$A11,'RD Condos'!$A:$A,1) | K11: =IFERROR(AVERAGEIFS('RD Condos'!$B:$B,'RD Condos'!$K:$K,$A11,'RD Condos'!$A:$A,1),"") | L11: =IFERROR(AVERAGEIFS('RD Condos'!$AB:$AB,'RD Condos'!$K:$K,$A11,'RD Condos'!$A:$A,1),"") | M11: =IFERROR(AVERAGEIFS('RD Condos'!$E:$E,'RD Condos'!$K:$K,$A11,'RD Condos'!$A:$A,1),"")
A12: Aqua | B12: 410 Queens Quay W | C12: Waterfront | D12: — | E12: 2003 | F12: 2003 | G12: Condo | H12: 16 | I12: 273 | J12: =COUNTIFS('RD Condos'!$K:$K,$A12,'RD Condos'!$A:$A,1) | K12: =IFERROR(AVERAGEIFS('RD Condos'!$B:$B,'RD Condos'!$K:$K,$A12,'RD Condos'!$A:$A,1),"") | L12: =IFERROR(AVERAGEIFS('RD Condos'!$AB:$AB,'RD Condos'!$K:$K,$A12,'RD Condos'!$A:$A,1),"") | M12: =IFERROR(AVERAGEIFS('RD Condos'!$E:$E,'RD Condos'!$K:$K,$A12,'RD Condos'!$A:$A,1),"")
A13: ALL CONDOS | J13: =SUM(J4:J12) | K13: =IFERROR(AVERAGEIFS('RD Condos'!$B:$B,'RD Condos'!$A:$A,1),"") | L13: =IFERROR(AVERAGEIFS('RD Condos'!$AB:$AB,'RD Condos'!$A:$A,1),"") | M13: =IFERROR(AVERAGEIFS('RD Condos'!$AN:$AN,'RD Condos'!$A:$A,1),"")
A14: ALL APARTMENTS | J14: =COUNTIFS('RD Apartments'!$A:$A,1) | K14: =IFERROR(AVERAGEIFS('RD Apartments'!$B:$B,'RD Apartments'!$A:$A,1),"") | L14: =IFERROR(AVERAGEIFS('RD Apartments'!$AB:$AB,'RD Apartments'!$A:$A,1),"") | M14: =IFERROR(AVERAGEIFS('RD Apartments'!$AN:$AN,'RD Apartments'!$A:$A,1),"")
A15: Apartment band is structurally present per spec; no apartment comps in this set (subject + all 9 comps are condos).

Sheet Data_Summary
B1: Date Filter (include leases on/after) | C1: 45658 | D1: lever — trailing window; all comps are 2026 leases (well inside). Tunable. | G1: Subject unit mix (1BR/2BR/3BR, den-incl) — DERIVED | J1: SF | K1: #Park | L1: 2BD | M1: 3BD | N1: Leased$ | P1: Subject Unit-Mix Derivation (P/Q) | S1: Subject Output mix & suite count (estimated, pre-con)
B2: Parking Adjustment ($/spot/mo) | C2: =INDEX(LINEST(N2:N40,J2:M40,TRUE(),FALSE()),1,3) | D2: LIVE OLS regression (rent ~ SF + parking + 2BD + 3BD) over verified leased rows J:N. Derived, not typed. | G2: 1BR wt | H2: =IF($Q$5>0,$Q$2/$Q$5,$Q$8) | J2: ='RD Condos'!B2 | K2: ='RD Condos'!U2 | L2: =IF('RD Condos'!H2="2",1,0) | M2: =IF('RD Condos'!H2="3",1,0) | N2: ='RD Condos'!AB2 | P2: 1BR plans (SUBJECT, den-incl) | Q2: =COUNTIFS('Floor Plans'!$A:$A,"*(SUBJECT)*",'Floor Plans'!$E:$E,"<=1") | S2: Suite count | T2: 511 | U2: vipcondos Step 0 (511 suites, 49 storeys)
B3: Apartment premium (apt comps only) | C3: 0.1 | D3: condo-vs-apartment markup; applies to RD Apartments only. No apartment comps in this set, so unused. | G3: 2BR wt | H3: =IF($Q$5>0,$Q$3/$Q$5,$Q$9) | J3: ='RD Condos'!B3 | K3: ='RD Condos'!U3 | L3: =IF('RD Condos'!H3="2",1,0) | M3: =IF('RD Condos'!H3="3",1,0) | N3: ='RD Condos'!AB3 | P3: 2BR plans (SUBJECT) | Q3: =COUNTIFS('Floor Plans'!$A:$A,"*(SUBJECT)*",'Floor Plans'!$E:$E,2) | S3: 1BR wt | T3: 0.45 | U3: estimated mix (sums to 100%); tunable. 2026-06-16
B4: Subject rental premium (new-build / lease-up; comp $/SF → subject) | C4: 0.1 | D4: PROPOSED 10% — brand-new 2029-30 waterfront delivery vs comp blend. Judgment lever, tunable (2026-06-16). | G4: 3BR wt | H4: =IF($Q$5>0,$Q$4/$Q$5,$Q$10) | J4: ='RD Condos'!B4 | K4: ='RD Condos'!U4 | L4: =IF('RD Condos'!H4="2",1,0) | M4: =IF('RD Condos'!H4="3",1,0) | N4: ='RD Condos'!AB4 | P4: 3BR plans (SUBJECT) | Q4: =COUNTIFS('Floor Plans'!$A:$A,"*(SUBJECT)*",'Floor Plans'!$E:$E,">=3") | S4: 1+Den wt | T4: 0.18
A5: Comp building rollup (included leases) | J5: ='RD Condos'!B5 | K5: ='RD Condos'!U5 | L5: =IF('RD Condos'!H5="2",1,0) | M5: =IF('RD Condos'!H5="3",1,0) | N5: ='RD Condos'!AB5 | P5: Total tagged plans | Q5: =SUM(Q2:Q4) | S5: 2BR wt | T5: 0.3
A6: Building | B6: Address | C6: Built | D6: Incl. | E6: Avg SF | F6: Avg Rent | G6: Avg $/SF | J6: ='RD Condos'!B6 | K6: ='RD Condos'!U6 | L6: =IF('RD Condos'!H6="2",1,0) | M6: =IF('RD Condos'!H6="3",1,0) | N6: ='RD Condos'!AB6 | P6: (0 ⇒ falls back to manual mix Q8:Q10) | S6: 3BR wt | T6: 0.07
A7: Concord Canada House | B7: 23 Spadina Ave | C7: Built 2025 | D7: =COUNTIFS('RD Condos'!$K:$K,$A7,'RD Condos'!$A:$A,1) | E7: =IFERROR(AVERAGEIFS('RD Condos'!$B:$B,'RD Condos'!$K:$K,$A7,'RD Condos'!$A:$A,1),"") | F7: =IFERROR(AVERAGEIFS('RD Condos'!$AB:$AB,'RD Condos'!$K:$K,$A7,'RD Condos'!$A:$A,1),"") | G7: =IFERROR(AVERAGEIFS('RD Condos'!$E:$E,'RD Condos'!$K:$K,$A7,'RD Condos'!$A:$A,1),"") | J7: ='RD Condos'!B7 | K7: ='RD Condos'!U7 | L7: =IF('RD Condos'!H7="2",1,0) | M7: =IF('RD Condos'!H7="3",1,0) | N7: ='RD Condos'!AB7 | P7: Source | Q7: estimated — typical downtown waterfront condo program; no subject plans published (pre-construction), 2026-06-16
A8: Nobu Residences | B8: 15 Mercer St | C8: Built 2024 | D8: =COUNTIFS('RD Condos'!$K:$K,$A8,'RD Condos'!$A:$A,1) | E8: =IFERROR(AVERAGEIFS('RD Condos'!$B:$B,'RD Condos'!$K:$K,$A8,'RD Condos'!$A:$A,1),"") | F8: =IFERROR(AVERAGEIFS('RD Condos'!$AB:$AB,'RD Condos'!$K:$K,$A8,'RD Condos'!$A:$A,1),"") | G8: =IFERROR(AVERAGEIFS('RD Condos'!$E:$E,'RD Condos'!$K:$K,$A8,'RD Condos'!$A:$A,1),"") | J8: ='RD Condos'!B8 | K8: ='RD Condos'!U8 | L8: =IF('RD Condos'!H8="2",1,0) | M8: =IF('RD Condos'!H8="3",1,0) | N8: ='RD Condos'!AB8 | P8: 1BR wt (manual) | Q8: 0.63
A9: The Well | B9: 470-480 Front St W | C9: Built 2024 | D9: =COUNTIFS('RD Condos'!$K:$K,$A9,'RD Condos'!$A:$A,1) | E9: =IFERROR(AVERAGEIFS('RD Condos'!$B:$B,'RD Condos'!$K:$K,$A9,'RD Condos'!$A:$A,1),"") | F9: =IFERROR(AVERAGEIFS('RD Condos'!$AB:$AB,'RD Condos'!$K:$K,$A9,'RD Condos'!$A:$A,1),"") | G9: =IFERROR(AVERAGEIFS('RD Condos'!$E:$E,'RD Condos'!$K:$K,$A9,'RD Condos'!$A:$A,1),"") | J9: ='RD Condos'!B9 | K9: ='RD Condos'!U9 | L9: =IF('RD Condos'!H9="2",1,0) | M9: =IF('RD Condos'!H9="3",1,0) | N9: ='RD Condos'!AB9 | P9: 2BR wt (manual) | Q9: 0.3
A10: Ten York | B10: 10 York St | C10: Built 2019 | D10: =COUNTIFS('RD Condos'!$K:$K,$A10,'RD Condos'!$A:$A,1) | E10: =IFERROR(AVERAGEIFS('RD Condos'!$B:$B,'RD Condos'!$K:$K,$A10,'RD Condos'!$A:$A,1),"") | F10: =IFERROR(AVERAGEIFS('RD Condos'!$AB:$AB,'RD Condos'!$K:$K,$A10,'RD Condos'!$A:$A,1),"") | G10: =IFERROR(AVERAGEIFS('RD Condos'!$E:$E,'RD Condos'!$K:$K,$A10,'RD Condos'!$A:$A,1),"") | J10: ='RD Condos'!B10 | K10: ='RD Condos'!U10 | L10: =IF('RD Condos'!H10="2",1,0) | M10: =IF('RD Condos'!H10="3",1,0) | N10: ='RD Condos'!AB10 | P10: 3BR wt (manual) | Q10: 0.07
A11: Forward Condos | B11: 70-90 Queens Wharf Rd | C11: Built 2018 | D11: =COUNTIFS('RD Condos'!$K:$K,$A11,'RD Condos'!$A:$A,1) | E11: =IFERROR(AVERAGEIFS('RD Condos'!$B:$B,'RD Condos'!$K:$K,$A11,'RD Condos'!$A:$A,1),"") | F11: =IFERROR(AVERAGEIFS('RD Condos'!$AB:$AB,'RD Condos'!$K:$K,$A11,'RD Condos'!$A:$A,1),"") | G11: =IFERROR(AVERAGEIFS('RD Condos'!$E:$E,'RD Condos'!$K:$K,$A11,'RD Condos'!$A:$A,1),"") | J11: ='RD Condos'!B11 | K11: ='RD Condos'!U11 | L11: =IF('RD Condos'!H11="2",1,0) | M11: =IF('RD Condos'!H11="3",1,0) | N11: ='RD Condos'!AB11
A12: Quartz/Spectra | B12: 75-85 Queens Wharf Rd | C12: Built 2015 | D12: =COUNTIFS('RD Condos'!$K:$K,$A12,'RD Condos'!$A:$A,1) | E12: =IFERROR(AVERAGEIFS('RD Condos'!$B:$B,'RD Condos'!$K:$K,$A12,'RD Condos'!$A:$A,1),"") | F12: =IFERROR(AVERAGEIFS('RD Condos'!$AB:$AB,'RD Condos'!$K:$K,$A12,'RD Condos'!$A:$A,1),"") | G12: =IFERROR(AVERAGEIFS('RD Condos'!$E:$E,'RD Condos'!$K:$K,$A12,'RD Condos'!$A:$A,1),"") | J12: ='RD Condos'!B12 | K12: ='RD Condos'!U12 | L12: =IF('RD Condos'!H12="2",1,0) | M12: =IF('RD Condos'!H12="3",1,0) | N12: ='RD Condos'!AB12
A13: Library District | B13: 170 Fort York Blvd | C13: Built 2014 | D13: =COUNTIFS('RD Condos'!$K:$K,$A13,'RD Condos'!$A:$A,1) | E13: =IFERROR(AVERAGEIFS('RD Condos'!$B:$B,'RD Condos'!$K:$K,$A13,'RD Condos'!$A:$A,1),"") | F13: =IFERROR(AVERAGEIFS('RD Condos'!$AB:$AB,'RD Condos'!$K:$K,$A13,'RD Condos'!$A:$A,1),"") | G13: =IFERROR(AVERAGEIFS('RD Condos'!$E:$E,'RD Condos'!$K:$K,$A13,'RD Condos'!$A:$A,1),"") | J13: ='RD Condos'!B13 | K13: ='RD Condos'!U13 | L13: =IF('RD Condos'!H13="2",1,0) | M13: =IF('RD Condos'!H13="3",1,0) | N13: ='RD Condos'!AB13
A14: N1 | N2 - CityPlace | B14: 15 Fort York Blvd | C14: Built 2008 | D14: =COUNTIFS('RD Condos'!$K:$K,$A14,'RD Condos'!$A:$A,1) | E14: =IFERROR(AVERAGEIFS('RD Condos'!$B:$B,'RD Condos'!$K:$K,$A14,'RD Condos'!$A:$A,1),"") | F14: =IFERROR(AVERAGEIFS('RD Condos'!$AB:$AB,'RD Condos'!$K:$K,$A14,'RD Condos'!$A:$A,1),"") | G14: =IFERROR(AVERAGEIFS('RD Condos'!$E:$E,'RD Condos'!$K:$K,$A14,'RD Condos'!$A:$A,1),"") | J14: ='RD Condos'!B14 | K14: ='RD Condos'!U14 | L14: =IF('RD Condos'!H14="2",1,0) | M14: =IF('RD Condos'!H14="3",1,0) | N14: ='RD Condos'!AB14
A15: Aqua | B15: 410 Queens Quay W | C15: Built 2003 | D15: =COUNTIFS('RD Condos'!$K:$K,$A15,'RD Condos'!$A:$A,1) | E15: =IFERROR(AVERAGEIFS('RD Condos'!$B:$B,'RD Condos'!$K:$K,$A15,'RD Condos'!$A:$A,1),"") | F15: =IFERROR(AVERAGEIFS('RD Condos'!$AB:$AB,'RD Condos'!$K:$K,$A15,'RD Condos'!$A:$A,1),"") | G15: =IFERROR(AVERAGEIFS('RD Condos'!$E:$E,'RD Condos'!$K:$K,$A15,'RD Condos'!$A:$A,1),"") | J15: ='RD Condos'!B15 | K15: ='RD Condos'!U15 | L15: =IF('RD Condos'!H15="2",1,0) | M15: =IF('RD Condos'!H15="3",1,0) | N15: ='RD Condos'!AB15
A16: ALL COMPS | D16: =SUM(D7:D15) | E16: =IFERROR(AVERAGEIFS('RD Condos'!$B:$B,'RD Condos'!$A:$A,1),"") | F16: =IFERROR(AVERAGEIFS('RD Condos'!$AB:$AB,'RD Condos'!$A:$A,1),"") | G16: =IFERROR(AVERAGEIFS('RD Condos'!$AN:$AN,'RD Condos'!$A:$A,1),"") | J16: ='RD Condos'!B16 | K16: ='RD Condos'!U16 | L16: =IF('RD Condos'!H16="2",1,0) | M16: =IF('RD Condos'!H16="3",1,0) | N16: ='RD Condos'!AB16
J17: ='RD Condos'!B17 | K17: ='RD Condos'!U17 | L17: =IF('RD Condos'!H17="2",1,0) | M17: =IF('RD Condos'!H17="3",1,0) | N17: ='RD Condos'!AB17
A18: By Bedroom — all comps (den-incl.) | J18: ='RD Condos'!B18 | K18: ='RD Condos'!U18 | L18: =IF('RD Condos'!H18="2",1,0) | M18: =IF('RD Condos'!H18="3",1,0) | N18: ='RD Condos'!AB18
A19: Beds | B19: Incl. | C19: Avg SF | D19: Avg Rent | E19: Avg $/SF | J19: ='RD Condos'!B19 | K19: ='RD Condos'!U19 | L19: =IF('RD Condos'!H19="2",1,0) | M19: =IF('RD Condos'!H19="3",1,0) | N19: ='RD Condos'!AB19
A20: 1 Bed | B20: =COUNTIFS('RD Condos'!$H:$H,"1",'RD Condos'!$A:$A,1) | C20: =IFERROR(AVERAGEIFS('RD Condos'!$B:$B,'RD Condos'!$H:$H,"1",'RD Condos'!$A:$A,1),"") | D20: =IFERROR(AVERAGEIFS('RD Condos'!$AB:$AB,'RD Condos'!$H:$H,"1",'RD Condos'!$A:$A,1),"") | E20: =IFERROR(AVERAGEIFS('RD Condos'!$AN:$AN,'RD Condos'!$H:$H,"1",'RD Condos'!$A:$A,1),"") | J20: ='RD Condos'!B20 | K20: ='RD Condos'!U20 | L20: =IF('RD Condos'!H20="2",1,0) | M20: =IF('RD Condos'!H20="3",1,0) | N20: ='RD Condos'!AB20
A21: 2 Bed | B21: =COUNTIFS('RD Condos'!$H:$H,"2",'RD Condos'!$A:$A,1) | C21: =IFERROR(AVERAGEIFS('RD Condos'!$B:$B,'RD Condos'!$H:$H,"2",'RD Condos'!$A:$A,1),"") | D21: =IFERROR(AVERAGEIFS('RD Condos'!$AB:$AB,'RD Condos'!$H:$H,"2",'RD Condos'!$A:$A,1),"") | E21: =IFERROR(AVERAGEIFS('RD Condos'!$AN:$AN,'RD Condos'!$H:$H,"2",'RD Condos'!$A:$A,1),"") | J21: ='RD Condos'!B21 | K21: ='RD Condos'!U21 | L21: =IF('RD Condos'!H21="2",1,0) | M21: =IF('RD Condos'!H21="3",1,0) | N21: ='RD Condos'!AB21
A22: 3 Bed | B22: =COUNTIFS('RD Condos'!$H:$H,"3",'RD Condos'!$A:$A,1) | C22: =IFERROR(AVERAGEIFS('RD Condos'!$B:$B,'RD Condos'!$H:$H,"3",'RD Condos'!$A:$A,1),"") | D22: =IFERROR(AVERAGEIFS('RD Condos'!$AB:$AB,'RD Condos'!$H:$H,"3",'RD Condos'!$A:$A,1),"") | E22: =IFERROR(AVERAGEIFS('RD Condos'!$AN:$AN,'RD Condos'!$H:$H,"3",'RD Condos'!$A:$A,1),"") | J22: ='RD Condos'!B22 | K22: ='RD Condos'!U22 | L22: =IF('RD Condos'!H22="2",1,0) | M22: =IF('RD Condos'!H22="3",1,0) | N22: ='RD Condos'!AB22
J23: ='RD Condos'!B23 | K23: ='RD Condos'!U23 | L23: =IF('RD Condos'!H23="2",1,0) | M23: =IF('RD Condos'!H23="3",1,0) | N23: ='RD Condos'!AB23
A24: By Bedroom — Concord Canada House only (new-build basis) | J24: ='RD Condos'!B24 | K24: ='RD Condos'!U24 | L24: =IF('RD Condos'!H24="2",1,0) | M24: =IF('RD Condos'!H24="3",1,0) | N24: ='RD Condos'!AB24
A25: Beds | B25: Incl. | C25: Avg SF | D25: Avg Rent | E25: $/SF | F25: Subj Rent (+prem) | J25: ='RD Condos'!B25 | K25: ='RD Condos'!U25 | L25: =IF('RD Condos'!H25="2",1,0) | M25: =IF('RD Condos'!H25="3",1,0) | N25: ='RD Condos'!AB25
A26: 1 Bed | B26: =COUNTIFS('RD Condos'!$K:$K,"Concord Canada House",'RD Condos'!$H:$H,"1",'RD Condos'!$A:$A,1) | C26: =IFERROR(AVERAGEIFS('RD Condos'!$B:$B,'RD Condos'!$K:$K,"Concord Canada House",'RD Condos'!$H:$H,"1",'RD Condos'!$A:$A,1),"") | D26: =IFERROR(AVERAGEIFS('RD Condos'!$AB:$AB,'RD Condos'!$K:$K,"Concord Canada House",'RD Condos'!$H:$H,"1",'RD Condos'!$A:$A,1),"") | E26: =IFERROR(AVERAGEIFS('RD Condos'!$E:$E,'RD Condos'!$K:$K,"Concord Canada House",'RD Condos'!$H:$H,"1",'RD Condos'!$A:$A,1),"") | F26: =IFERROR(D26*(1+$C$4),"") | J26: ='RD Condos'!B26 | K26: ='RD Condos'!U26 | L26: =IF('RD Condos'!H26="2",1,0) | M26: =IF('RD Condos'!H26="3",1,0) | N26: ='RD Condos'!AB26
A27: 2 Bed | B27: =COUNTIFS('RD Condos'!$K:$K,"Concord Canada House",'RD Condos'!$H:$H,"2",'RD Condos'!$A:$A,1) | C27: =IFERROR(AVERAGEIFS('RD Condos'!$B:$B,'RD Condos'!$K:$K,"Concord Canada House",'RD Condos'!$H:$H,"2",'RD Condos'!$A:$A,1),"") | D27: =IFERROR(AVERAGEIFS('RD Condos'!$AB:$AB,'RD Condos'!$K:$K,"Concord Canada House",'RD Condos'!$H:$H,"2",'RD Condos'!$A:$A,1),"") | E27: =IFERROR(AVERAGEIFS('RD Condos'!$E:$E,'RD Condos'!$K:$K,"Concord Canada House",'RD Condos'!$H:$H,"2",'RD Condos'!$A:$A,1),"") | F27: =IFERROR(D27*(1+$C$4),"") | J27: ='RD Condos'!B27 | K27: ='RD Condos'!U27 | L27: =IF('RD Condos'!H27="2",1,0) | M27: =IF('RD Condos'!H27="3",1,0) | N27: ='RD Condos'!AB27
A28: 3 Bed | B28: =COUNTIFS('RD Condos'!$K:$K,"Concord Canada House",'RD Condos'!$H:$H,"3",'RD Condos'!$A:$A,1) | C28: =IFERROR(AVERAGEIFS('RD Condos'!$B:$B,'RD Condos'!$K:$K,"Concord Canada House",'RD Condos'!$H:$H,"3",'RD Condos'!$A:$A,1),"") | D28: =IFERROR(AVERAGEIFS('RD Condos'!$AB:$AB,'RD Condos'!$K:$K,"Concord Canada House",'RD Condos'!$H:$H,"3",'RD Condos'!$A:$A,1),"") | E28: =IFERROR(AVERAGEIFS('RD Condos'!$E:$E,'RD Condos'!$K:$K,"Concord Canada House",'RD Condos'!$H:$H,"3",'RD Condos'!$A:$A,1),"") | F28: =IFERROR(D28*(1+$C$4),"") | J28: ='RD Condos'!B28 | K28: ='RD Condos'!U28 | L28: =IF('RD Condos'!H28="2",1,0) | M28: =IF('RD Condos'!H28="3",1,0) | N28: ='RD Condos'!AB28
J29: ='RD Condos'!B29 | K29: ='RD Condos'!U29 | L29: =IF('RD Condos'!H29="2",1,0) | M29: =IF('RD Condos'!H29="3",1,0) | N29: ='RD Condos'!AB29
A30: SUBJECT RECOMMENDATION (comp $/SF + premium) | J30: ='RD Condos'!B30 | K30: ='RD Condos'!U30 | L30: =IF('RD Condos'!H30="2",1,0) | M30: =IF('RD Condos'!H30="3",1,0) | N30: ='RD Condos'!AB30
A31: Weighted comp $/SF — Concord basis | C31: =E26*$H$2+E27*$H$3+E28*$H$4 | J31: ='RD Condos'!B31 | K31: ='RD Condos'!U31 | L31: =IF('RD Condos'!H31="2",1,0) | M31: =IF('RD Condos'!H31="3",1,0) | N31: ='RD Condos'!AB31
A32: Weighted comp $/SF — all-comp basis | C32: =E20*$H$2+E21*$H$3+E22*$H$4 | J32: ='RD Condos'!B32 | K32: ='RD Condos'!U32 | L32: =IF('RD Condos'!H32="2",1,0) | M32: =IF('RD Condos'!H32="3",1,0) | N32: ='RD Condos'!AB32
A33: Subject rental premium | C33: =C4 | J33: ='RD Condos'!B33 | K33: ='RD Condos'!U33 | L33: =IF('RD Condos'!H33="2",1,0) | M33: =IF('RD Condos'!H33="3",1,0) | N33: ='RD Condos'!AB33
A34: RECOMMENDED subject $/SF (Concord + premium) | C34: =C31*(1+C4) | J34: ='RD Condos'!B34 | K34: ='RD Condos'!U34 | L34: =IF('RD Condos'!H34="2",1,0) | M34: =IF('RD Condos'!H34="3",1,0) | N34: ='RD Condos'!AB34
A35: Subject $/SF (all-comp + premium) | C35: =C32*(1+C4) | J35: ='RD Condos'!B35 | K35: ='RD Condos'!U35 | L35: =IF('RD Condos'!H35="2",1,0) | M35: =IF('RD Condos'!H35="3",1,0) | N35: ='RD Condos'!AB35
A36: Prior model subject | C36: n/a — new subject (no prior model) | J36: ='RD Condos'!B36 | K36: ='RD Condos'!U36 | L36: =IF('RD Condos'!H36="2",1,0) | M36: =IF('RD Condos'!H36="3",1,0) | N36: ='RD Condos'!AB36
A37: Residual vs prior | C37: n/a | J37: ='RD Condos'!B37 | K37: ='RD Condos'!U37 | L37: =IF('RD Condos'!H37="2",1,0) | M37: =IF('RD Condos'!H37="3",1,0) | N37: ='RD Condos'!AB37
J38: ='RD Condos'!B38 | K38: ='RD Condos'!U38 | L38: =IF('RD Condos'!H38="2",1,0) | M38: =IF('RD Condos'!H38="3",1,0) | N38: ='RD Condos'!AB38
J39: ='RD Condos'!B39 | K39: ='RD Condos'!U39 | L39: =IF('RD Condos'!H39="2",1,0) | M39: =IF('RD Condos'!H39="3",1,0) | N39: ='RD Condos'!AB39
J40: ='RD Condos'!B40 | K40: ='RD Condos'!U40 | L40: =IF('RD Condos'!H40="2",1,0) | M40: =IF('RD Condos'!H40="3",1,0) | N40: ='RD Condos'!AB40
...

Sheet RD Condos
A1: Include | B1: Sq Ft. | C1: Rent | D1: Adj. Rent | E1: $/sq ft | F1: Adj. $/sq ft | G1: Adj BD | H1: Beds Number | I1: Den | J1: Date | K1: Building Name | L1: Building Address | M1: Building City | N1: Developer | O1: Unit # | P1: Unit Address | Q1: Beds | R1: Baths | S1: Sqft (Condos.ca) | T1: MLS Size Range | U1: # Parking | V1: Parking Included | W1: Locker | X1: Outdoor Space | Y1: Exposure | Z1: Building Age | AA1: Building Amenities | AB1: Leased Rent ($) | AC1: Listed Rent ($) | AD1: PSF (Calculated) | AE1: PSF (Listing) | AF1: Furnished | AG1: Hydro Included | AH1: Water Included | AI1: Lease Date | AJ1: MLS# | AK1: Listing URL | AL1: Description | AM1: Product Type | AN1: $/SF (Product-Adj) | AO1: Date Scraped
A2: =IF(AND(ISNUMBER(B2),B2>0,ISNUMBER(AB2),AB2>0,J2>=Data_Summary!$C$1),1,0) | B2: 908 | C2: =IF(ISNUMBER(AB2),AB2,"") | D2: =IF(ISNUMBER(C2),C2-U2*Data_Summary!$C$2,"") | E2: =IFERROR(C2/B2,"") | F2: =IFERROR(D2/B2,"") | G2: =Q2 | H2: =IFERROR(LEFT(G2,1),"") | I2: =IF(LEN(G2)>1,1,0) | J2: 46185 | K2: Concord Canada House | L2: 23 Spadina Ave | M2: Toronto (CityPlace) | N2: 2025 | O2: 2505 | P2: 2505 - 23 Spadina Ave | Q2: 3 | R2: 2 | S2: 908 | U2: 1 | V2: Yes | Z2: Built 2025 | AB2: 4300 | AC2: 4300 | AD2: =IFERROR(AB2/B2,"") | AE2: =IFERROR(AC2/B2,"") | AI2: 2026-06-12 | AJ2: C13234234 | AK2: https://condos.ca/toronto/concord-canada-house-23-spadina-ave-1-3-concord-cityplace-way/unit-2505-C13234234 | AL2: Leased comp. Interior SF verified (condos.ca per-unit registered area), the 2026-06-16 pull (re-confirm on live page next run). | AM2: Condo | AN2: =IFERROR(E2*(1+IF(AM2="Apartment",Data_Summary!$C$3,0)),"") | AO2: 46189
A3: =IF(AND(ISNUMBER(B3),B3>0,ISNUMBER(AB3),AB3>0,J3>=Data_Summary!$C$1),1,0) | B3: 1050 | C3: =IF(ISNUMBER(AB3),AB3,"") | D3: =IF(ISNUMBER(C3),C3-U3*Data_Summary!$C$2,"") | E3: =IFERROR(C3/B3,"") | F3: =IFERROR(D3/B3,"") | G3: =Q3 | H3: =IFERROR(LEFT(G3,1),"") | I3: =IF(LEN(G3)>1,1,0) | J3: 46185 | K3: Concord Canada House | L3: 23 Spadina Ave | M3: Toronto (CityPlace) | N3: 2025 | O3: 6201 | P3: 6201 - 23 Spadina Ave | Q3: 2 | R3: 3 | S3: 1050 | U3: 1 | V3: Yes | Z3: Built 2025 | AB3: 4500 | AC3: 4900 | AD3: =IFERROR(AB3/B3,"") | AE3: =IFERROR(AC3/B3,"") | AI3: 2026-06-12 | AJ3: C12939248 | AK3: https://condos.ca/toronto/concord-canada-house-23-spadina-ave-1-3-concord-cityplace-way/unit-6201-C12939248 | AL3: Leased comp. Interior SF verified (condos.ca per-unit registered area), the 2026-06-16 pull (re-confirm on live page next run). | AM3: Condo | AN3: =IFERROR(E3*(1+IF(AM3="Apartment",Data_Summary!$C$3,0)),"") | AO3: 46189
A4: =IF(AND(ISNUMBER(B4),B4>0,ISNUMBER(AB4),AB4>0,J4>=Data_Summary!$C$1),1,0) | B4: 718 | C4: =IF(ISNUMBER(AB4),AB4,"") | D4: =IF(ISNUMBER(C4),C4-U4*Data_Summary!$C$2,"") | E4: =IFERROR(C4/B4,"") | F4: =IFERROR(D4/B4,"") | G4: =Q4 | H4: =IFERROR(LEFT(G4,1),"") | I4: =IF(LEN(G4)>1,1,0) | J4: 46181 | K4: Concord Canada House | L4: 23 Spadina Ave | M4: Toronto (CityPlace) | N4: 2025 | O4: 5611 | P4: 5611 - 23 Spadina Ave | Q4: 2 | R4: 2 | S4: 718 | U4: 1 | V4: Yes | Z4: Built 2025 | AB4: 3500 | AC4: 3400 | AD4: =IFERROR(AB4/B4,"") | AE4: =IFERROR(AC4/B4,"") | AI4: 2026-06-08 | AJ4: C13238978 | AK4: https://condos.ca/toronto/concord-canada-house-23-spadina-ave-1-3-concord-cityplace-way/unit-5611-C13238978 | AL4: Leased comp. Interior SF verified (condos.ca per-unit registered area), the 2026-06-16 pull (re-confirm on live page next run). | AM4: Condo | AN4: =IFERROR(E4*(1+IF(AM4="Apartment",Data_Summary!$C$3,0)),"") | AO4: 46189
A5: =IF(AND(ISNUMBER(B5),B5>0,ISNUMBER(AB5),AB5>0,J5>=Data_Summary!$C$1),1,0) | B5: 692 | C5: =IF(ISNUMBER(AB5),AB5,"") | D5: =IF(ISNUMBER(C5),C5-U5*Data_Summary!$C$2,"") | E5: =IFERROR(C5/B5,"") | F5: =IFERROR(D5/B5,"") | G5: =Q5 | H5: =IFERROR(LEFT(G5,1),"") | I5: =IF(LEN(G5)>1,1,0) | J5: 46178 | K5: Concord Canada House | L5: 23 Spadina Ave | M5: Toronto (CityPlace) | N5: 2025 | O5: 1705 | P5: 1705 - 23 Spadina Ave | Q5: 2 | R5: 2 | S5: 692 | U5: 1 | V5: Yes | Z5: Built 2025 | AB5: 3300 | AC5: 3400 | AD5: =IFERROR(AB5/B5,"") | AE5: =IFERROR(AC5/B5,"") | AI5: 2026-06-05 | AJ5: C13046560 | AK5: https://condos.ca/toronto/concord-canada-house-23-spadina-ave-1-3-concord-cityplace-way/unit-1705-C13046560 | AL5: Leased comp. Interior SF verified (condos.ca per-unit registered area), the 2026-06-16 pull (re-confirm on live page next run). | AM5: Condo | AN5: =IFERROR(E5*(1+IF(AM5="Apartment",Data_Summary!$C$3,0)),"") | AO5: 46189
A6: =IF(AND(ISNUMBER(B6),B6>0,ISNUMBER(AB6),AB6>0,J6>=Data_Summary!$C$1),1,0) | B6: 736 | C6: =IF(ISNUMBER(AB6),AB6,"") | D6: =IF(ISNUMBER(C6),C6-U6*Data_Summary!$C$2,"") | E6: =IFERROR(C6/B6,"") | F6: =IFERROR(D6/B6,"") | G6: =Q6 | H6: =IFERROR(LEFT(G6,1),"") | I6: =IF(LEN(G6)>1,1,0) | J6: 46182 | K6: Concord Canada House | L6: 23 Spadina Ave | M6: Toronto (CityPlace) | N6: 2025 | O6: 312 | P6: 312 - 23 Spadina Ave | Q6: 2 | R6: 2 | S6: 736 | U6: 0 | V6: No | Z6: Built 2025 | AB6: 3050 | AC6: 3150 | AD6: =IFERROR(AB6/B6,"") | AE6: =IFERROR(AC6/B6,"") | AI6: 2026-06-09 | AJ6: C13157296 | AK6: https://condos.ca/toronto/concord-canada-house-23-spadina-ave-1-3-concord-cityplace-way/unit-312-C13157296 | AL6: Leased comp. Interior SF verified (condos.ca per-unit registered area), the 2026-06-16 pull (re-confirm on live page next run). | AM6: Condo | AN6: =IFERROR(E6*(1+IF(AM6="Apartment",Data_Summary!$C$3,0)),"") | AO6: 46189
A7: =IF(AND(ISNUMBER(B7),B7>0,ISNUMBER(AB7),AB7>0,J7>=Data_Summary!$C$1),1,0) | B7: 650 | C7: =IF(ISNUMBER(AB7),AB7,"") | D7: =IF(ISNUMBER(C7),C7-U7*Data_Summary!$C$2,"") | E7: =IFERROR(C7/B7,"") | F7: =IFERROR(D7/B7,"") | G7: =Q7 | H7: =IFERROR(LEFT(G7,1),"") | I7: =IF(LEN(G7)>1,1,0) | J7: 46183 | K7: Concord Canada House | L7: 23 Spadina Ave | M7: Toronto (CityPlace) | N7: 2025 | O7: 2106 | P7: 2106 - 23 Spadina Ave | Q7: 1+1 | R7: 2 | S7: 650 | U7: 0 | V7: No | Z7: Built 2025 | AB7: 2750 | AC7: 2850 | AD7: =IFERROR(AB7/B7,"") | AE7: =IFERROR(AC7/B7,"") | AI7: 2026-06-10 | AJ7: C13217872 | AK7: https://condos.ca/toronto/concord-canada-house-23-spadina-ave-1-3-concord-cityplace-way/unit-2106-C13217872 | AL7: Leased comp. Interior SF verified (condos.ca per-unit registered area), the 2026-06-16 pull (re-confirm on live page next run). | AM7: Condo | AN7: =IFERROR(E7*(1+IF(AM7="Apartment",Data_Summary!$C$3,0)),"") | AO7: 46189
A8: =IF(AND(ISNUMBER(B8),B8>0,ISNUMBER(AB8),AB8>0,J8>=Data_Summary!$C$1),1,0) | B8: 600 | C8: =IF(ISNUMBER(AB8),AB8,"") | D8: =IF(ISNUMBER(C8),C8-U8*Data_Summary!$C$2,"") | E8: =IFERROR(C8/B8,"") | F8: =IFERROR(D8/B8,"") | G8: =Q8 | H8: =IFERROR(LEFT(G8,1),"") | I8: =IF(LEN(G8)>1,1,0) | J8: 46182 | K8: Concord Canada House | L8: 23 Spadina Ave | M8: Toronto (CityPlace) | N8: 2025 | O8: 2608 | P8: 2608 - 23 Spadina Ave | Q8: 1+1 | R8: 1 | S8: 600 | U8: 0 | V8: No | Z8: Built 2025 | AB8: 2800 | AC8: 2850 | AD8: =IFERROR(AB8/B8,"") | AE8: =IFERROR(AC8/B8,"") | AI8: 2026-06-09 | AJ8: C12874476 | AK8: https://condos.ca/toronto/concord-canada-house-23-spadina-ave-1-3-concord-cityplace-way/unit-2608-C12874476 | AL8: Leased comp. Interior SF verified (condos.ca per-unit registered area), the 2026-06-16 pull (re-confirm on live page next run). | AM8: Condo | AN8: =IFERROR(E8*(1+IF(AM8="Apartment",Data_Summary!$C$3,0)),"") | AO8: 46189
A9: =IF(AND(ISNUMBER(B9),B9>0,ISNUMBER(AB9),AB9>0,J9>=Data_Summary!$C$1),1,0) | B9: 578 | C9: =IF(ISNUMBER(AB9),AB9,"") | D9: =IF(ISNUMBER(C9),C9-U9*Data_Summary!$C$2,"") | E9: =IFERROR(C9/B9,"") | F9: =IFERROR(D9/B9,"") | G9: =Q9 | H9: =IFERROR(LEFT(G9,1),"") | I9: =IF(LEN(G9)>1,1,0) | J9: 46178 | K9: Concord Canada House | L9: 23 Spadina Ave | M9: Toronto (CityPlace) | N9: 2025 | O9: 1907 | P9: 1907 - 23 Spadina Ave | Q9: 1 | R9: 1 | S9: 578 | U9: 0 | V9: No | Z9: Built 2025 | AB9: 2500 | AC9: 2500 | AD9: =IFERROR(AB9/B9,"") | AE9: =IFERROR(AC9/B9,"") | AI9: 2026-06-05 | AJ9: C13219416 | AK9: https://condos.ca/toronto/concord-canada-house-23-spadina-ave-1-3-concord-cityplace-way/unit-1907-C13219416 | AL9: Leased comp. Interior SF verified (condos.ca per-unit registered area), the 2026-06-16 pull (re-confirm on live page next run). | AM9: Condo | AN9: =IFERROR(E9*(1+IF(AM9="Apartment",Data_Summary!$C$3,0)),"") | AO9: 46189
A10: =IF(AND(ISNUMBER(B10),B10>0,ISNUMBER(AB10),AB10>0,J10>=Data_Summary!$C$1),1,0) | B10: 505 | C10: =IF(ISNUMBER(AB10),AB10,"") | D10: =IF(ISNUMBER(C10),C10-U10*Data_Summary!$C$2,"") | E10: =IFERROR(C10/B10,"") | F10: =IFERROR(D10/B10,"") | G10: =Q10 | H10: =IFERROR(LEFT(G10,1),"") | I10: =IF(LEN(G10)>1,1,0) | J10: 46177 | K10: Concord Canada House | L10: 23 Spadina Ave | M10: Toronto (CityPlace) | N10: 2025 | O10: 2212 | P10: 2212 - 23 Spadina Ave | Q10: 1 | R10: 1 | S10: 505 | U10: 0 | V10: No | Z10: Built 2025 | AB10: 2300 | AC10: 2300 | AD10: =IFERROR(AB10/B10,"") | AE10: =IFERROR(AC10/B10,"") | AI10: 2026-06-04 | AJ10: C13231928 | AK10: https://condos.ca/toronto/concord-canada-house-23-spadina-ave-1-3-concord-cityplace-way/unit-2212-C13231928 | AL10: Leased comp. Interior SF verified (condos.ca per-unit registered area), the 2026-06-16 pull (re-confirm on live page next run). | AM10: Condo | AN10: =IFERROR(E10*(1+IF(AM10="Apartment",Data_Summary!$C$3,0)),"") | AO10: 46189
