Workbook

Sheet Output
G2: Unit Mix Adjusted1
B3: Building | C3: First Occupancy | D3: Avg.Lease Date | E3: Vacancy | F3: Transaction Count | G3: Avg Suite Size | H3: Adj. Avg. Rent | I3: Avg. Net Rent PSF
B5: Lawrence & Jane St
B6: The Humber | C6: ='Building Summary'!E4 -> 2023 | D6: =IFERROR(AVERAGEIFS('Raw Data'!$J:$J,'Raw Data'!$K:$K,$B6,'Raw Data'!$A:$A,1),"") -> 45996 | F6: ='Building Summary'!J4 -> 22 | G6: ='Building Summary'!K4 -> 761.72727 | H6: =IFERROR(AVERAGEIFS('Raw Data'!$D:$D,'Raw Data'!$K:$K,$B6,'Raw Data'!$A:$A,1),"") -> 2322.9839 | I6: =IFERROR(AVERAGEIFS('Raw Data'!$F:$F,'Raw Data'!$K:$K,$B6,'Raw Data'!$A:$A,1),"") -> 3.0973317
B8: Average | F8: =F6 -> 22 | G8: =G6 -> 761.72727 | H8: =H6 -> 2322.9839 | I8: =I6 -> 3.0973317
B9: PBR Premium | H9: =Data_Summary!C4 -> 0.133 | I9: =Data_Summary!C4 -> 0.133
B10: Implied Untrended Rent | G10: =G8 -> 761.72727 | H10: =IFERROR(H8*(1+H9),"") -> 2631.9408 | I10: =IFERROR(I8*(1+I9),"") -> 3.5092769
B12: Subject Site (Untrended Rent) | G12: =G10 -> 761.72727 | H12: =H10 -> 2631.9408 | I12: =I10 -> 3.5092769
B15: Other Excluded
B16: River Hill (2006) · The Winston House (1976) · Emmett House (1974) — REMOVED per user instruction 2026-06-09; re-offered in fresh shortlist 2026-06-11, not selected.
B17: Shortlisted 2026-06-11, not selected: River Ridge — 1–3 Hickory Tree Rd (1991, 19fl/413u, ~12 recent rentals, exact per-unit SF, ~450 m — NEW candidate) · West22/WestonHub — 22 John St (2020 PBR apt, 30fl/377u, ~300 m — closest vintage but 0 MLS lease records; asking-rent evidence only, would need PBR premium).
B18: Also evaluated & excluded 2026-06-11: Weston On The Humber — 2464 Weston Rd (2007 micro-suites 343–957sf, ~5 leases $1,400–1,850 — segment mismatch) · The Charlton Residences — 1695 Weston Rd (precon condo, 0 rentals) · Weston Gate — 2130 Weston Rd (1978, 75u, 2 leases, bracket-only SF) · Eglinton Park Place — 3559 Eglinton W (1988, ~2.3 km, 2 leases) · Lexington on the Green (2008 low-rise towns — product) · Sidney Belsey 50–74 / W Towns / Riverboat Landing (stacked towns — product) · Humberview Heights (0 rentals) · RioCan Hall 126 John (precon) · 2255/2275 Weston, 1530 Weston, 38 Gibson (non-condo / partial units).
B19: Average | C19: (no excluded-building comps in workbook — group removed)
B20: PBR Premium
B21: Implied Untrended Rent
B23: Weighted Average | F23: =F6 -> 22 | G23: =G6 -> 761.72727 | H23: =H6 -> 2322.9839 | I23: =I6 -> 3.0973317
B24: PBR Premium | H24: =Data_Summary!C4 -> 0.133 | I24: =Data_Summary!C4 -> 0.133
B25: Implied Untrended Rent | G25: =G23 -> 761.72727 | H25: =IFERROR(H23*(1+H24),"") -> 2631.9408 | I25: =IFERROR(I23*(1+I24),"") -> 3.5092769
L27: 1-Bedroom Units | P27: 1-Bedroom + Den Units | T27: 2-Bedroom Units | X27: 3-Bedroom Units
K28: Building | L28: Transaction Count | M28: Avg. Suite Size | N28: Adj. Avg. Rent | O28: Avg. Net Rent PSF | P28: Transaction Count | Q28: Avg. Suite Size | R28: Adj. Avg. Rent | S28: Avg. Net Rent PSF | T28: Transaction Count | U28: Avg. Suite Size | V28: Adj. Avg. Rent | W28: Avg. Net Rent PSF | X28: Transaction Count | Y28: Avg. Suite Size | Z28: Adj. Avg. Rent | AA28: Avg. Net Rent PSF
K29: The Humber | L29: =COUNTIFS('Raw Data'!$Q:$Q,"1",'Raw Data'!$A:$A,1,'Raw Data'!$K:$K,"The Humber") -> 3 | M29: =IFERROR(AVERAGEIFS('Raw Data'!$B:$B,'Raw Data'!$Q:$Q,"1",'Raw Data'!$A:$A,1,'Raw Data'!$K:$K,"The Humber"),"") -> 596.66667 | N29: =IFERROR(AVERAGEIFS('Raw Data'!$D:$D,'Raw Data'!$Q:$Q,"1",'Raw Data'!$A:$A,1,'Raw Data'!$K:$K,"The Humber"),"") -> 1967.3321 | O29: =IFERROR(AVERAGEIFS('Raw Data'!$F:$F,'Raw Data'!$Q:$Q,"1",'Raw Data'!$A:$A,1,'Raw Data'!$K:$K,"The Humber"),"") -> 3.3110991 | P29: =COUNTIFS('Raw Data'!$Q:$Q,"1+1",'Raw Data'!$A:$A,1,'Raw Data'!$K:$K,"The Humber") -> 7 | Q29: =IFERROR(AVERAGEIFS('Raw Data'!$B:$B,'Raw Data'!$Q:$Q,"1+1",'Raw Data'!$A:$A,1,'Raw Data'!$K:$K,"The Humber"),"") -> 651.57143 | R29: =IFERROR(AVERAGEIFS('Raw Data'!$D:$D,'Raw Data'!$Q:$Q,"1+1",'Raw Data'!$A:$A,1,'Raw Data'!$K:$K,"The Humber"),"") -> 2071.7138 | S29: =IFERROR(AVERAGEIFS('Raw Data'!$F:$F,'Raw Data'!$Q:$Q,"1+1",'Raw Data'!$A:$A,1,'Raw Data'!$K:$K,"The Humber"),"") -> 3.2064122 | T29: =COUNTIFS('Raw Data'!$H:$H,"2",'Raw Data'!$A:$A,1,'Raw Data'!$K:$K,"The Humber") -> 7 | U29: =IFERROR(AVERAGEIFS('Raw Data'!$B:$B,'Raw Data'!$H:$H,"2",'Raw Data'!$A:$A,1,'Raw Data'!$K:$K,"The Humber"),"") -> 760 | V29: =IFERROR(AVERAGEIFS('Raw Data'!$D:$D,'Raw Data'!$H:$H,"2",'Raw Data'!$A:$A,1,'Raw Data'!$K:$K,"The Humber"),"") -> 2354.4275 | W29: =IFERROR(AVERAGEIFS('Raw Data'!$F:$F,'Raw Data'!$H:$H,"2",'Raw Data'!$A:$A,1,'Raw Data'!$K:$K,"The Humber"),"") -> 3.1065216 | X29: =COUNTIFS('Raw Data'!$H:$H,"3",'Raw Data'!$A:$A,1,'Raw Data'!$K:$K,"The Humber") -> 5 | Y29: =IFERROR(AVERAGEIFS('Raw Data'!$B:$B,'Raw Data'!$H:$H,"3",'Raw Data'!$A:$A,1,'Raw Data'!$K:$K,"The Humber"),"") -> 1017.4 | Z29: =IFERROR(AVERAGEIFS('Raw Data'!$D:$D,'Raw Data'!$H:$H,"3",'Raw Data'!$A:$A,1,'Raw Data'!$K:$K,"The Humber"),"") -> 2844.1323 | AA29: =IFERROR(AVERAGEIFS('Raw Data'!$F:$F,'Raw Data'!$H:$H,"3",'Raw Data'!$A:$A,1,'Raw Data'!$K:$K,"The Humber"),"") -> 2.8034929
K31: Weighted Avg. | L31: =COUNTIFS('Raw Data'!$Q:$Q,"1",'Raw Data'!$A:$A,1) -> 3 | M31: =IFERROR(AVERAGEIFS('Raw Data'!$B:$B,'Raw Data'!$Q:$Q,"1",'Raw Data'!$A:$A,1),"") -> 596.66667 | N31: =IFERROR(AVERAGEIFS('Raw Data'!$D:$D,'Raw Data'!$Q:$Q,"1",'Raw Data'!$A:$A,1),"") -> 1967.3321 | O31: =IFERROR(AVERAGEIFS('Raw Data'!$F:$F,'Raw Data'!$Q:$Q,"1",'Raw Data'!$A:$A,1),"") -> 3.3110991 | P31: =COUNTIFS('Raw Data'!$Q:$Q,"1+1",'Raw Data'!$A:$A,1) -> 7 | Q31: =IFERROR(AVERAGEIFS('Raw Data'!$B:$B,'Raw Data'!$Q:$Q,"1+1",'Raw Data'!$A:$A,1),"") -> 651.57143 | R31: =IFERROR(AVERAGEIFS('Raw Data'!$D:$D,'Raw Data'!$Q:$Q,"1+1",'Raw Data'!$A:$A,1),"") -> 2071.7138 | S31: =IFERROR(AVERAGEIFS('Raw Data'!$F:$F,'Raw Data'!$Q:$Q,"1+1",'Raw Data'!$A:$A,1),"") -> 3.2064122 | T31: =COUNTIFS('Raw Data'!$H:$H,"2",'Raw Data'!$A:$A,1) -> 7 | U31: =IFERROR(AVERAGEIFS('Raw Data'!$B:$B,'Raw Data'!$H:$H,"2",'Raw Data'!$A:$A,1),"") -> 760 | V31: =IFERROR(AVERAGEIFS('Raw Data'!$D:$D,'Raw Data'!$H:$H,"2",'Raw Data'!$A:$A,1),"") -> 2354.4275 | W31: =IFERROR(AVERAGEIFS('Raw Data'!$F:$F,'Raw Data'!$H:$H,"2",'Raw Data'!$A:$A,1),"") -> 3.1065216 | X31: =COUNTIFS('Raw Data'!$H:$H,"3",'Raw Data'!$A:$A,1) -> 5 | Y31: =IFERROR(AVERAGEIFS('Raw Data'!$B:$B,'Raw Data'!$H:$H,"3",'Raw Data'!$A:$A,1),"") -> 1017.4 | Z31: =IFERROR(AVERAGEIFS('Raw Data'!$D:$D,'Raw Data'!$H:$H,"3",'Raw Data'!$A:$A,1),"") -> 2844.1323 | AA31: =IFERROR(AVERAGEIFS('Raw Data'!$F:$F,'Raw Data'!$H:$H,"3",'Raw Data'!$A:$A,1),"") -> 2.8034929
K32: Low | O32: =SUMPRODUCT(MIN(IF((('Raw Data'!$Q$2:$Q$34="1")*('Raw Data'!$A$2:$A$34=1)),'Raw Data'!$F$2:$F$34))) -> 3.0253897 | S32: =SUMPRODUCT(MIN(IF((('Raw Data'!$Q$2:$Q$34="1+1")*('Raw Data'!$A$2:$A$34=1)),'Raw Data'!$F$2:$F$34))) -> 2.7962716 | W32: =SUMPRODUCT(MIN(IF((('Raw Data'!$H$2:$H$34="2")*('Raw Data'!$A$2:$A$34=1)),'Raw Data'!$F$2:$F$34))) -> 2.9411765 | AA32: =SUMPRODUCT(MIN(IF((('Raw Data'!$H$2:$H$34="3")*('Raw Data'!$A$2:$A$34=1)),'Raw Data'!$F$2:$F$34))) -> 2.5265775
K33: High | O33: =SUMPRODUCT(MAX(IF((('Raw Data'!$Q$2:$Q$34="1")*('Raw Data'!$A$2:$A$34=1)),'Raw Data'!$F$2:$F$34))) -> 3.7188227 | S33: =SUMPRODUCT(MAX(IF((('Raw Data'!$Q$2:$Q$34="1+1")*('Raw Data'!$A$2:$A$34=1)),'Raw Data'!$F$2:$F$34))) -> 3.5714286 | W33: =SUMPRODUCT(MAX(IF((('Raw Data'!$H$2:$H$34="2")*('Raw Data'!$A$2:$A$34=1)),'Raw Data'!$F$2:$F$34))) -> 3.3395755 | AA33: =SUMPRODUCT(MAX(IF((('Raw Data'!$H$2:$H$34="3")*('Raw Data'!$A$2:$A$34=1)),'Raw Data'!$F$2:$F$34))) -> 3.1049245
K35: PBR Premium | O35: =Data_Summary!C4 -> 0.133 | S35: =Data_Summary!C4 -> 0.133 | W35: =Data_Summary!C4 -> 0.133 | AA35: =Data_Summary!C4 -> 0.133
K36: Weighted Avg. | N36: =IFERROR(N31*(1+O35),"") -> 2228.9873 | O36: =IFERROR(O31*(1+O35),"") -> 3.7514753 | R36: =IFERROR(R31*(1+S35),"") -> 2347.2517 | S36: =IFERROR(S31*(1+S35),"") -> 3.632865 | V36: =IFERROR(V31*(1+W35),"") -> 2667.5664 | W36: =IFERROR(W31*(1+W35),"") -> 3.519689 | Z36: =IFERROR(Z31*(1+AA35),"") -> 3222.4019 | AA36: =IFERROR(AA31*(1+AA35),"") -> 3.1763574
K37: Weighted Avg. Building Total (Comps) | L37: =IFERROR((N31*0.3+R31*0.16+V31*0.45+Z31*0.09)*446,"") -> 997763.6
K39: Subject Property (Using Comp $ Rent) | N39: =IFERROR(N36,"") -> 2228.9873 | R39: =IFERROR(R36,"") -> 2347.2517 | V39: =IFERROR(V36,"") -> 2667.5664 | Z39: =IFERROR(Z36,"") -> 3222.4019
K40: Subject Property Rent Building Total | L40: =IFERROR((N39*0.3+R39*0.16+V39*0.45+Z39*0.09)*446,"") -> 1130466.2
K42: Subject Property (Using Comp PSF Rent) | N42: =IFERROR(O36*M31,"") -> 2238.3803 | R42: =IFERROR(S36*Q31,"") -> 2367.0711 | V42: =IFERROR(W36*U31,"") -> 2674.9636 | Z42: =IFERROR(AA36*Y31,"") -> 3231.6261
K43: Subject Property PSF Rent Building Total | L43: =IFERROR((N42*0.3+R42*0.16+V42*0.45+Z42*0.09)*446,"") -> 1134992.1
K45: Subject Property Rent | N45: =IFERROR(AVERAGE(N39,N42),"") -> 2233.6838 | R45: =IFERROR(AVERAGE(R39,R42),"") -> 2357.1614 | V45: =IFERROR(AVERAGE(V39,V42),"") -> 2671.265 | Z45: =IFERROR(AVERAGE(Z39,Z42),"") -> 3227.014
K46: Subject Property Rent Building Total | L46: =IFERROR((N45*0.3+R45*0.16+V45*0.45+Z45*0.09)*446,"") -> 1132729.1
K48: Regression:
K49: Coefficients:
K50: Total Building coefficient | L50: 0 | M50: ← input from regression model (Predictor sheet)
K52: Subject Property Rent (Increase)
K53: Subject Property Rent
N56: Unadjusted | V56: Unadjusted | Z56: Unadjusted
K57: TRREB Data (Q1 2026) | N57: Rent | V57: Rent | Z57: Rent
...

Sheet Subject & Conclusion
A1: ★ TLDR — RECOMMENDED RENT · Hickory Tree Tower Condos
A2: Subject = current comp evidence (The Humber, 2023, ~250 m) grossed up by your new-build / lease-up premium. Comp set: The Humber ONLY (user instruction 2026-06-09; re-confirmed via fresh shortlist 2026-06-11). Confidence: HIGH.
A4: RECOMMENDED SUBJECT RENT ($/SF) | C4: =Data_Summary!C25 -> 3.7121188
A5: Basis: Humber comp $/SF (Data_Summary!C25) x (1 + premium Data_Summary!C4)
A6: Conservative basis (all-comp + premium) | C6: =Data_Summary!C26 -> 3.7121188
A8: RECOMMENDED MONTHLY RENT — by suite type (subject = Humber comp + premium)
A9: Suite type | B9: Avg SF | C9: Recommended Rent
A10: 1-Bed / 1+Den | B10: =Data_Summary!C17 -> 635.1 | C10: =Data_Summary!F17 -> 2401.7334
A11: 2-Bed | B11: =Data_Summary!C18 -> 760 | C11: =Data_Summary!F18 -> 2796.0821
A12: 3-Bed | B12: =Data_Summary!C19 -> 1017.4 | C12: =Data_Summary!F19 -> 3342.35
A14: Custom suite — enter size (sq ft) → | D14: 700
A15: Implied rent @ recommended subject $/SF | D15: =IFERROR(D14*Data_Summary!C25,"") -> 2598.4832
A16: Implied rent @ raw comp $/SF (no premium) | D16: =IFERROR(D14*Data_Summary!C22,"") -> 2293.4538
A18: WHY THIS DIFFERS FROM YOUR PRIOR ~$3.90/SF
A19: Current-market comp $/SF — The Humber (2026 leases) | C19: =Data_Summary!C22 -> 3.2763626 | D19: market evidence today
A20: + New-build / lease-up premium | C20: =Data_Summary!C4 -> 0.133 | D20: your prior model assumption
A21: Recommended subject $/SF (current market) | C21: =Data_Summary!C25 -> 3.7121188 | D21: this workbook
A22: Your prior subject $/SF (2024-rent anchored) | C22: =Data_Summary!C27 -> 3.9 | D22: Data_Old "Wilby figures"
A23: Residual vs prior | C23: =Data_Summary!C28 -> -0.048174666 | D23: ~ rent softening 2024-2026 + comp-mix/den-grouping
A25: Validation: Humber 2-Bed $/SF = $3.26 vs your prior "Wilby" 2-Bed $3.25 — method ties out; gap to $3.90 is premium + market timing, not the comps.
A27: Confidence colours (Raw Data / Building Summary):
A28: High = leased in-window, SF verified per-unit
A29: Med = active/asking, older lease, or minor SF caveat
A30: Low = SF estimate/bracket only, or partial-unit
A32: Comp-derived detail (raw $/SF, before premium)
A33: Benchmark | B33: Avg SF | C33: Avg Leased Rent | D33: Avg $/SF | E33: Note
A34: The Humber only (new build, 2023) | B34: ='Building Summary'!K4 -> 761.72727 | C34: ='Building Summary'!L4 -> 2419.2273 | D34: ='Building Summary'!M4 -> 3.2275713 | E34: PRIMARY
A35: 1-Bed (all comps, den-incl.) | B35: =Data_Summary!C11 -> 635.1 | C35: =Data_Summary!D11 -> 2119.8 | D35: =Data_Summary!E11 -> 3.3662428
A36: 2-Bed (all comps) | B36: =Data_Summary!C12 -> 760 | C36: =Data_Summary!D12 -> 2467.8571 | D36: =Data_Summary!E12 -> 3.2583221
A37: 3-Bed (all comps) | B37: =Data_Summary!C13 -> 1017.4 | C37: =Data_Summary!D13 -> 2950 | D37: =Data_Summary!E13 -> 2.9071769
A39: • Subject: Hickory Tree Tower — Arkfield/A1, DIALOG, 38 storeys/446 suites, 1736-1746 Weston Rd (Planning Phase).
A40: • Parking adjustment is OLS-derived (Data_Summary C2 = regression coefficient, ~$140/spot), not a copied figure.
A41: • Colour rule: dark blue = hardcoded input, grey = formula, green = pulled from another sheet.
A42: • The Humber SF re-verified per-unit 2026-06-11 (every leased/active row opened; incl. unit 101, 1,135 sf). Fresh area shortlist 2026-06-11: River Ridge + West22 newly evaluated; user kept Humber-only set. Two new actives added (1102 $2,400 · 1004 $2,200).
A43: • Definitive SF source: registered declaration / suite-area schedule (Humber=TSCC-2982) or MPAC.

Sheet Building Summary
A1: Comp Building Summary — Hickory Tree Tower (1736-1746 Weston Rd)
A3: Building | B3: Address | C3: Area | D3: Developer | E3: First Occupancy | F3: Yr Built | G3: Product | H3: Storeys | I3: Units | J3: Transaction Count | K3: Avg SF | L3: Avg Rent | M3: Avg $/SF
A4: The Humber | B4: 10 Wilby Crescent | C4: Weston | D4: Options for Homes | E4: 2023 | F4: 2023 | G4: Condo | H4: 22 | I4: 232 | J4: =COUNTIFS('Raw Data'!$K:$K,$A4,'Raw Data'!$A:$A,1) -> 22 | K4: =IFERROR(AVERAGEIFS('Raw Data'!$B:$B,'Raw Data'!$K:$K,$A4,'Raw Data'!$A:$A,1),"") -> 761.72727 | L4: =IFERROR(AVERAGEIFS('Raw Data'!$AB:$AB,'Raw Data'!$K:$K,$A4,'Raw Data'!$A:$A,1),"") -> 2419.2273 | M4: =IFERROR(AVERAGEIFS('Raw Data'!$E:$E,'Raw Data'!$K:$K,$A4,'Raw Data'!$A:$A,1),"") -> 3.2275713
A5: ALL COMPS | J5: =SUM(J4) -> 22 | K5: =IFERROR(AVERAGEIFS('Raw Data'!$B:$B,'Raw Data'!$A:$A,1),"") -> 761.72727 | L5: =IFERROR(AVERAGEIFS('Raw Data'!$AB:$AB,'Raw Data'!$A:$A,1),"") -> 2419.2273 | M5: =IFERROR(AVERAGEIFS('Raw Data'!$AN:$AN,'Raw Data'!$A:$A,1),"") -> 3.2275713

Sheet Data_Summary
B1: Date Filter (include leases on/after) | C1: 45778 | G1: Subject unit mix — auto-derived from Floor Plans SUBJECT plan rows when present; else manual sourced mix in P7:Q10 (this subject is pre-construction — manual, sourced). See derivation block at P1. Never a bare constant. | J1: Parking regression helper (OLS): X = SF, Parking, 2-bed, 3-bed ; Y = Rent (leased rows 2-27) | P1: SUBJECT UNIT-MIX DERIVATION (provenance — never a bare constant)
B2: Parking Adjustment ($/spot/mo) — OLS-derived | C2: =INDEX(LINEST(N2:N27,J2:M27,TRUE(),FALSE()),1,3) -> 132.33457 | D2: OLS parking coefficient — live LINEST on the 26 Humber leased rows (controls: SF, 2bd/3bd dummies). Recomputes with the data. | G2: 1BR wt | H2: =IF($Q$5>0,$Q$2/$Q$5,$Q$8) -> 0.46 | J2: ='Raw Data'!B2 -> 694 | K2: ='Raw Data'!U2 -> 1 | L2: =IF('Raw Data'!H2="2",1,0) -> 1 | M2: =IF('Raw Data'!H2="3",1,0) -> 0 | N2: ='Raw Data'!AB2 -> 2450 | P2: 1BR + studio plans (Floor Plans SUBJECT rows) | Q2: =COUNTIFS('Floor Plans'!$A:$A,"*(SUBJECT)*",'Floor Plans'!$E:$E,"1*")+COUNTIFS('Floor Plans'!$A:$A,"*(SUBJECT)*",'Floor Plans'!$E:$E,"0*") -> 0
B3: Apartment / PBR premium (apt comps only) | C3: 0 | D3: 0 = off (no purpose-built-apartment comps in set) | G3: 2BR wt | H3: =IF($Q$5>0,$Q$3/$Q$5,$Q$9) -> 0.45 | J3: ='Raw Data'!B3 -> 694 | K3: ='Raw Data'!U3 -> 0 | L3: =IF('Raw Data'!H3="2",1,0) -> 0 | M3: =IF('Raw Data'!H3="3",1,0) -> 0 | N3: ='Raw Data'!AB3 -> 2000 | P3: 2BR plans | Q3: =COUNTIFS('Floor Plans'!$A:$A,"*(SUBJECT)*",'Floor Plans'!$E:$E,"2*") -> 0
B4: Subject rental premium (new-build / lease-up) | C4: 0.133 | D4: from prior Hickory model (Data_Old): +12.4-13.3%. Tunable. | G4: 3BR wt | H4: =IF($Q$5>0,$Q$4/$Q$5,$Q$10) -> 0.09 | J4: ='Raw Data'!B4 -> 715 | K4: ='Raw Data'!U4 -> 1 | L4: =IF('Raw Data'!H4="2",1,0) -> 1 | M4: =IF('Raw Data'!H4="3",1,0) -> 0 | N4: ='Raw Data'!AB4 -> 2350 | P4: 3BR plans | Q4: =COUNTIFS('Floor Plans'!$A:$A,"*(SUBJECT)*",'Floor Plans'!$E:$E,"3*") -> 0
A5: Comp building rollup (included leases) | J5: ='Raw Data'!B5 -> 617 | K5: ='Raw Data'!U5 -> 1 | L5: =IF('Raw Data'!H5="2",1,0) -> 0 | M5: =IF('Raw Data'!H5="3",1,0) -> 0 | N5: ='Raw Data'!AB5 -> 1999 | P5: Total subject plans found | Q5: =Q2+Q3+Q4 -> 0
A6: Building | B6: Address | C6: Built | D6: Incl. | E6: Avg SF | F6: Avg Rent | G6: Avg $/SF | J6: ='Raw Data'!B6 -> 751 | K6: ='Raw Data'!U6 -> 0 | L6: =IF('Raw Data'!H6="2",1,0) -> 0 | M6: =IF('Raw Data'!H6="3",1,0) -> 0 | N6: ='Raw Data'!AB6 -> 2100 | P6: Mode | Q6: =IF(Q5>0,"LIVE plan-count from Floor Plans (studios->1BR)","MANUAL sourced mix (Q8:Q10)") -> MANUAL sourced mix (Q8:Q10)
A7: The Humber | B7: 10 Wilby Crescent | C7: Built 2023 (3 yrs) | D7: =COUNTIFS('Raw Data'!$K:$K,$A7,'Raw Data'!$A:$A,1) -> 22 | E7: =IFERROR(AVERAGEIFS('Raw Data'!$B:$B,'Raw Data'!$K:$K,$A7,'Raw Data'!$A:$A,1),"") -> 761.72727 | F7: =IFERROR(AVERAGEIFS('Raw Data'!$AB:$AB,'Raw Data'!$K:$K,$A7,'Raw Data'!$A:$A,1),"") -> 2419.2273 | G7: =IFERROR(AVERAGEIFS('Raw Data'!$E:$E,'Raw Data'!$K:$K,$A7,'Raw Data'!$A:$A,1),"") -> 3.2275713 | J7: ='Raw Data'!B7 -> 816 | K7: ='Raw Data'!U7 -> 1 | L7: =IF('Raw Data'!H7="2",1,0) -> 1 | M7: =IF('Raw Data'!H7="3",1,0) -> 0 | N7: ='Raw Data'!AB7 -> 2575 | P7: Manual mix source (used only when no SUBJECT plans tagged) | Q7: Hickory Tree Tower planned mix 30/16/45/9 (1B/1+Den/2B/3B), den folded into 1BR -> 46/45/9. Source: subject 446-suite / 38-storey program (A1 Development / Arkfield). Pre-construction: no subject plans in Floor Plans (comp = The Humber only), so not derivable here. Confirm vs developer suite schedule.
A8: ALL COMPS | D8: =COUNTIFS('Raw Data'!$A:$A,1) -> 22 | E8: =IFERROR(AVERAGEIFS('Raw Data'!$B:$B,'Raw Data'!$A:$A,1),"") -> 761.72727 | F8: =IFERROR(AVERAGEIFS('Raw Data'!$AB:$AB,'Raw Data'!$A:$A,1),"") -> 2419.2273 | G8: =IFERROR(AVERAGEIFS('Raw Data'!$AN:$AN,'Raw Data'!$A:$A,1),"") -> 3.2275713 | J8: ='Raw Data'!B8 -> 583 | K8: ='Raw Data'!U8 -> 1 | L8: =IF('Raw Data'!H8="2",1,0) -> 0 | M8: =IF('Raw Data'!H8="3",1,0) -> 0 | N8: ='Raw Data'!AB8 -> 2200 | P8: Manual 1BR wt | Q8: 0.46
A9: By Bedroom — all comps (den-incl.) | J9: ='Raw Data'!B9 -> 988 | K9: ='Raw Data'!U9 -> 0 | L9: =IF('Raw Data'!H9="2",1,0) -> 0 | M9: =IF('Raw Data'!H9="3",1,0) -> 1 | N9: ='Raw Data'!AB9 -> 2550 | P9: Manual 2BR wt | Q9: 0.45
A10: Beds | B10: Incl. | C10: Avg SF | D10: Avg Rent | E10: Avg $/SF | J10: ='Raw Data'!B10 -> 694 | K10: ='Raw Data'!U10 -> 1 | L10: =IF('Raw Data'!H10="2",1,0) -> 0 | M10: =IF('Raw Data'!H10="3",1,0) -> 0 | N10: ='Raw Data'!AB10 -> 2199 | P10: Manual 3BR wt | Q10: 0.09
A11: 1 Bed | B11: =COUNTIFS('Raw Data'!$H:$H,"1",'Raw Data'!$A:$A,1) -> 10 | C11: =IFERROR(AVERAGEIFS('Raw Data'!$B:$B,'Raw Data'!$H:$H,"1",'Raw Data'!$A:$A,1),"") -> 635.1 | D11: =IFERROR(AVERAGEIFS('Raw Data'!$AB:$AB,'Raw Data'!$H:$H,"1",'Raw Data'!$A:$A,1),"") -> 2119.8 | E11: =IFERROR(AVERAGEIFS('Raw Data'!$AN:$AN,'Raw Data'!$H:$H,"1",'Raw Data'!$A:$A,1),"") -> 3.3662428 | J11: ='Raw Data'!B11 -> 588 | K11: ='Raw Data'!U11 -> 0 | L11: =IF('Raw Data'!H11="2",1,0) -> 0 | M11: =IF('Raw Data'!H11="3",1,0) -> 0 | N11: ='Raw Data'!AB11 -> 2100 | P11: Weights below auto-switch: derived if plans tagged, else manual.
A12: 2 Bed | B12: =COUNTIFS('Raw Data'!$H:$H,"2",'Raw Data'!$A:$A,1) -> 7 | C12: =IFERROR(AVERAGEIFS('Raw Data'!$B:$B,'Raw Data'!$H:$H,"2",'Raw Data'!$A:$A,1),"") -> 760 | D12: =IFERROR(AVERAGEIFS('Raw Data'!$AB:$AB,'Raw Data'!$H:$H,"2",'Raw Data'!$A:$A,1),"") -> 2467.8571 | E12: =IFERROR(AVERAGEIFS('Raw Data'!$AN:$AN,'Raw Data'!$H:$H,"2",'Raw Data'!$A:$A,1),"") -> 3.2583221 | J12: ='Raw Data'!B12 -> 1135 | K12: ='Raw Data'!U12 -> 1 | L12: =IF('Raw Data'!H12="2",1,0) -> 0 | M12: =IF('Raw Data'!H12="3",1,0) -> 1 | N12: ='Raw Data'!AB12 -> 3000
A13: 3 Bed | B13: =COUNTIFS('Raw Data'!$H:$H,"3",'Raw Data'!$A:$A,1) -> 5 | C13: =IFERROR(AVERAGEIFS('Raw Data'!$B:$B,'Raw Data'!$H:$H,"3",'Raw Data'!$A:$A,1),"") -> 1017.4 | D13: =IFERROR(AVERAGEIFS('Raw Data'!$AB:$AB,'Raw Data'!$H:$H,"3",'Raw Data'!$A:$A,1),"") -> 2950 | E13: =IFERROR(AVERAGEIFS('Raw Data'!$AN:$AN,'Raw Data'!$H:$H,"3",'Raw Data'!$A:$A,1),"") -> 2.9071769 | J13: ='Raw Data'!B13 -> 694 | K13: ='Raw Data'!U13 -> 1 | L13: =IF('Raw Data'!H13="2",1,0) -> 1 | M13: =IF('Raw Data'!H13="3",1,0) -> 0 | N13: ='Raw Data'!AB13 -> 2400
J14: ='Raw Data'!B14 -> 788 | K14: ='Raw Data'!U14 -> 1 | L14: =IF('Raw Data'!H14="2",1,0) -> 1 | M14: =IF('Raw Data'!H14="3",1,0) -> 0 | N14: ='Raw Data'!AB14 -> 2600
A15: By Bedroom — The Humber only (new-build basis) | J15: ='Raw Data'!B15 -> 988 | K15: ='Raw Data'!U15 -> 1 | L15: =IF('Raw Data'!H15="2",1,0) -> 0 | M15: =IF('Raw Data'!H15="3",1,0) -> 1 | N15: ='Raw Data'!AB15 -> 3000
A16: Beds | B16: Incl. | C16: Avg SF | D16: Avg Rent | E16: $/SF | F16: Subj Rent (+prem) | J16: ='Raw Data'!B16 -> 556 | K16: ='Raw Data'!U16 -> 1 | L16: =IF('Raw Data'!H16="2",1,0) -> 0 | M16: =IF('Raw Data'!H16="3",1,0) -> 0 | N16: ='Raw Data'!AB16 -> 2200
A17: 1 Bed | B17: =COUNTIFS('Raw Data'!$K:$K,"The Humber",'Raw Data'!$H:$H,"1",'Raw Data'!$A:$A,1) -> 10 | C17: =IFERROR(AVERAGEIFS('Raw Data'!$B:$B,'Raw Data'!$K:$K,"The Humber",'Raw Data'!$H:$H,"1",'Raw Data'!$A:$A,1),"") -> 635.1 | D17: =IFERROR(AVERAGEIFS('Raw Data'!$AB:$AB,'Raw Data'!$K:$K,"The Humber",'Raw Data'!$H:$H,"1",'Raw Data'!$A:$A,1),"") -> 2119.8 | E17: =IFERROR(AVERAGEIFS('Raw Data'!$E:$E,'Raw Data'!$K:$K,"The Humber",'Raw Data'!$H:$H,"1",'Raw Data'!$A:$A,1),"") -> 3.3662428 | F17: =IFERROR(D17*(1+$C$4),"") -> 2401.7334 | J17: ='Raw Data'!B17 -> 988 | K17: ='Raw Data'!U17 -> 1 | L17: =IF('Raw Data'!H17="2",1,0) -> 0 | M17: =IF('Raw Data'!H17="3",1,0) -> 1 | N17: ='Raw Data'!AB17 -> 3000
A18: 2 Bed | B18: =COUNTIFS('Raw Data'!$K:$K,"The Humber",'Raw Data'!$H:$H,"2",'Raw Data'!$A:$A,1) -> 7 | C18: =IFERROR(AVERAGEIFS('Raw Data'!$B:$B,'Raw Data'!$K:$K,"The Humber",'Raw Data'!$H:$H,"2",'Raw Data'!$A:$A,1),"") -> 760 | D18: =IFERROR(AVERAGEIFS('Raw Data'!$AB:$AB,'Raw Data'!$K:$K,"The Humber",'Raw Data'!$H:$H,"2",'Raw Data'!$A:$A,1),"") -> 2467.8571 | E18: =IFERROR(AVERAGEIFS('Raw Data'!$E:$E,'Raw Data'!$K:$K,"The Humber",'Raw Data'!$H:$H,"2",'Raw Data'!$A:$A,1),"") -> 3.2583221 | F18: =IFERROR(D18*(1+$C$4),"") -> 2796.0821 | J18: ='Raw Data'!B18 -> 663 | K18: ='Raw Data'!U18 -> 1 | L18: =IF('Raw Data'!H18="2",1,0) -> 0 | M18: =IF('Raw Data'!H18="3",1,0) -> 0 | N18: ='Raw Data'!AB18 -> 2300
A19: 3 Bed | B19: =COUNTIFS('Raw Data'!$K:$K,"The Humber",'Raw Data'!$H:$H,"3",'Raw Data'!$A:$A,1) -> 5 | C19: =IFERROR(AVERAGEIFS('Raw Data'!$B:$B,'Raw Data'!$K:$K,"The Humber",'Raw Data'!$H:$H,"3",'Raw Data'!$A:$A,1),"") -> 1017.4 | D19: =IFERROR(AVERAGEIFS('Raw Data'!$AB:$AB,'Raw Data'!$K:$K,"The Humber",'Raw Data'!$H:$H,"3",'Raw Data'!$A:$A,1),"") -> 2950 | E19: =IFERROR(AVERAGEIFS('Raw Data'!$E:$E,'Raw Data'!$K:$K,"The Humber",'Raw Data'!$H:$H,"3",'Raw Data'!$A:$A,1),"") -> 2.9071769 | F19: =IFERROR(D19*(1+$C$4),"") -> 3342.35 | J19: ='Raw Data'!B19 -> 588 | K19: ='Raw Data'!U19 -> 0 | L19: =IF('Raw Data'!H19="2",1,0) -> 0 | M19: =IF('Raw Data'!H19="3",1,0) -> 0 | N19: ='Raw Data'!AB19 -> 2000
J20: ='Raw Data'!B20 -> 988 | K20: ='Raw Data'!U20 -> 1 | L20: =IF('Raw Data'!H20="2",1,0) -> 0 | M20: =IF('Raw Data'!H20="3",1,0) -> 1 | N20: ='Raw Data'!AB20 -> 3200
A21: SUBJECT RECOMMENDATION (comp $/SF + premium) | J21: ='Raw Data'!B21 -> 797 | K21: ='Raw Data'!U21 -> 1 | L21: =IF('Raw Data'!H21="2",1,0) -> 1 | M21: =IF('Raw Data'!H21="3",1,0) -> 0 | N21: ='Raw Data'!AB21 -> 2500
A22: Weighted comp $/SF — Humber basis | C22: =E17*$H$2+E18*$H$3+E19*$H$4 -> 3.2763626 | J22: ='Raw Data'!B22 -> 816 | K22: ='Raw Data'!U22 -> 0 | L22: =IF('Raw Data'!H22="2",1,0) -> 1 | M22: =IF('Raw Data'!H22="3",1,0) -> 0 | N22: ='Raw Data'!AB22 -> 2400
A23: Weighted comp $/SF — all-comp basis | C23: =E11*$H$2+E12*$H$3+E13*$H$4 -> 3.2763626 | J23: ='Raw Data'!B23 -> 617 | K23: ='Raw Data'!U23 -> 1 | L23: =IF('Raw Data'!H23="2",1,0) -> 0 | M23: =IF('Raw Data'!H23="3",1,0) -> 0 | N23: ='Raw Data'!AB23 -> 2100
A24: Subject rental premium | C24: =C4 -> 0.133 | J24: ='Raw Data'!B24 -> 751 | K24: ='Raw Data'!U24 -> 1 | L24: =IF('Raw Data'!H24="2",1,0) -> 1 | M24: =IF('Raw Data'!H24="3",1,0) -> 0 | N24: ='Raw Data'!AB24 -> 2500
A25: RECOMMENDED subject $/SF (Humber + premium) | C25: =C22*(1+C4) -> 3.7121188 | J25: ='Raw Data'!B25 -> 694 | K25: ='Raw Data'!U25 -> 1 | L25: =IF('Raw Data'!H25="2",1,0) -> 1 | M25: =IF('Raw Data'!H25="3",1,0) -> 0 | N25: ='Raw Data'!AB25 -> 2400
A26: Subject $/SF (all-comp + premium) | C26: =C23*(1+C4) -> 3.7121188 | J26: ='Raw Data'!B26 -> 715 | K26: ='Raw Data'!U26 -> 0 | L26: =IF('Raw Data'!H26="2",1,0) -> 1 | M26: =IF('Raw Data'!H26="3",1,0) -> 0 | N26: ='Raw Data'!AB26 -> 2600
A27: Prior model subject (Data_Old, 2024-anchored) | C27: 3.9 | J27: ='Raw Data'!B27 -> 694 | K27: ='Raw Data'!U27 -> 0 | L27: =IF('Raw Data'!H27="2",1,0) -> 0 | M27: =IF('Raw Data'!H27="3",1,0) -> 0 | N27: ='Raw Data'!AB27 -> 2150
A28: Residual vs prior (market timing etc.) | C28: =C25/C27-1 -> -0.048174666

Sheet Raw Data
A1: Include | B1: Sq Ft. | C1: Rent | D1: Adj. Rent | E1: $/sq ft | F1: Adj. $/sq ft | G1: Adj BD | H1: Beds Number | I1: Den | J1: Date | K1: Building Name | L1: Building Address | M1: Building City | N1: Developer | O1: Unit # | P1: Unit Address | Q1: Beds | R1: Baths | S1: Sqft (Condos.ca) | T1: MLS Size Range | U1: # Parking | V1: Parking Included | W1: Locker | X1: Outdoor Space | Y1: Exposure | Z1: Building Age | AA1: Building Amenities | AB1: Leased Rent ($) | AC1: Listed Rent ($) | AD1: PSF (Calculated) | AE1: PSF (Listing) | AF1: Furnished | AG1: Hydro Included | AH1: Water Included | AI1: Lease Date | AJ1: MLS# | AK1: Listing URL | AL1: Description | AM1: Product Type | AN1: $/SF (Product-Adj)
A2: =IF(AND(ISNUMBER(B2),B2>0,ISNUMBER(AB2),AB2>0,J2>=Data_Summary!$C$1),1,0) -> 1 | B2: 694 | C2: =IF(ISNUMBER(AB2),AB2,"") -> 2450 | D2: =IF(ISNUMBER(C2),C2-U2*Data_Summary!$C$2,"") -> 2317.6654 | E2: =IFERROR(C2/B2,"") -> 3.5302594 | F2: =IFERROR(D2/B2,"") -> 3.3395755 | G2: =Q2 -> 2 | H2: =IFERROR(LEFT(G2,1),"") -> 2 | I2: =IF(LEN(G2)>1,1,0) -> 0 | J2: 46136 | K2: The Humber | L2: 10 Wilby Crescent | M2: Toronto (Weston) | N2: Options for Homes | O2: 1602 | P2: 1602 - 10 Wilby Crescent | Q2: 2 | R2: 2 | S2: 694 | T2: 600-699 sqft | U2: 1 | V2: Yes | W2: Ensuite | X2: Balcony, Patio | Y2: W | Z2: Built 2023 (3 yrs) | AA2: Gym, Party Room, Rooftop Deck, Visitor Parking, BBQ, Bike Storage, Concierge, Coin Laundry | AB2: 2450 | AC2: 2450 | AD2: =IFERROR(AB2/B2,"") -> 3.5302594 | AE2: =IFERROR(AC2/B2,"") -> 3.5302594 | AF2: No | AG2: No | AH2: No | AI2: 2026-04-24 | AJ2: W12954480 | AK2: https://condos.ca/toronto/the-humber-10-wilby-crescent-10-wilby-cres/unit-1602-W12954480 | AL2: Leased comp. SF: Verified (condos.ca per-unit). Re-verified 2026-06-11 (unit page opened: SF/beds/baths/parking/rent/date/MLS match). | AM2: Condo | AN2: =IFERROR(E2*(1+IF(AM2="Apartment",Data_Summary!$C$3,0)),"") -> 3.5302594
A3: =IF(AND(ISNUMBER(B3),B3>0,ISNUMBER(AB3),AB3>0,J3>=Data_Summary!$C$1),1,0) -> 1 | B3: 694 | C3: =IF(ISNUMBER(AB3),AB3,"") -> 2000 | D3: =IF(ISNUMBER(C3),C3-U3*Data_Summary!$C$2,"") -> 2000 | E3: =IFERROR(C3/B3,"") -> 2.8818444 | F3: =IFERROR(D3/B3,"") -> 2.8818444 | G3: =Q3 -> 1+1 | H3: =IFERROR(LEFT(G3,1),"") -> 1 | I3: =IF(LEN(G3)>1,1,0) -> 1 | J3: 46134 | K3: The Humber | L3: 10 Wilby Crescent | M3: Toronto (Weston) | N3: Options for Homes | O3: 409 | P3: 409 - 10 Wilby Crescent | Q3: 1+1 | R3: 1 | S3: 694 | T3: 600-699 sqft | U3: 0 | V3: No | W3: None | X3: Balcony, Patio | Y3: S | Z3: Built 2023 (3 yrs) | AA3: Gym, Party Room, Rooftop Deck, Visitor Parking, BBQ, Bike Storage, Concierge, Coin Laundry | AB3: 2000 | AC3: 2050 | AD3: =IFERROR(AB3/B3,"") -> 2.8818444 | AE3: =IFERROR(AC3/B3,"") -> 2.9538905 | AF3: No | AG3: No | AH3: No | AI3: 2026-04-22 | AJ3: W12873004 | AK3: https://condos.ca/toronto/the-humber-10-wilby-crescent-10-wilby-cres/unit-409-W12873004 | AL3: Leased comp. SF: Verified (condos.ca per-unit). Re-verified 2026-06-11 (unit page opened: SF/beds/baths/parking/rent/date/MLS match). | AM3: Condo | AN3: =IFERROR(E3*(1+IF(AM3="Apartment",Data_Summary!$C$3,0)),"") -> 2.8818444
A4: =IF(AND(ISNUMBER(B4),B4>0,ISNUMBER(AB4),AB4>0,J4>=Data_Summary!$C$1),1,0) -> 1 | B4: 715 | C4: =IF(ISNUMBER(AB4),AB4,"") -> 2350 | D4: =IF(ISNUMBER(C4),C4-U4*Data_Summary!$C$2,"") -> 2217.6654 | E4: =IFERROR(C4/B4,"") -> 3.2867133 | F4: =IFERROR(D4/B4,"") -> 3.10163 | G4: =Q4 -> 2 | H4: =IFERROR(LEFT(G4,1),"") -> 2 | I4: =IF(LEN(G4)>1,1,0) -> 0 | J4: 46133 | K4: The Humber | L4: 10 Wilby Crescent | M4: Toronto (Weston) | N4: Options for Homes | O4: 1807 | P4: 1807 - 10 Wilby Crescent | Q4: 2 | R4: 2 | S4: 715 | T4: 700-799 sqft | U4: 1 | V4: Yes | W4: Owned | X4: Balcony, Patio | Y4: NE | Z4: Built 2023 (3 yrs) | AA4: Gym, Party Room, Rooftop Deck, Visitor Parking, BBQ, Bike Storage, Concierge, Coin Laundry | AB4: 2350 | AC4: 2400 | AD4: =IFERROR(AB4/B4,"") -> 3.2867133 | AE4: =IFERROR(AC4/B4,"") -> 3.3566434 | AF4: No | AG4: No | AH4: No | AI4: 2026-04-21 | AJ4: W12930642 | AK4: https://condos.ca/toronto/the-humber-10-wilby-crescent-10-wilby-cres/unit-1807-W12930642 | AL4: Leased comp. SF: Verified (condos.ca per-unit). Re-verified 2026-06-11 (unit page opened: SF/beds/baths/parking/rent/date/MLS match). | AM4: Condo | AN4: =IFERROR(E4*(1+IF(AM4="Apartment",Data_Summary!$C$3,0)),"") -> 3.2867133
A5: =IF(AND(ISNUMBER(B5),B5>0,ISNUMBER(AB5),AB5>0,J5>=Data_Summary!$C$1),1,0) -> 1 | B5: 617 | C5: =IF(ISNUMBER(AB5),AB5,"") -> 1999 | D5: =IF(ISNUMBER(C5),C5-U5*Data_Summary!$C$2,"") -> 1866.6654 | E5: =IFERROR(C5/B5,"") -> 3.2398703 | F5: =IFERROR(D5/B5,"") -> 3.0253897 | G5: =Q5 -> 1 | H5: =IFERROR(LEFT(G5,1),"") -> 1 | I5: =IF(LEN(G5)>1,1,0) -> 0 | J5: 46125 | K5: The Humber | L5: 10 Wilby Crescent | M5: Toronto (Weston) | N5: Options for Homes | O5: 204 | P5: 204 - 10 Wilby Crescent | Q5: 1 | R5: 1 | S5: 617 | T5: 600-699 sqft | U5: 1 | V5: Yes | W5: Owned | X5: Balcony, Patio | Y5: E | Z5: Built 2023 (3 yrs) | AA5: Gym, Party Room, Rooftop Deck, Visitor Parking, BBQ, Bike Storage, Concierge, Coin Laundry | AB5: 1999 | AC5: 1999 | AD5: =IFERROR(AB5/B5,"") -> 3.2398703 | AE5: =IFERROR(AC5/B5,"") -> 3.2398703 | AF5: No | AG5: No | AH5: No | AI5: 2026-04-13 | AJ5: W12984894 | AK5: https://condos.ca/toronto/the-humber-10-wilby-crescent-10-wilby-cres/unit-204-W12984894 | AL5: Leased comp. SF: Verified (condos.ca per-unit). Re-verified 2026-06-11 (unit page opened: SF/beds/baths/parking/rent/date/MLS match). | AM5: Condo | AN5: =IFERROR(E5*(1+IF(AM5="Apartment",Data_Summary!$C$3,0)),"") -> 3.2398703
A6: =IF(AND(ISNUMBER(B6),B6>0,ISNUMBER(AB6),AB6>0,J6>=Data_Summary!$C$1),1,0) -> 1 | B6: 751 | C6: =IF(ISNUMBER(AB6),AB6,"") -> 2100 | D6: =IF(ISNUMBER(C6),C6-U6*Data_Summary!$C$2,"") -> 2100 | E6: =IFERROR(C6/B6,"") -> 2.7962716 | F6: =IFERROR(D6/B6,"") -> 2.7962716 | G6: =Q6 -> 1+1 | H6: =IFERROR(LEFT(G6,1),"") -> 1 | I6: =IF(LEN(G6)>1,1,0) -> 1 | J6: 46113 | K6: The Humber | L6: 10 Wilby Crescent | M6: Toronto (Weston) | N6: Options for Homes | O6: 202 | P6: 202 - 10 Wilby Crescent | Q6: 1+1 | R6: 2 | S6: 751 | T6: 700-799 sqft | U6: 0 | V6: No | W6: None | X6: Balcony, Patio | Y6: NE | Z6: Built 2023 (3 yrs) | AA6: Gym, Party Room, Rooftop Deck, Visitor Parking, BBQ, Bike Storage, Concierge, Coin Laundry | AB6: 2100 | AC6: 2100 | AD6: =IFERROR(AB6/B6,"") -> 2.7962716 | AE6: =IFERROR(AC6/B6,"") -> 2.7962716 | AF6: No | AG6: No | AH6: No | AI6: 2026-04-01 | AJ6: W12841906 | AK6: https://condos.ca/toronto/the-humber-10-wilby-crescent-10-wilby-cres/unit-202-W12841906 | AL6: Leased comp. SF: Verified (condos.ca per-unit). Re-verified 2026-06-11 (unit page opened: SF/beds/baths/parking/rent/date/MLS match). | AM6: Condo | AN6: =IFERROR(E6*(1+IF(AM6="Apartment",Data_Summary!$C$3,0)),"") -> 2.7962716
A7: =IF(AND(ISNUMBER(B7),B7>0,ISNUMBER(AB7),AB7>0,J7>=Data_Summary!$C$1),1,0) -> 1 | B7: 816 | C7: =IF(ISNUMBER(AB7),AB7,"") -> 2575 | D7: =IF(ISNUMBER(C7),C7-U7*Data_Summary!$C$2,"") -> 2442.6654 | E7: =IFERROR(C7/B7,"") -> 3.1556373 | F7: =IFERROR(D7/B7,"") -> 2.9934625 | G7: =Q7 -> 2 | H7: =IFERROR(LEFT(G7,1),"") -> 2 | I7: =IF(LEN(G7)>1,1,0) -> 0 | J7: 46109 | K7: The Humber | L7: 10 Wilby Crescent | M7: Toronto (Weston) | N7: Options for Homes | O7: 1409 | P7: 1409 - 10 Wilby Crescent | Q7: 2 | R7: 2 | S7: 816 | T7: 800-899 sqft | U7: 1 | V7: Yes | W7: None | X7: Balcony, Patio | Y7: E | Z7: Built 2023 (3 yrs) | AA7: Gym, Party Room, Rooftop Deck, Visitor Parking, BBQ, Bike Storage, Concierge, Coin Laundry | AB7: 2575 | AC7: 2600 | AD7: =IFERROR(AB7/B7,"") -> 3.1556373 | AE7: =IFERROR(AC7/B7,"") -> 3.1862745 | AF7: No | AG7: No | AH7: No | AI7: 2026-03-28 | AJ7: W12898704 | AK7: https://condos.ca/toronto/the-humber-10-wilby-crescent-10-wilby-cres/unit-1409-W12898704 | AL7: Leased comp. SF: Verified (condos.ca per-unit). Re-verified 2026-06-11 (unit page opened: SF/beds/baths/parking/rent/date/MLS match). | AM7: Condo | AN7: =IFERROR(E7*(1+IF(AM7="Apartment",Data_Summary!$C$3,0)),"") -> 3.1556373
A8: =IF(AND(ISNUMBER(B8),B8>0,ISNUMBER(AB8),AB8>0,J8>=Data_Summary!$C$1),1,0) -> 1 | B8: 583 | C8: =IF(ISNUMBER(AB8),AB8,"") -> 2200 | D8: =IF(ISNUMBER(C8),C8-U8*Data_Summary!$C$2,"") -> 2067.6654 | E8: =IFERROR(C8/B8,"") -> 3.7735849 | F8: =IFERROR(D8/B8,"") -> 3.5465959 | G8: =Q8 -> 1+1 | H8: =IFERROR(LEFT(G8,1),"") -> 1 | I8: =IF(LEN(G8)>1,1,0) -> 1 | J8: 46105 | K8: The Humber | L8: 10 Wilby Crescent | M8: Toronto (Weston) | N8: Options for Homes | O8: 1005 | P8: 1005 - 10 Wilby Crescent | Q8: 1+1 | R8: 1 | S8: 583 | T8: 500-599 sqft | U8: 1 | V8: Yes | W8: Owned | X8: Balcony, Patio | Y8: S | Z8: Built 2023 (3 yrs) | AA8: Gym, Party Room, Rooftop Deck, Visitor Parking, BBQ, Bike Storage, Concierge, Coin Laundry | AB8: 2200 | AC8: 2200 | AD8: =IFERROR(AB8/B8,"") -> 3.7735849 | AE8: =IFERROR(AC8/B8,"") -> 3.7735849 | AF8: No | AG8: No | AH8: No | AI8: 2026-03-24 | AJ8: W12848862 | AK8: https://condos.ca/toronto/the-humber-10-wilby-crescent-10-wilby-cres/unit-1005-W12848862 | AL8: Leased comp. SF: Verified (condos.ca per-unit). Re-verified 2026-06-11 (unit page opened: SF/beds/baths/parking/rent/date/MLS match). | AM8: Condo | AN8: =IFERROR(E8*(1+IF(AM8="Apartment",Data_Summary!$C$3,0)),"") -> 3.7735849
A9: =IF(AND(ISNUMBER(B9),B9>0,ISNUMBER(AB9),AB9>0,J9>=Data_Summary!$C$1),1,0) -> 1 | B9: 988 | C9: =IF(ISNUMBER(AB9),AB9,"") -> 2550 | D9: =IF(ISNUMBER(C9),C9-U9*Data_Summary!$C$2,"") -> 2550 | E9: =IFERROR(C9/B9,"") -> 2.5809717 | F9: =IFERROR(D9/B9,"") -> 2.5809717 | G9: =Q9 -> 3 | H9: =IFERROR(LEFT(G9,1),"") -> 3 | I9: =IF(LEN(G9)>1,1,0) -> 0 | J9: 46084 | K9: The Humber | L9: 10 Wilby Crescent | M9: Toronto (Weston) | N9: Options for Homes | O9: 1206 | P9: 1206 - 10 Wilby Crescent | Q9: 3 | R9: 2 | S9: 988 | T9: 900-999 sqft | U9: 0 | V9: No | W9: Owned | X9: Balcony, Patio | Y9: SW | Z9: Built 2023 (3 yrs) | AA9: Gym, Party Room, Rooftop Deck, Visitor Parking, BBQ, Bike Storage, Concierge, Coin Laundry | AB9: 2550 | AC9: 2700 | AD9: =IFERROR(AB9/B9,"") -> 2.5809717 | AE9: =IFERROR(AC9/B9,"") -> 2.7327935 | AF9: No | AG9: No | AH9: No | AI9: 2026-03-03 | AJ9: W12473063 | AK9: https://condos.ca/toronto/the-humber-10-wilby-crescent-10-wilby-cres/unit-1206-W12473063 | AL9: Leased comp. SF: Verified (condos.ca per-unit). Re-verified 2026-06-11 (unit page opened: SF/beds/baths/parking/rent/date/MLS match). | AM9: Condo | AN9: =IFERROR(E9*(1+IF(AM9="Apartment",Data_Summary!$C$3,0)),"") -> 2.5809717
A10: =IF(AND(ISNUMBER(B10),B10>0,ISNUMBER(AB10),AB10>0,J10>=Data_Summary!$C$1),1,0) -> 1 | B10: 694 | C10: =IF(ISNUMBER(AB10),AB10,"") -> 2199 | D10: =IF(ISNUMBER(C10),C10-U10*Data_Summary!$C$2,"") -> 2066.6654 | E10: =IFERROR(C10/B10,"") -> 3.1685879 | F10: =IFERROR(D10/B10,"") -> 2.9779041 | G10: =Q10 -> 1+1 | H10: =IFERROR(LEFT(G10,1),"") -> 1 | I10: =IF(LEN(G10)>1,1,0) -> 1 | J10: 46044 | K10: The Humber | L10: 10 Wilby Crescent | M10: Toronto (Weston) | N10: Options for Homes | O10: 308 | P10: 308 - 10 Wilby Crescent | Q10: 1+1 | R10: 1 | S10: 694 | T10: 600-699 sqft | U10: 1 | V10: Yes | W10: Owned | X10: Balcony, Patio | Y10: S | Z10: Built 2023 (3 yrs) | AA10: Gym, Party Room, Rooftop Deck, Visitor Parking, BBQ, Bike Storage, Concierge, Coin Laundry | AB10: 2199 | AC10: 2199 | AD10: =IFERROR(AB10/B10,"") -> 3.1685879 | AE10: =IFERROR(AC10/B10,"") -> 3.1685879 | AF10: No | AG10: No | AH10: No | AI10: 2026-01-22 | AJ10: W12686952 | AK10: https://condos.ca/toronto/the-humber-10-wilby-crescent-10-wilby-cres/unit-308-W12686952 | AL10: Leased comp. SF: Verified (condos.ca per-unit). Re-verified 2026-06-11 (unit page opened: SF/beds/baths/parking/rent/date/MLS match). | AM10: Condo | AN10: =IFERROR(E10*(1+IF(AM10="Apartment",Data_Summary!$C$3,0)),"") -> 3.1685879
A11: =IF(AND(ISNUMBER(B11),B11>0,ISNUMBER(AB11),AB11>0,J11>=Data_Summary!$C$1),1,0) -> 1 | B11: 588 | C11: =IF(ISNUMBER(AB11),AB11,"") -> 2100 | D11: =IF(ISNUMBER(C11),C11-U11*Data_Summary!$C$2,"") -> 2100 | E11: =IFERROR(C11/B11,"") -> 3.5714286 | F11: =IFERROR(D11/B11,"") -> 3.5714286 | G11: =Q11 -> 1+1 | H11: =IFERROR(LEFT(G11,1),"") -> 1 | I11: =IF(LEN(G11)>1,1,0) -> 1 | J11: 46043 | K11: The Humber | L11: 10 Wilby Crescent | M11: Toronto (Weston) | N11: Options for Homes | O11: 2004 | P11: 2004 - 10 Wilby Crescent | Q11: 1+1 | R11: 1 | S11: 588 | T11: 500-599 sqft | U11: 0 | V11: No | W11: Owned | X11: Balcony, Patio | Y11: W | Z11: Built 2023 (3 yrs) | AA11: Gym, Party Room, Rooftop Deck, Visitor Parking, BBQ, Bike Storage, Concierge, Coin Laundry | AB11: 2100 | AC11: 2100 | AD11: =IFERROR(AB11/B11,"") -> 3.5714286 | AE11: =IFERROR(AC11/B11,"") -> 3.5714286 | AF11: Yes | AG11: No | AH11: No | AI11: 2026-01-21 | AJ11: W12460996 | AK11: https://condos.ca/toronto/the-humber-10-wilby-crescent-10-wilby-cres/unit-2004-W12460996 | AL11: Leased comp. SF: Verified (condos.ca per-unit). Re-verified 2026-06-11 (unit page opened: SF/beds/baths/parking/rent/date/MLS match). | AM11: Condo | AN11: =IFERROR(E11*(1+IF(AM11="Apartment",Data_Summary!$C$3,0)),"") -> 3.5714286
A12: =IF(AND(ISNUMBER(B12),B12>0,ISNUMBER(AB12),AB12>0,J12>=Data_Summary!$C$1),1,0) -> 1 | B12: 1135 | C12: =IF(ISNUMBER(AB12),AB12,"") -> 3000 | D12: =IF(ISNUMBER(C12),C12-U12*Data_Summary!$C$2,"") -> 2867.6654 | E12: =IFERROR(C12/B12,"") -> 2.6431718 | F12: =IFERROR(D12/B12,"") -> 2.5265775 | G12: =Q12 -> 3 | H12: =IFERROR(LEFT(G12,1),"") -> 3 | I12: =IF(LEN(G12)>1,1,0) -> 0 | J12: 46010 | K12: The Humber | L12: 10 Wilby Crescent | M12: Toronto (Weston) | N12: Options for Homes | O12: 101 | P12: 101 - 10 Wilby Crescent | Q12: 3 | R12: 2 | S12: 1135 | T12: 1,000-1,199 sqft | U12: 1 | V12: Yes | W12: Owned | X12: Balcony, Patio | Y12: W | Z12: Built 2023 (3 yrs) | AA12: Gym, Party Room, Rooftop Deck, Visitor Parking, BBQ, Bike Storage, Concierge, Coin Laundry | AB12: 3000 | AC12: 2995 | AD12: =IFERROR(AB12/B12,"") -> 2.6431718 | AE12: =IFERROR(AC12/B12,"") -> 2.6387665 | AF12: No | AG12: No | AH12: No | AI12: 2025-12-19 | AJ12: W12506510 | AK12: https://condos.ca/toronto/the-humber-10-wilby-crescent-10-wilby-cres/unit-101-W12506510 | AL12: Leased comp. SF: Verified (condos.ca per-unit). Added 2026-06-09 deep-verify; 2-storey grade-level suite. Re-verified 2026-06-11 (unit page opened: SF/beds/baths/parking/rent/date/MLS match). | AM12: Condo | AN12: =IFERROR(E12*(1+IF(AM12="Apartment",Data_Summary!$C$3,0)),"") -> 2.6431718
A13: =IF(AND(ISNUMBER(B13),B13>0,ISNUMBER(AB13),AB13>0,J13>=Data_Summary!$C$1),1,0) -> 1 | B13: 694 | C13: =IF(ISNUMBER(AB13),AB13,"") -> 2400 | D13: =IF(ISNUMBER(C13),C13-U13*Data_Summary!$C$2,"") -> 2267.6654 | E13: =IFERROR(C13/B13,"") -> 3.4582133 | F13: =IFERROR(D13/B13,"") -> 3.2675294 | G13: =Q13 -> 2 | H13: =IFERROR(LEFT(G13,1),"") -> 2 | I13: =IF(LEN(G13)>1,1,0) -> 0 | J13: 46009 | K13: The Humber | L13: 10 Wilby Crescent | M13: Toronto (Weston) | N13: Options for Homes | O13: 2102 | P13: 2102 - 10 Wilby Crescent | Q13: 2 | R13: 2 | S13: 694 | T13: 600-699 sqft | U13: 1 | V13: Yes | W13: Owned | X13: Balcony, Patio | Y13: S | Z13: Built 2023 (3 yrs) | AA13: Gym, Party Room, Rooftop Deck, Visitor Parking, BBQ, Bike Storage, Concierge, Coin Laundry | AB13: 2400 | AC13: 2500 | AD13: =IFERROR(AB13/B13,"") -> 3.4582133 | AE13: =IFERROR(AC13/B13,"") -> 3.6023055 | AF13: No | AG13: No | AH13: No | AI13: 2025-12-18 | AJ13: W12573868 | AK13: https://condos.ca/toronto/the-humber-10-wilby-crescent-10-wilby-cres/unit-2102-W12573868 | AL13: Leased comp. SF: Verified (condos.ca per-unit). Re-verified 2026-06-11 (unit page opened: SF/beds/baths/parking/rent/date/MLS match). | AM13: Condo | AN13: =IFERROR(E13*(1+IF(AM13="Apartment",Data_Summary!$C$3,0)),"") -> 3.4582133
... A27: =IF(AND(ISNUMBER(B27),B27>0,ISNUMBER(AB27),AB27>0,J27>=Data_Summary!$C$1),1,0) -> 0 | B27: 694 | C27: =IF(ISNUMBER(AB27),AB27,"") -> 2150 | D27: =IF(ISNUMBER(C27),C27-U27*Data_Summary!$C$2,"") -> 2150 | E27: =IFERROR(C27/B27,"") -> 3.0979827 | F27: =IFERROR(D27/B27,"") -> 3.0979827 | G27: =Q27 -> 1+1 | H27: =IFERROR(LEFT(G27,1),"") -> 1 | I27: =IF(LEN(G27)>1,1,0) -> 1 | J27: 45758 | K27: The Humber | L27: 10 Wilby Crescent | M27: Toronto (Weston) | N27: Options for Homes | O27: 309 | P27: 309 - 10 Wilby Crescent | Q27: 1+1 | R27: 1 | S27: 694 | T27: 600-699 sqft | U27: 0 | V27: No | W27: None | X27: Balcony, Patio | Y27: SW | Z27: Built 2023 (3 yrs) | AA27: Gym, Party Room, Rooftop Deck, Visitor Parking, BBQ, Bike Storage, Concierge, Coin Laundry | AB27: 2150 | AC27: 2150 | AD27: =IFERROR(AB27/B27,"") -> 3.0979827 | AE27: =IFERROR(AC27/B27,"") -> 3.0979827 | AF27: No | AG27: No | AH27: No | AI27: 2025-04-11 | AJ27: W12051780 | AK27: https://condos.ca/toronto/the-humber-10-wilby-crescent-10-wilby-cres/unit-309-W12051780 | AL27: Leased comp. SF: Verified (condos.ca per-unit). Re-verified 2026-06-11 (unit page opened: SF/beds/baths/parking/rent/date/MLS match). | AM27: Condo | AN27: =IFERROR(E27*(1+IF(AM27="Apartment",Data_Summary!$C$3,0)),"") -> 3.0979827
A28: =IF(AND(ISNUMBER(B28),B28>0,ISNUMBER(AB28),AB28>0,J28>=Data_Summary!$C$1),1,0) -> 0 | B28: 715 | C28: =IF(ISNUMBER(AB28),AB28,"") | D28: =IF(ISNUMBER(C28),C28-U28*Data_Summary!$C$2,"") | E28: =IFERROR(C28/B28,"") | F28: =IFERROR(D28/B28,"") | G28: =Q28 -> 2 | H28: =IFERROR(LEFT(G28,1),"") -> 2 | I28: =IF(LEN(G28)>1,1,0) -> 0 | J28: 46162 | K28: The Humber | L28: 10 Wilby Crescent | M28: Toronto (Weston) | N28: Options for Homes | O28: 907 | P28: 907 - 10 Wilby Crescent | Q28: 2 | R28: 2 | S28: 715 | T28: 700-799 sqft | U28: 1 | V28: Yes | W28: None | X28: Balcony, Patio | Y28: NE | Z28: Built 2023 (3 yrs) | AA28: Gym, Party Room, Rooftop Deck, Visitor Parking, BBQ, Bike Storage, Concierge, Coin Laundry | AC28: 2400 | AD28: =IFERROR(AB28/B28,"") -> 0 | AE28: =IFERROR(AC28/B28,"") -> 3.3566434 | AF28: No | AG28: No | AH28: No | AI28: 2026-05-20 | AJ28: W13150160 | AK28: https://condos.ca/toronto/the-humber-10-wilby-crescent-10-wilby-cres/unit-907-W13150160 | AL28: ACTIVE asking rent (not a closed lease). | AM28: Condo | AN28: =IFERROR(E28*(1+IF(AM28="Apartment",Data_Summary!$C$3,0)),"")
A29: =IF(AND(ISNUMBER(B29),B29>0,ISNUMBER(AB29),AB29>0,J29>=Data_Summary!$C$1),1,0) -> 0 | B29: 715 | C29: =IF(ISNUMBER(AB29),AB29,"") | D29: =IF(ISNUMBER(C29),C29-U29*Data_Summary!$C$2,"") | E29: =IFERROR(C29/B29,"") | F29: =IFERROR(D29/B29,"") | G29: =Q29 -> 2 | H29: =IFERROR(LEFT(G29,1),"") -> 2 | I29: =IF(LEN(G29)>1,1,0) -> 0 | J29: 46164 | K29: The Humber | L29: 10 Wilby Crescent | M29: Toronto (Weston) | N29: Options for Homes | O29: 1407 | P29: 1407 - 10 Wilby Crescent | Q29: 2 | R29: 2 | S29: 715 | T29: 700-799 sqft | U29: 0 | V29: No | W29: None | X29: Balcony, Patio | Y29: NE | Z29: Built 2023 (3 yrs) | AA29: Gym, Party Room, Rooftop Deck, Visitor Parking, BBQ, Bike Storage, Concierge, Coin Laundry | AC29: 2500 | AD29: =IFERROR(AB29/B29,"") -> 0 | AE29: =IFERROR(AC29/B29,"") -> 3.4965035 | AF29: Part | AG29: No | AH29: No | AI29: 2026-05-22 | AJ29: W13159224 | AK29: https://condos.ca/toronto/the-humber-10-wilby-crescent-10-wilby-cres/unit-1407-W13159224 | AL29: ACTIVE asking rent (not a closed lease). | AM29: Condo | AN29: =IFERROR(E29*(1+IF(AM29="Apartment",Data_Summary!$C$3,0)),"")
A30: =IF(AND(ISNUMBER(B30),B30>0,ISNUMBER(AB30),AB30>0,J30>=Data_Summary!$C$1),1,0) -> 0 | B30: 715 | C30: =IF(ISNUMBER(AB30),AB30,"") | D30: =IF(ISNUMBER(C30),C30-U30*Data_Summary!$C$2,"") | E30: =IFERROR(C30/B30,"") | F30: =IFERROR(D30/B30,"") | G30: =Q30 -> 2 | H30: =IFERROR(LEFT(G30,1),"") -> 2 | I30: =IF(LEN(G30)>1,1,0) -> 0 | J30: 46084 | K30: The Humber | L30: 10 Wilby Crescent | M30: Toronto (Weston) | N30: Options for Homes | O30: 1907 | P30: 1907 - 10 Wilby Crescent | Q30: 2 | R30: 2 | S30: 715 | T30: 600-699 sqft | U30: 1 | V30: Yes | W30: None | X30: Balcony, Patio | Y30: N | Z30: Built 2023 (3 yrs) | AA30: Gym, Party Room, Rooftop Deck, Visitor Parking, BBQ, Bike Storage, Concierge, Coin Laundry | AC30: 2500 | AD30: =IFERROR(AB30/B30,"") -> 0 | AE30: =IFERROR(AC30/B30,"") -> 3.4965035 | AF30: No | AG30: No | AH30: No | AI30: 2026-03-03 | AJ30: W12841668 | AK30: https://condos.ca/toronto/the-humber-10-wilby-crescent-10-wilby-cres/unit-1907-W12841668 | AL30: ACTIVE asking rent (not a closed lease). Leased conditional (99 DOM as of 2026-06-11). Re-verified 2026-06-11 on unit page: 715 sqft*, 2/2, 1 parking, $2,500. MLS bracket 600-699 per 2026-06-09 read — caveat: calc SF above bracket. | AM30: Condo | AN30: =IFERROR(E30*(1+IF(AM30="Apartment",Data_Summary!$C$3,0)),"")
A31: =IF(AND(ISNUMBER(B31),B31>0,ISNUMBER(AB31),AB31>0,J31>=Data_Summary!$C$1),1,0) -> 0 | B31: 694 | C31: =IF(ISNUMBER(AB31),AB31,"") | D31: =IF(ISNUMBER(C31),C31-U31*Data_Summary!$C$2,"") | E31: =IFERROR(C31/B31,"") | F31: =IFERROR(D31/B31,"") | G31: =Q31 -> 2 | H31: =IFERROR(LEFT(G31,1),"") -> 2 | I31: =IF(LEN(G31)>1,1,0) -> 0 | J31: 46178 | K31: The Humber | L31: 10 Wilby Crescent | M31: Toronto (Weston) | N31: Options for Homes | O31: 1102 | P31: 1102 - 10 Wilby Crescent | Q31: 2 | R31: 2 | S31: 694 | U31: 0 | V31: No | W31: None | X31: Balcony, Patio | Z31: Built 2023 (3 yrs) | AA31: Gym, Party Room, Rooftop Deck, Visitor Parking, BBQ, Bike Storage, Concierge, Coin Laundry | AC31: 2400 | AD31: =IFERROR(AB31/B31,"") -> 0 | AE31: =IFERROR(AC31/B31,"") -> 3.4582133 | AF31: No | AG31: No | AH31: No | AI31: 2026-06-05 | AJ31: W13243038 | AK31: https://condos.ca/toronto/the-humber-10-wilby-crescent-10-wilby-cres/unit-1102-W13243038 | AL31: ACTIVE asking rent (not a closed lease). Read 2026-06-11 on unit page: 694 sqft*, 2 bed/2 bath, 0 parking, $2,400, 6 days on market (listed 2026-06-05). MLS size range and exposure not displayed (signed-in view). | AM31: Condo | AN31: =IFERROR(E31*(1+IF(AM31="Apartment",Data_Summary!$C$3,0)),"")
A32: =IF(AND(ISNUMBER(B32),B32>0,ISNUMBER(AB32),AB32>0,J32>=Data_Summary!$C$1),1,0) -> 0 | B32: 588 | C32: =IF(ISNUMBER(AB32),AB32,"") | D32: =IF(ISNUMBER(C32),C32-U32*Data_Summary!$C$2,"") | E32: =IFERROR(C32/B32,"") | F32: =IFERROR(D32/B32,"") | G32: =Q32 -> 1+1 | H32: =IFERROR(LEFT(G32,1),"") -> 1 | I32: =IF(LEN(G32)>1,1,0) -> 1 | J32: 46184 | K32: The Humber | L32: 10 Wilby Crescent | M32: Toronto (Weston) | N32: Options for Homes | O32: 1004 | P32: 1004 - 10 Wilby Crescent | Q32: 1+1 | R32: 1 | S32: 588 | T32: 600-699 sqft | U32: 0 | V32: No | W32: None | X32: Balcony, Patio | Z32: Built 2023 (3 yrs) | AA32: Gym, Party Room, Rooftop Deck, Visitor Parking, BBQ, Bike Storage, Concierge, Coin Laundry | AC32: 2200 | AD32: =IFERROR(AB32/B32,"") -> 0 | AE32: =IFERROR(AC32/B32,"") -> 3.7414966 | AF32: No | AG32: No | AH32: No | AI32: 2026-06-11 | AJ32: W13430024 | AK32: https://condos.ca/toronto/the-humber-10-wilby-crescent-10-wilby-cres/unit-1004-W13430024 | AL32: ACTIVE asking rent (not a closed lease). Read 2026-06-11 on unit page: 588 sqft*, 1+1 bed/1 bath, 0 parking, $2,200, listed 2026-06-11 (1 hr on market). Bracket 600-699 per vipcondos card; exposure not displayed. | AM32: Condo | AN32: =IFERROR(E32*(1+IF(AM32="Apartment",Data_Summary!$C$3,0)),"")
A33: =IF(AND(ISNUMBER(B33),B33>0,ISNUMBER(AB33),AB33>0,J33>=Data_Summary!$C$1),1,0) -> 0 | C33: =IF(ISNUMBER(AB33),AB33,"") -> 1560 | D33: =IF(ISNUMBER(C33),C33-U33*Data_Summary!$C$2,"") -> 1560 | E33: =IFERROR(C33/B33,"") | F33: =IFERROR(D33/B33,"") | G33: =Q33 -> 1 | H33: =IFERROR(LEFT(G33,1),"") -> 1 | I33: =IF(LEN(G33)>1,1,0) -> 0 | J33: 46118 | K33: The Humber | L33: 10 Wilby Crescent | M33: Toronto (Weston) | N33: Options for Homes | O33: 1801-P | P33: 1801-P - 10 Wilby Crescent | Q33: 1 | R33: 1 | T33: 700-799 sqft | U33: 0 | V33: No | W33: None | X33: Balcony, Patio | Z33: Built 2023 (3 yrs) | AA33: Gym, Party Room, Rooftop Deck, Visitor Parking, BBQ, Bike Storage, Concierge, Coin Laundry | AB33: 1560 | AC33: 1480 | AD33: =IFERROR(AB33/B33,"") | AE33: =IFERROR(AC33/B33,"") | AF33: No | AG33: No | AH33: No | AI33: 2026-04-06 | AJ33: W12905894 | AK33: https://condos.ca/toronto/the-humber-10-wilby-crescent-10-wilby-cres/unit-1801-P-W12905894 | AL33: Room rental of unit 1801 (P/S) — excluded. Re-verified 2026-06-11 on unit page: 1 bed/1 bath, 0 parking, bracket 700-799, leased $1,560 on 2026-04-06 (listed $1,480). | AM33: Condo | AN33: =IFERROR(E33*(1+IF(AM33="Apartment",Data_Summary!$C$3,0)),"")
A34: =IF(AND(ISNUMBER(B34),B34>0,ISNUMBER(AB34),AB34>0,J34>=Data_Summary!$C$1),1,0) -> 0 | C34: =IF(ISNUMBER(AB34),AB34,"") -> 1280 | D34: =IF(ISNUMBER(C34),C34-U34*Data_Summary!$C$2,"") -> 1280 | E34: =IFERROR(C34/B34,"") | F34: =IFERROR(D34/B34,"") | G34: =Q34 -> 1 | H34: =IFERROR(LEFT(G34,1),"") -> 1 | I34: =IF(LEN(G34)>1,1,0) -> 0 | J34: 45860 | K34: The Humber | L34: 10 Wilby Crescent | M34: Toronto (Weston) | N34: Options for Homes | O34: 1801-S | P34: 1801-S - 10 Wilby Crescent | Q34: 1 | R34: 1 | T34: 700-799 sqft | U34: 0 | V34: No | W34: None | X34: Balcony, Patio | Z34: Built 2023 (3 yrs) | AA34: Gym, Party Room, Rooftop Deck, Visitor Parking, BBQ, Bike Storage, Concierge, Coin Laundry | AB34: 1280 | AC34: 1380 | AD34: =IFERROR(AB34/B34,"") | AE34: =IFERROR(AC34/B34,"") | AF34: No | AG34: No | AH34: No | AI34: 2025-07-22 | AJ34: W12194033 | AK34: https://condos.ca/toronto/the-humber-10-wilby-crescent-10-wilby-cres/unit-1801-S-W12194033 | AL34: Room rental of unit 1801 (P/S) — excluded. Re-verified 2026-06-11 on unit page: 1 bed/1 bath, 0 parking, bracket 700-799, leased $1,280 on 2025-07-22 (listed $1,380). | AM34: Condo | AN34: =IFERROR(E34*(1+IF(AM34="Apartment",Data_Summary!$C$3,0)),"")

Sheet Floor Plans
A1: Building Name | B1: Building Address | C1: Building City | D1: Suite Name | E1: Beds | F1: Baths | G1: Sq Ft | H1: Exposure
A2: The Humber | B2: 10 Wilby Crescent | C2: Toronto (Weston) | D2: 1B | E2: 1 | F2: 1 | G2: 556 | H2: NW
A3: The Humber | B3: 10 Wilby Crescent | C3: Toronto (Weston) | D3: 1A | E3: 1 | F3: 1 | G3: 617 | H3: E
A4: The Humber | B4: 10 Wilby Crescent | C4: Toronto (Weston) | D4: 1D-583 | E4: 1 | F4: 1 | G4: 583 | H4: S
A5: The Humber | B5: 10 Wilby Crescent | C5: Toronto (Weston) | D5: 1D-588 | E5: 1 | F5: 1 | G5: 588 | H5: SW
A6: The Humber | B6: 10 Wilby Crescent | C6: Toronto (Weston) | D6: 1D-663 | E6: 1 | F6: 1 | G6: 663 | H6: NE
A7: The Humber | B7: 10 Wilby Crescent | C7: Toronto (Weston) | D7: 1D-694 | E7: 1 | F7: 1 | G7: 694 | H7: S
A8: The Humber | B8: 10 Wilby Crescent | C8: Toronto (Weston) | D8: 1DX-751 | E8: 1 | F8: 2 | G8: 751 | H8: NE
A9: The Humber | B9: 10 Wilby Crescent | C9: Toronto (Weston) | D9: 2A-694 | E9: 2 | F9: 2 | G9: 694 | H9: S/W/NE
A10: The Humber | B10: 10 Wilby Crescent | C10: Toronto (Weston) | D10: 2B-715 | E10: 2 | F10: 2 | G10: 715 | H10: N/NE
A11: The Humber | B11: 10 Wilby Crescent | C11: Toronto (Weston) | D11: 2C-788 | E11: 2 | F11: 2 | G11: 788 | H11: NE
A12: The Humber | B12: 10 Wilby Crescent | C12: Toronto (Weston) | D12: 2D-797 | E12: 2 | F12: 2 | G12: 797 | H12: NE
A13: The Humber | B13: 10 Wilby Crescent | C13: Toronto (Weston) | D13: 2E-816 | E13: 2 | F13: 2 | G13: 816 | H13: E
... A15: The Humber | B15: 10 Wilby Crescent | C15: Toronto (Weston) | D15: 3B-1135 | E15: 3 | F15: 2 | G15: 1135 | H15: W
