Workbook

Sheet Output
G2: Unit Mix Adjusted1
B3: Building | C3: First Occupancy | D3: Avg.Lease Date | E3: Vacancy | F3: Transaction Count | G3: Avg Suite Size | H3: Adj. Avg. Rent | I3: Avg. Net Rent PSF
B5: Lawrence & Jane St
B6: The Humber
B8: Average
B9: PBR Premium
B10: Implied Untrended Rent
B12: Subject Site (Untrended Rent)
B15: Other Excluded
B19: Average
B20: PBR Premium
B21: Implied Untrended Rent
B23: Weighted Average
B24: PBR Premium
B25: Implied Untrended Rent
B27: ★ RECOMMENDATION — RECOMMENDED SUBJECT RENT | L27: Studio Units | P27: 1-Bedroom Units | T27: 1-Bedroom + Den Units | X27: 2-Bedroom Units | AB27: 3-Bedroom Units
B28: Recommended subject $/SF | D28: =Data_Summary!$C$25 | K28: Building | L28: Transaction Count | M28: Avg. Suite Size | N28: Adj. Avg. Rent | O28: Avg. Net Rent PSF | P28: Transaction Count | Q28: Avg. Suite Size | R28: Adj. Avg. Rent | S28: Avg. Net Rent PSF | T28: Transaction Count | U28: Avg. Suite Size | V28: Adj. Avg. Rent | W28: Avg. Net Rent PSF | X28: Transaction Count | Y28: Avg. Suite Size | Z28: Adj. Avg. Rent | AA28: Avg. Net Rent PSF | AB28: Transaction Count | AC28: Avg. Suite Size | AD28: Adj. Avg. Rent | AE28: Avg. Net Rent PSF
B29: Conservative (all-comp + premium) $/SF | D29: =Data_Summary!$C$26 | K29: The Humber
B30: Raw comp $/SF (Humber, no premium) | D30: =Data_Summary!$C$22
B31: Plus — new-build / lease-up premium | D31: =Data_Summary!$C$4 | K31: Weighted Avg.
K32: Low
B33: Recommended monthly rent by suite type | K33: High
B34: Suite | C34: Avg SF | D34: Rec. Rent
B35: 1-Bed | C35: =Data_Summary!C17 | D35: =Data_Summary!F17 | K35: PBR Premium
B36: 2-Bed | C36: =Data_Summary!C18 | D36: =Data_Summary!F18 | K36: Weighted Avg.
B37: 3-Bed | C37: =Data_Summary!C19 | D37: =Data_Summary!F19 | K37: Weighted Avg. Building Total (Comps)
B39: Custom suite — enter size (sq ft) → | D39: 700 | K39: Subject Property (Using Comp $ Rent)
B40: Implied rent @ recommended subject $/SF | D40: =IFERROR(D39*Data_Summary!$C$25,"") | K40: Subject Property Rent Building Total
B41: Implied rent @ raw comp $/SF (no premium) | D41: =IFERROR(D39*Data_Summary!$C$22,"")
K42: Subject Property (Using Comp PSF Rent)
B43: NOTES & CONTEXT | K43: Subject Property PSF Rent Building Total
B44: Recommendation folded in from the former Subject & Conclusion sheet (now deleted). Source bridge: raw comp $/SF → + subject premium → recommended $/SF; all-comp basis = conservative floor.
B45: Confidence fills (Raw Data): green = leased in-window + SF verified per-unit · cream = active / older / minor caveat / apartment asking-only · orange = excluded partial / bracket-only. | K45: Subject Property Rent
K46: Subject Property Rent Building Total
K48: Regression:
K49: Coefficients:
K50: Total Building coefficient
K52: Subject Property Rent (Increase)
K53: Subject Property Rent
R56: Unadjusted | Z56: Unadjusted | AD56: Unadjusted
...

Sheet Building Summary
A1: Comp Building Summary — Hickory Tree Tower (1736-1746 Weston Rd)
A3: Building | B3: Address | C3: Area | D3: Developer | E3: First Occupancy | F3: Yr Built | G3: Product | H3: Storeys | I3: Units | J3: Transaction Count | K3: Avg SF | L3: Avg Rent | M3: Avg $/SF
A4: The Humber | B4: 10 Wilby Crescent | C4: Weston | D4: Options for Homes | F4: 2023 | G4: Condo | H4: 22 | I4: 232 | J4: =COUNTIFS('RD Condos'!$K:$K,$A4,'RD Condos'!$A:$A,1) | K4: =IFERROR(AVERAGEIFS('RD Condos'!$B:$B,'RD Condos'!$K:$K,$A4,'RD Condos'!$A:$A,1),"") | L4: =IFERROR(AVERAGEIFS('RD Condos'!$AB:$AB,'RD Condos'!$K:$K,$A4,'RD Condos'!$A:$A,1),"") | M4: =IFERROR(AVERAGEIFS('RD Condos'!$E:$E,'RD Condos'!$K:$K,$A4,'RD Condos'!$A:$A,1),"")
A5: ALL CONDOS | J5: =SUM(J4:J4) | K5: =IFERROR(AVERAGEIFS('RD Condos'!$B:$B,'RD Condos'!$A:$A,1),"") | L5: =IFERROR(AVERAGEIFS('RD Condos'!$AB:$AB,'RD Condos'!$A:$A,1),"") | M5: =IFERROR(AVERAGEIFS('RD Condos'!$AN:$AN,'RD Condos'!$A:$A,1),"")
A6: ALL APARTMENTS | J6: =COUNTIFS('RD Apartments'!$A:$A,1) | K6: =IFERROR(AVERAGEIFS('RD Apartments'!$B:$B,'RD Apartments'!$A:$A,1),"") | L6: =IFERROR(AVERAGEIFS('RD Apartments'!$AB:$AB,'RD Apartments'!$A:$A,1),"") | M6: =IFERROR(AVERAGEIFS('RD Apartments'!$AN:$AN,'RD Apartments'!$A:$A,1),"")
A7: Apartment band is structurally present per spec; no apartment comps in this template set.

Sheet Data_Summary
B1: Date Filter (include leases on/after) | C1: 45778 | G1: Subject unit mix (1BR/2BR/3BR, den-incl) — DERIVED | J1: SF | K1: #Park | L1: 2BD | M1: 3BD | N1: Leased$ | P1: Subject Unit-Mix Derivation (P/Q) | S1: Subject Output mix & suite count (template — replace per subject)
B2: Parking Adjustment ($/spot/mo) | C2: =IFERROR(IF(AND(COUNT($N$2:$N$26)>=10,(MAX($K$2:$K$26)-MIN($K$2:$K$26))>0),INDEX(LINEST($N$2:$N$26,$J$2:$M$26,TRUE(),FALSE()),1,3),0),0) | D2: =IF(AND(COUNT($N$2:$N$26)>=10,(MAX($K$2:$K$26)-MIN($K$2:$K$26))>0),"LIVE OLS coefficient — rent ~ SF + parking + 2BD + 3BD over verified leased rows (helper J:N). Recomputes with the data; never typed.","0 — insufficient parking variation in included comp set") | G2: 1BR wt | H2: =IFERROR(IF($Q$5>0,$Q$2/$Q$5,$Q$8),$Q$8) | J2: ='RD Condos'!B2 | K2: ='RD Condos'!U2 | L2: =IF('RD Condos'!H2="2",1,0) | M2: =IF('RD Condos'!H2="3",1,0) | N2: ='RD Condos'!AB2 | P2: 1BR plans (SUBJECT, den-incl) | Q2: =COUNTIFS('Floor Plans'!$A:$A,"*(SUBJECT)*",'Floor Plans'!$I:$I,"<=1") | S2: Suite count | T2: 232 | U2: template placeholder — replace with the subject's suite count
B3: Apartment premium (apt comps only) — OFF | C3: 0 | D3: =IF(COUNTIFS('RD Apartments'!$A:$A,1)>0,"Apartment→condo $/SF markup; applies to RD Apartments col AN only — derive from APARTMENT PREMIUM BASIS or user-confirm; never a bare %.","Unused — no apartment comps in selected set") | G3: 2BR wt | H3: =IFERROR(IF($Q$5>0,$Q$3/$Q$5,$Q$9),$Q$9) | J3: ='RD Condos'!B3 | K3: ='RD Condos'!U3 | L3: =IF('RD Condos'!H3="2",1,0) | M3: =IF('RD Condos'!H3="3",1,0) | N3: ='RD Condos'!AB3 | P3: 2BR plans (SUBJECT) | Q3: =COUNTIFS('Floor Plans'!$A:$A,"*(SUBJECT)*",'Floor Plans'!$I:$I,2) | S3: 1BR wt | T3: 0.36
B4: Subject rental premium (new-build / lease-up; comp $/SF → subject) | C4: 0.133 | D4: =IF(C35=0,"JUDGMENT lever — single-comp set so the live vintage spread is 0%; C4="&TEXT(C4,"0.0%")&" carried from the prior Hickory model (Data_Old, +12.4–13.3%). Confirm with user.","JUDGMENT lever — anchored to PREMIUM BASIS below: spread "&TEXT(C35,"0.0%")&" to "&TEXT(C36,"0.0%")&"; C4="&TEXT(C4,"0.0%")&". Confirm with user.") | G4: 3BR wt | H4: =IFERROR(IF($Q$5>0,$Q$4/$Q$5,$Q$10),$Q$10) | J4: ='RD Condos'!B4 | K4: ='RD Condos'!U4 | L4: =IF('RD Condos'!H4="2",1,0) | M4: =IF('RD Condos'!H4="3",1,0) | N4: ='RD Condos'!AB4 | P4: 3BR plans (SUBJECT) | Q4: =COUNTIFS('Floor Plans'!$A:$A,"*(SUBJECT)*",'Floor Plans'!$I:$I,">=3") | S4: 1+Den wt | T4: 0.1
A5: Comp building rollup (included leases) | J5: ='RD Condos'!B5 | K5: ='RD Condos'!U5 | L5: =IF('RD Condos'!H5="2",1,0) | M5: =IF('RD Condos'!H5="3",1,0) | N5: ='RD Condos'!AB5 | P5: Total tagged plans | Q5: =SUM(Q2:Q4) | S5: 2BR wt | T5: 0.45
A6: Building | B6: Address | C6: Built | D6: Incl. | E6: Avg SF | F6: Avg Rent | G6: Avg $/SF | J6: ='RD Condos'!B6 | K6: ='RD Condos'!U6 | L6: =IF('RD Condos'!H6="2",1,0) | M6: =IF('RD Condos'!H6="3",1,0) | N6: ='RD Condos'!AB6 | P6: (0 ⇒ falls back to manual mix Q8:Q10) | S6: 3BR wt | T6: 0.09
A7: The Humber | B7: 10 Wilby Crescent | C7: Built 2023 (3 yrs) | D7: =COUNTIFS('RD Condos'!$K:$K,$A7,'RD Condos'!$A:$A,1) | E7: =IFERROR(AVERAGEIFS('RD Condos'!$B:$B,'RD Condos'!$K:$K,$A7,'RD Condos'!$A:$A,1),"") | F7: =IFERROR(AVERAGEIFS('RD Condos'!$AB:$AB,'RD Condos'!$K:$K,$A7,'RD Condos'!$A:$A,1),"") | G7: =IFERROR(AVERAGEIFS('RD Condos'!$E:$E,'RD Condos'!$K:$K,$A7,'RD Condos'!$A:$A,1),"") | J7: ='RD Condos'!B7 | K7: ='RD Condos'!U7 | L7: =IF('RD Condos'!H7="2",1,0) | M7: =IF('RD Condos'!H7="3",1,0) | N7: ='RD Condos'!AB7 | P7: Source | Q7: template — no subject plans tagged (SUBJECT); replace with the subject's developer suite schedule / planned mix
A8: ALL COMPS | D8: =SUM(D7:D7) | E8: =IFERROR(AVERAGEIFS('RD Condos'!$B:$B,'RD Condos'!$A:$A,1),"") | F8: =IFERROR(AVERAGEIFS('RD Condos'!$AB:$AB,'RD Condos'!$A:$A,1),"") | G8: =IFERROR(AVERAGEIFS('RD Condos'!$AN:$AN,'RD Condos'!$A:$A,1),"") | J8: ='RD Condos'!B8 | K8: ='RD Condos'!U8 | L8: =IF('RD Condos'!H8="2",1,0) | M8: =IF('RD Condos'!H8="3",1,0) | N8: ='RD Condos'!AB8 | P8: 1BR wt (manual) | Q8: 0.46
A9: By Bedroom — all comps (den-incl.) | J9: ='RD Condos'!B9 | K9: ='RD Condos'!U9 | L9: =IF('RD Condos'!H9="2",1,0) | M9: =IF('RD Condos'!H9="3",1,0) | N9: ='RD Condos'!AB9 | P9: 2BR wt (manual) | Q9: 0.45
A10: Beds | B10: Incl. | C10: Avg SF | D10: Avg Rent | E10: Avg $/SF | J10: ='RD Condos'!B10 | K10: ='RD Condos'!U10 | L10: =IF('RD Condos'!H10="2",1,0) | M10: =IF('RD Condos'!H10="3",1,0) | N10: ='RD Condos'!AB10 | P10: 3BR wt (manual) | Q10: 0.09
A11: 1 Bed | B11: =COUNTIFS('RD Condos'!$H:$H,"1",'RD Condos'!$A:$A,1) | C11: =IFERROR(AVERAGEIFS('RD Condos'!$B:$B,'RD Condos'!$H:$H,"1",'RD Condos'!$A:$A,1),"") | D11: =IFERROR(AVERAGEIFS('RD Condos'!$AB:$AB,'RD Condos'!$H:$H,"1",'RD Condos'!$A:$A,1),"") | E11: =IFERROR(AVERAGEIFS('RD Condos'!$AN:$AN,'RD Condos'!$H:$H,"1",'RD Condos'!$A:$A,1),"") | J11: ='RD Condos'!B11 | K11: ='RD Condos'!U11 | L11: =IF('RD Condos'!H11="2",1,0) | M11: =IF('RD Condos'!H11="3",1,0) | N11: ='RD Condos'!AB11
A12: 2 Bed | B12: =COUNTIFS('RD Condos'!$H:$H,"2",'RD Condos'!$A:$A,1) | C12: =IFERROR(AVERAGEIFS('RD Condos'!$B:$B,'RD Condos'!$H:$H,"2",'RD Condos'!$A:$A,1),"") | D12: =IFERROR(AVERAGEIFS('RD Condos'!$AB:$AB,'RD Condos'!$H:$H,"2",'RD Condos'!$A:$A,1),"") | E12: =IFERROR(AVERAGEIFS('RD Condos'!$AN:$AN,'RD Condos'!$H:$H,"2",'RD Condos'!$A:$A,1),"") | J12: ='RD Condos'!B12 | K12: ='RD Condos'!U12 | L12: =IF('RD Condos'!H12="2",1,0) | M12: =IF('RD Condos'!H12="3",1,0) | N12: ='RD Condos'!AB12
A13: 3 Bed | B13: =COUNTIFS('RD Condos'!$H:$H,"3",'RD Condos'!$A:$A,1) | C13: =IFERROR(AVERAGEIFS('RD Condos'!$B:$B,'RD Condos'!$H:$H,"3",'RD Condos'!$A:$A,1),"") | D13: =IFERROR(AVERAGEIFS('RD Condos'!$AB:$AB,'RD Condos'!$H:$H,"3",'RD Condos'!$A:$A,1),"") | E13: =IFERROR(AVERAGEIFS('RD Condos'!$AN:$AN,'RD Condos'!$H:$H,"3",'RD Condos'!$A:$A,1),"") | J13: ='RD Condos'!B13 | K13: ='RD Condos'!U13 | L13: =IF('RD Condos'!H13="2",1,0) | M13: =IF('RD Condos'!H13="3",1,0) | N13: ='RD Condos'!AB13
J14: ='RD Condos'!B14 | K14: ='RD Condos'!U14 | L14: =IF('RD Condos'!H14="2",1,0) | M14: =IF('RD Condos'!H14="3",1,0) | N14: ='RD Condos'!AB14
A15: By Bedroom — The Humber only (new-build basis) | J15: ='RD Condos'!B15 | K15: ='RD Condos'!U15 | L15: =IF('RD Condos'!H15="2",1,0) | M15: =IF('RD Condos'!H15="3",1,0) | N15: ='RD Condos'!AB15
A16: Beds | B16: Incl. | C16: Avg SF | D16: Avg Rent | E16: $/SF | F16: Subj Rent (+prem) | J16: ='RD Condos'!B16 | K16: ='RD Condos'!U16 | L16: =IF('RD Condos'!H16="2",1,0) | M16: =IF('RD Condos'!H16="3",1,0) | N16: ='RD Condos'!AB16
A17: 1 Bed | B17: =COUNTIFS('RD Condos'!$K:$K,"The Humber",'RD Condos'!$H:$H,"1",'RD Condos'!$A:$A,1) | C17: =IFERROR(AVERAGEIFS('RD Condos'!$B:$B,'RD Condos'!$K:$K,"The Humber",'RD Condos'!$H:$H,"1",'RD Condos'!$A:$A,1),"") | D17: =IFERROR(AVERAGEIFS('RD Condos'!$AB:$AB,'RD Condos'!$K:$K,"The Humber",'RD Condos'!$H:$H,"1",'RD Condos'!$A:$A,1),"") | E17: =IFERROR(AVERAGEIFS('RD Condos'!$E:$E,'RD Condos'!$K:$K,"The Humber",'RD Condos'!$H:$H,"1",'RD Condos'!$A:$A,1),"") | F17: =IFERROR(D17*(1+$C$4),"") | J17: ='RD Condos'!B17 | K17: ='RD Condos'!U17 | L17: =IF('RD Condos'!H17="2",1,0) | M17: =IF('RD Condos'!H17="3",1,0) | N17: ='RD Condos'!AB17
A18: 2 Bed | B18: =COUNTIFS('RD Condos'!$K:$K,"The Humber",'RD Condos'!$H:$H,"2",'RD Condos'!$A:$A,1) | C18: =IFERROR(AVERAGEIFS('RD Condos'!$B:$B,'RD Condos'!$K:$K,"The Humber",'RD Condos'!$H:$H,"2",'RD Condos'!$A:$A,1),"") | D18: =IFERROR(AVERAGEIFS('RD Condos'!$AB:$AB,'RD Condos'!$K:$K,"The Humber",'RD Condos'!$H:$H,"2",'RD Condos'!$A:$A,1),"") | E18: =IFERROR(AVERAGEIFS('RD Condos'!$E:$E,'RD Condos'!$K:$K,"The Humber",'RD Condos'!$H:$H,"2",'RD Condos'!$A:$A,1),"") | F18: =IFERROR(D18*(1+$C$4),"") | J18: ='RD Condos'!B18 | K18: ='RD Condos'!U18 | L18: =IF('RD Condos'!H18="2",1,0) | M18: =IF('RD Condos'!H18="3",1,0) | N18: ='RD Condos'!AB18
A19: 3 Bed | B19: =COUNTIFS('RD Condos'!$K:$K,"The Humber",'RD Condos'!$H:$H,"3",'RD Condos'!$A:$A,1) | C19: =IFERROR(AVERAGEIFS('RD Condos'!$B:$B,'RD Condos'!$K:$K,"The Humber",'RD Condos'!$H:$H,"3",'RD Condos'!$A:$A,1),"") | D19: =IFERROR(AVERAGEIFS('RD Condos'!$AB:$AB,'RD Condos'!$K:$K,"The Humber",'RD Condos'!$H:$H,"3",'RD Condos'!$A:$A,1),"") | E19: =IFERROR(AVERAGEIFS('RD Condos'!$E:$E,'RD Condos'!$K:$K,"The Humber",'RD Condos'!$H:$H,"3",'RD Condos'!$A:$A,1),"") | F19: =IFERROR(D19*(1+$C$4),"") | J19: ='RD Condos'!B19 | K19: ='RD Condos'!U19 | L19: =IF('RD Condos'!H19="2",1,0) | M19: =IF('RD Condos'!H19="3",1,0) | N19: ='RD Condos'!AB19
J20: ='RD Condos'!B20 | K20: ='RD Condos'!U20 | L20: =IF('RD Condos'!H20="2",1,0) | M20: =IF('RD Condos'!H20="3",1,0) | N20: ='RD Condos'!AB20
A21: SUBJECT RECOMMENDATION (comp $/SF + premium) | J21: ='RD Condos'!B21 | K21: ='RD Condos'!U21 | L21: =IF('RD Condos'!H21="2",1,0) | M21: =IF('RD Condos'!H21="3",1,0) | N21: ='RD Condos'!AB21
A22: Weighted comp $/SF — Humber basis | C22: =E17*$H$2+E18*$H$3+E19*$H$4 | J22: ='RD Condos'!B22 | K22: ='RD Condos'!U22 | L22: =IF('RD Condos'!H22="2",1,0) | M22: =IF('RD Condos'!H22="3",1,0) | N22: ='RD Condos'!AB22
A23: Weighted comp $/SF — all-comp basis | C23: =E11*$H$2+E12*$H$3+E13*$H$4 | J23: ='RD Condos'!B23 | K23: ='RD Condos'!U23 | L23: =IF('RD Condos'!H23="2",1,0) | M23: =IF('RD Condos'!H23="3",1,0) | N23: ='RD Condos'!AB23
A24: Subject rental premium | C24: =C4 | J24: ='RD Condos'!B24 | K24: ='RD Condos'!U24 | L24: =IF('RD Condos'!H24="2",1,0) | M24: =IF('RD Condos'!H24="3",1,0) | N24: ='RD Condos'!AB24
A25: RECOMMENDED subject $/SF (Humber + premium) | C25: =C22*(1+C4) | J25: ='RD Condos'!B25 | K25: ='RD Condos'!U25 | L25: =IF('RD Condos'!H25="2",1,0) | M25: =IF('RD Condos'!H25="3",1,0) | N25: ='RD Condos'!AB25
A26: Subject $/SF (all-comp + premium) | C26: =C23*(1+C4) | J26: ='RD Condos'!B26 | K26: ='RD Condos'!U26 | L26: =IF('RD Condos'!H26="2",1,0) | M26: =IF('RD Condos'!H26="3",1,0) | N26: ='RD Condos'!AB26
A27: Prior model subject (Data_Old, 2024-anchored) | C27: 3.9
A28: Residual vs prior (market timing etc.) | C28: =C25/C27-1
A30: PREMIUM BASIS (live) — vintage $/SF spread anchoring the subject premium (C4)
A31: Metric | C31: $/SF
A32: Newest comp avg $/SF | C32: =IFERROR(AVERAGEIFS('RD Condos'!$E:$E,'RD Condos'!$K:$K,"The Humber",'RD Condos'!$A:$A,1),"") | D32: Single-comp set → newest = oldest = the only comp; vintage spread is 0% here. Replace per subject.
A33: All-comp avg $/SF | C33: =IFERROR(AVERAGEIFS('RD Condos'!$AN:$AN,'RD Condos'!$A:$A,1),"")
A34: Oldest comp avg $/SF | C34: =IFERROR(AVERAGEIFS('RD Condos'!$E:$E,'RD Condos'!$K:$K,"The Humber",'RD Condos'!$A:$A,1),"")
A35: Observed vintage premium — newest ÷ all-comp − 1 | C35: =IFERROR(C32/C33-1,"")
A36: Observed vintage premium — newest ÷ oldest − 1 | C36: =IFERROR(C32/C34-1,"")
A37: Subject premium C4 (sits within observed range) | C37: =C4
A39: MIX BASIS (live) — comp-set bed distribution vs the estimated subject mix (x-check on H2:H4)
A40: Bucket | B40: Comp # | C40: Comp share | D40: Subject est.
A41: 1-Bed (H=1, den-incl) | B41: =COUNTIFS('RD Condos'!$H:$H,"1",'RD Condos'!$A:$A,1) | C41: =IFERROR(B41/$B$44,"") | D41: =H2
A42: 2-Bed (H=2, incl 2+den) | B42: =COUNTIFS('RD Condos'!$H:$H,"2",'RD Condos'!$A:$A,1) | C42: =IFERROR(B42/$B$44,"") | D42: =H3
...

Sheet RD Condos
A1: Include | B1: Sq Ft. | C1: Rent | D1: Adj. Rent | E1: $/sq ft | F1: Adj. $/sq ft | G1: Adj BD | H1: Beds Number | I1: Den | J1: Date | K1: Building Name | L1: Building Address | M1: Building City | N1: Developer | O1: Unit # | P1: Unit Address | Q1: Beds | R1: Baths | S1: Sqft (Condos.ca) | T1: MLS Size Range | U1: # Parking | V1: Parking Included | W1: Locker | X1: Outdoor Space | Y1: Exposure | Z1: Building Age | AA1: Building Amenities | AB1: Leased Rent ($) | AC1: Listed Rent ($) | AD1: PSF (Calculated) | AE1: PSF (Listing) | AF1: Furnished | AG1: Hydro Included | AH1: Water Included | AI1: Lease Date | AJ1: MLS# | AK1: Listing URL | AL1: Description | AM1: Product Type | AN1: $/SF (Product-Adj) | AO1: Date Scraped | AP1: SF Verification Status | AQ1: SF Source Type | AR1: SF Source / URL | AS1: SF Explanation / Not Validated Reason
A2: =IF(AND(ISNUMBER(B2),B2>0,ISNUMBER(AB2),AB2>0,J2>=Data_Summary!$C$1),1,0) | B2: 694 | C2: =IF(ISNUMBER(AB2),AB2,"") | D2: =IF(ISNUMBER(C2),C2-U2*Data_Summary!$C$2,"") | E2: =IFERROR(C2/B2,"") | F2: =IFERROR(D2/B2,"") | G2: =Q2 | H2: =IFERROR(LEFT(G2,1),"") | I2: =IF(LEN(G2)>1,1,0) | J2: 46136 | K2: The Humber | L2: 10 Wilby Crescent | M2: Toronto (Weston) | N2: Options for Homes | O2: 1602 | P2: 1602 - 10 Wilby Crescent | Q2: 2 | R2: 2 | S2: 694 | T2: 600-699 sqft | U2: 1 | V2: Yes | W2: Ensuite | X2: Balcony, Patio | Y2: W | Z2: Built 2023 (3 yrs) | AA2: Gym, Party Room, Rooftop Deck, Visitor Parking, BBQ, Bike Storage, Concierge, Coin Laundry | AB2: 2450 | AC2: 2450 | AD2: =IFERROR(AB2/B2,"") | AE2: =IFERROR(AC2/B2,"") | AF2: No | AG2: No | AH2: No | AI2: 2026-04-24 | AJ2: W12626670 | AK2: https://condos.ca/toronto/the-humber-10-wilby-crescent-10-wilby-cres/unit-1602-W12626670 | AL2: Leased comp. SF: Verified (condos.ca per-unit). | AM2: Condo | AN2: =IFERROR(E2*(1+IF(AM2="Apartment",Data_Summary!$C$3,0)),"") | AP2: Verified registered area | AQ2: condos.ca registered area | AS2: condos.ca per-unit registered area; used in $/SF. (template row)
A3: =IF(AND(ISNUMBER(B3),B3>0,ISNUMBER(AB3),AB3>0,J3>=Data_Summary!$C$1),1,0) | B3: 694 | C3: =IF(ISNUMBER(AB3),AB3,"") | D3: =IF(ISNUMBER(C3),C3-U3*Data_Summary!$C$2,"") | E3: =IFERROR(C3/B3,"") | F3: =IFERROR(D3/B3,"") | G3: =Q3 | H3: =IFERROR(LEFT(G3,1),"") | I3: =IF(LEN(G3)>1,1,0) | J3: 46134 | K3: The Humber | L3: 10 Wilby Crescent | M3: Toronto (Weston) | N3: Options for Homes | O3: 409 | P3: 409 - 10 Wilby Crescent | Q3: 1+1 | R3: 1 | S3: 694 | T3: 600-699 sqft | U3: 0 | V3: No | W3: None | X3: Balcony, Patio | Y3: S | Z3: Built 2023 (3 yrs) | AA3: Gym, Party Room, Rooftop Deck, Visitor Parking, BBQ, Bike Storage, Concierge, Coin Laundry | AB3: 2000 | AC3: 2050 | AD3: =IFERROR(AB3/B3,"") | AE3: =IFERROR(AC3/B3,"") | AF3: No | AG3: No | AH3: No | AI3: 2026-04-22 | AJ3: W12873004 | AK3: https://condos.ca/toronto/the-humber-10-wilby-crescent-10-wilby-cres/unit-409-W12873004 | AL3: Leased comp. SF: Verified (condos.ca per-unit). | AM3: Condo | AN3: =IFERROR(E3*(1+IF(AM3="Apartment",Data_Summary!$C$3,0)),"") | AP3: Verified registered area | AQ3: condos.ca registered area | AS3: condos.ca per-unit registered area; used in $/SF. (template row)
A4: =IF(AND(ISNUMBER(B4),B4>0,ISNUMBER(AB4),AB4>0,J4>=Data_Summary!$C$1),1,0) | B4: 715 | C4: =IF(ISNUMBER(AB4),AB4,"") | D4: =IF(ISNUMBER(C4),C4-U4*Data_Summary!$C$2,"") | E4: =IFERROR(C4/B4,"") | F4: =IFERROR(D4/B4,"") | G4: =Q4 | H4: =IFERROR(LEFT(G4,1),"") | I4: =IF(LEN(G4)>1,1,0) | J4: 46133 | K4: The Humber | L4: 10 Wilby Crescent | M4: Toronto (Weston) | N4: Options for Homes | O4: 1807 | P4: 1807 - 10 Wilby Crescent | Q4: 2 | R4: 2 | S4: 715 | T4: 700-799 sqft | U4: 1 | V4: Yes | W4: Owned | X4: Balcony, Patio | Y4: NE | Z4: Built 2023 (3 yrs) | AA4: Gym, Party Room, Rooftop Deck, Visitor Parking, BBQ, Bike Storage, Concierge, Coin Laundry | AB4: 2350 | AC4: 2400 | AD4: =IFERROR(AB4/B4,"") | AE4: =IFERROR(AC4/B4,"") | AF4: No | AG4: No | AH4: No | AI4: 2026-04-21 | AJ4: W12930642 | AK4: https://condos.ca/toronto/the-humber-10-wilby-crescent-10-wilby-cres/unit-1807-W12930642 | AL4: Leased comp. SF: Verified (condos.ca per-unit). | AM4: Condo | AN4: =IFERROR(E4*(1+IF(AM4="Apartment",Data_Summary!$C$3,0)),"") | AP4: Verified registered area | AQ4: condos.ca registered area | AS4: condos.ca per-unit registered area; used in $/SF. (template row)
A5: =IF(AND(ISNUMBER(B5),B5>0,ISNUMBER(AB5),AB5>0,J5>=Data_Summary!$C$1),1,0) | B5: 617 | C5: =IF(ISNUMBER(AB5),AB5,"") | D5: =IF(ISNUMBER(C5),C5-U5*Data_Summary!$C$2,"") | E5: =IFERROR(C5/B5,"") | F5: =IFERROR(D5/B5,"") | G5: =Q5 | H5: =IFERROR(LEFT(G5,1),"") | I5: =IF(LEN(G5)>1,1,0) | J5: 46125 | K5: The Humber | L5: 10 Wilby Crescent | M5: Toronto (Weston) | N5: Options for Homes | O5: 204 | P5: 204 - 10 Wilby Crescent | Q5: 1 | R5: 1 | S5: 617 | T5: 600-699 sqft | U5: 1 | V5: Yes | W5: Owned | X5: Balcony, Patio | Y5: E | Z5: Built 2023 (3 yrs) | AA5: Gym, Party Room, Rooftop Deck, Visitor Parking, BBQ, Bike Storage, Concierge, Coin Laundry | AB5: 1999 | AC5: 1999 | AD5: =IFERROR(AB5/B5,"") | AE5: =IFERROR(AC5/B5,"") | AF5: No | AG5: No | AH5: No | AI5: 2026-04-13 | AJ5: W12051218 | AK5: https://condos.ca/toronto/the-humber-10-wilby-crescent-10-wilby-cres/unit-204-W12051218 | AL5: Leased comp. SF: Verified (condos.ca per-unit). | AM5: Condo | AN5: =IFERROR(E5*(1+IF(AM5="Apartment",Data_Summary!$C$3,0)),"") | AP5: Verified registered area | AQ5: condos.ca registered area | AS5: condos.ca per-unit registered area; used in $/SF. (template row)
A6: =IF(AND(ISNUMBER(B6),B6>0,ISNUMBER(AB6),AB6>0,J6>=Data_Summary!$C$1),1,0) | B6: 751 | C6: =IF(ISNUMBER(AB6),AB6,"") | D6: =IF(ISNUMBER(C6),C6-U6*Data_Summary!$C$2,"") | E6: =IFERROR(C6/B6,"") | F6: =IFERROR(D6/B6,"") | G6: =Q6 | H6: =IFERROR(LEFT(G6,1),"") | I6: =IF(LEN(G6)>1,1,0) | J6: 46113 | K6: The Humber | L6: 10 Wilby Crescent | M6: Toronto (Weston) | N6: Options for Homes | O6: 202 | P6: 202 - 10 Wilby Crescent | Q6: 1+1 | R6: 2 | S6: 751 | T6: 700-799 sqft | U6: 0 | V6: No | W6: None | X6: Balcony, Patio | Y6: NE | Z6: Built 2023 (3 yrs) | AA6: Gym, Party Room, Rooftop Deck, Visitor Parking, BBQ, Bike Storage, Concierge, Coin Laundry | AB6: 2100 | AC6: 2100 | AD6: =IFERROR(AB6/B6,"") | AE6: =IFERROR(AC6/B6,"") | AF6: No | AG6: No | AH6: No | AI6: 2026-04-01 | AJ6: W12462017 | AK6: https://condos.ca/toronto/the-humber-10-wilby-crescent-10-wilby-cres/unit-202-W12462017 | AL6: Leased comp. SF: Verified (condos.ca per-unit). | AM6: Condo | AN6: =IFERROR(E6*(1+IF(AM6="Apartment",Data_Summary!$C$3,0)),"") | AP6: Verified registered area | AQ6: condos.ca registered area | AS6: condos.ca per-unit registered area; used in $/SF. (template row)
A7: =IF(AND(ISNUMBER(B7),B7>0,ISNUMBER(AB7),AB7>0,J7>=Data_Summary!$C$1),1,0) | B7: 816 | C7: =IF(ISNUMBER(AB7),AB7,"") | D7: =IF(ISNUMBER(C7),C7-U7*Data_Summary!$C$2,"") | E7: =IFERROR(C7/B7,"") | F7: =IFERROR(D7/B7,"") | G7: =Q7 | H7: =IFERROR(LEFT(G7,1),"") | I7: =IF(LEN(G7)>1,1,0) | J7: 46109 | K7: The Humber | L7: 10 Wilby Crescent | M7: Toronto (Weston) | N7: Options for Homes | O7: 1409 | P7: 1409 - 10 Wilby Crescent | Q7: 2 | R7: 2 | S7: 816 | T7: 800-899 sqft | U7: 1 | V7: Yes | W7: None | X7: Balcony, Patio | Y7: E | Z7: Built 2023 (3 yrs) | AA7: Gym, Party Room, Rooftop Deck, Visitor Parking, BBQ, Bike Storage, Concierge, Coin Laundry | AB7: 2575 | AC7: 2600 | AD7: =IFERROR(AB7/B7,"") | AE7: =IFERROR(AC7/B7,"") | AF7: No | AG7: No | AH7: No | AI7: 2026-03-28 | AJ7: W12430606 | AK7: https://condos.ca/toronto/the-humber-10-wilby-crescent-10-wilby-cres/unit-1409-W12430606 | AL7: Leased comp. SF: Verified (condos.ca per-unit). | AM7: Condo | AN7: =IFERROR(E7*(1+IF(AM7="Apartment",Data_Summary!$C$3,0)),"") | AP7: Verified registered area | AQ7: condos.ca registered area | AS7: condos.ca per-unit registered area; used in $/SF. (template row)
A8: =IF(AND(ISNUMBER(B8),B8>0,ISNUMBER(AB8),AB8>0,J8>=Data_Summary!$C$1),1,0) | B8: 583 | C8: =IF(ISNUMBER(AB8),AB8,"") | D8: =IF(ISNUMBER(C8),C8-U8*Data_Summary!$C$2,"") | E8: =IFERROR(C8/B8,"") | F8: =IFERROR(D8/B8,"") | G8: =Q8 | H8: =IFERROR(LEFT(G8,1),"") | I8: =IF(LEN(G8)>1,1,0) | J8: 46105 | K8: The Humber | L8: 10 Wilby Crescent | M8: Toronto (Weston) | N8: Options for Homes | O8: 1005 | P8: 1005 - 10 Wilby Crescent | Q8: 1+1 | R8: 1 | S8: 583 | T8: 500-599 sqft | U8: 1 | V8: Yes | W8: Owned | X8: Balcony, Patio | Y8: S | Z8: Built 2023 (3 yrs) | AA8: Gym, Party Room, Rooftop Deck, Visitor Parking, BBQ, Bike Storage, Concierge, Coin Laundry | AB8: 2200 | AC8: 2200 | AD8: =IFERROR(AB8/B8,"") | AE8: =IFERROR(AC8/B8,"") | AF8: No | AG8: No | AH8: No | AI8: 2026-03-24 | AJ8: W12848862 | AK8: https://condos.ca/toronto/the-humber-10-wilby-crescent-10-wilby-cres/unit-1005-W12848862 | AL8: Leased comp. SF: Verified (condos.ca per-unit). | AM8: Condo | AN8: =IFERROR(E8*(1+IF(AM8="Apartment",Data_Summary!$C$3,0)),"") | AP8: Verified registered area | AQ8: condos.ca registered area | AS8: condos.ca per-unit registered area; used in $/SF. (template row)
A9: =IF(AND(ISNUMBER(B9),B9>0,ISNUMBER(AB9),AB9>0,J9>=Data_Summary!$C$1),1,0) | B9: 988 | C9: =IF(ISNUMBER(AB9),AB9,"") | D9: =IF(ISNUMBER(C9),C9-U9*Data_Summary!$C$2,"") | E9: =IFERROR(C9/B9,"") | F9: =IFERROR(D9/B9,"") | G9: =Q9 | H9: =IFERROR(LEFT(G9,1),"") | I9: =IF(LEN(G9)>1,1,0) | J9: 46084 | K9: The Humber | L9: 10 Wilby Crescent | M9: Toronto (Weston) | N9: Options for Homes | O9: 1206 | P9: 1206 - 10 Wilby Crescent | Q9: 3 | R9: 2 | S9: 988 | T9: 900-999 sqft | U9: 0 | V9: No | W9: Owned | X9: Balcony, Patio | Y9: SW | Z9: Built 2023 (3 yrs) | AA9: Gym, Party Room, Rooftop Deck, Visitor Parking, BBQ, Bike Storage, Concierge, Coin Laundry | AB9: 2550 | AC9: 2700 | AD9: =IFERROR(AB9/B9,"") | AE9: =IFERROR(AC9/B9,"") | AF9: No | AG9: No | AH9: No | AI9: 2026-03-03 | AJ9: W12473063 | AK9: https://condos.ca/toronto/the-humber-10-wilby-crescent-10-wilby-cres/unit-1206-W12473063 | AL9: Leased comp. SF: Verified (condos.ca per-unit). | AM9: Condo | AN9: =IFERROR(E9*(1+IF(AM9="Apartment",Data_Summary!$C$3,0)),"") | AP9: Verified registered area | AQ9: condos.ca registered area | AS9: condos.ca per-unit registered area; used in $/SF. (template row)
A10: =IF(AND(ISNUMBER(B10),B10>0,ISNUMBER(AB10),AB10>0,J10>=Data_Summary!$C$1),1,0) | B10: 694 | C10: =IF(ISNUMBER(AB10),AB10,"") | D10: =IF(ISNUMBER(C10),C10-U10*Data_Summary!$C$2,"") | E10: =IFERROR(C10/B10,"") | F10: =IFERROR(D10/B10,"") | G10: =Q10 | H10: =IFERROR(LEFT(G10,1),"") | I10: =IF(LEN(G10)>1,1,0) | J10: 46044 | K10: The Humber | L10: 10 Wilby Crescent | M10: Toronto (Weston) | N10: Options for Homes | O10: 308 | P10: 308 - 10 Wilby Crescent | Q10: 1+1 | R10: 1 | S10: 694 | T10: 600-699 sqft | U10: 1 | V10: Yes | W10: Owned | X10: Balcony, Patio | Y10: S | Z10: Built 2023 (3 yrs) | AA10: Gym, Party Room, Rooftop Deck, Visitor Parking, BBQ, Bike Storage, Concierge, Coin Laundry | AB10: 2199 | AC10: 2199 | AD10: =IFERROR(AB10/B10,"") | AE10: =IFERROR(AC10/B10,"") | AF10: No | AG10: No | AH10: No | AI10: 2026-01-22 | AJ10: W12686952 | AK10: https://condos.ca/toronto/the-humber-10-wilby-crescent-10-wilby-cres/unit-308-W12686952 | AL10: Leased comp. SF: Verified (condos.ca per-unit). | AM10: Condo | AN10: =IFERROR(E10*(1+IF(AM10="Apartment",Data_Summary!$C$3,0)),"") | AP10: Verified registered area | AQ10: condos.ca registered area | AS10: condos.ca per-unit registered area; used in $/SF. (template row)
A11: =IF(AND(ISNUMBER(B11),B11>0,ISNUMBER(AB11),AB11>0,J11>=Data_Summary!$C$1),1,0) | B11: 588 | C11: =IF(ISNUMBER(AB11),AB11,"") | D11: =IF(ISNUMBER(C11),C11-U11*Data_Summary!$C$2,"") | E11: =IFERROR(C11/B11,"") | F11: =IFERROR(D11/B11,"") | G11: =Q11 | H11: =IFERROR(LEFT(G11,1),"") | I11: =IF(LEN(G11)>1,1,0) | J11: 46043 | K11: The Humber | L11: 10 Wilby Crescent | M11: Toronto (Weston) | N11: Options for Homes | O11: 2004 | P11: 2004 - 10 Wilby Crescent | Q11: 1+1 | R11: 1 | S11: 588 | T11: 500-599 sqft | U11: 0 | V11: No | W11: Owned | X11: Balcony, Patio | Y11: W | Z11: Built 2023 (3 yrs) | AA11: Gym, Party Room, Rooftop Deck, Visitor Parking, BBQ, Bike Storage, Concierge, Coin Laundry | AB11: 2100 | AC11: 2100 | AD11: =IFERROR(AB11/B11,"") | AE11: =IFERROR(AC11/B11,"") | AF11: Yes | AG11: No | AH11: No | AI11: 2026-01-21 | AJ11: W12460996 | AK11: https://condos.ca/toronto/the-humber-10-wilby-crescent-10-wilby-cres/unit-2004-W12460996 | AL11: Leased comp. SF: Verified (condos.ca per-unit). | AM11: Condo | AN11: =IFERROR(E11*(1+IF(AM11="Apartment",Data_Summary!$C$3,0)),"") | AP11: Verified registered area | AQ11: condos.ca registered area | AS11: condos.ca per-unit registered area; used in $/SF. (template row)
A12: =IF(AND(ISNUMBER(B12),B12>0,ISNUMBER(AB12),AB12>0,J12>=Data_Summary!$C$1),1,0) | B12: 694 | C12: =IF(ISNUMBER(AB12),AB12,"") | D12: =IF(ISNUMBER(C12),C12-U12*Data_Summary!$C$2,"") | E12: =IFERROR(C12/B12,"") | F12: =IFERROR(D12/B12,"") | G12: =Q12 | H12: =IFERROR(LEFT(G12,1),"") | I12: =IF(LEN(G12)>1,1,0) | J12: 46009 | K12: The Humber | L12: 10 Wilby Crescent | M12: Toronto (Weston) | N12: Options for Homes | O12: 2102 | P12: 2102 - 10 Wilby Crescent | Q12: 2 | R12: 2 | S12: 694 | T12: 600-699 sqft | U12: 1 | V12: Yes | W12: Owned | X12: Balcony, Patio | Y12: S | Z12: Built 2023 (3 yrs) | AA12: Gym, Party Room, Rooftop Deck, Visitor Parking, BBQ, Bike Storage, Concierge, Coin Laundry | AB12: 2400 | AC12: 2400 | AD12: =IFERROR(AB12/B12,"") | AE12: =IFERROR(AC12/B12,"") | AF12: No | AG12: No | AH12: No | AI12: 2025-12-18 | AJ12: W12372035 | AK12: https://condos.ca/toronto/the-humber-10-wilby-crescent-10-wilby-cres/unit-2102-W12372035 | AL12: Leased comp. SF: Verified (condos.ca per-unit). | AM12: Condo | AN12: =IFERROR(E12*(1+IF(AM12="Apartment",Data_Summary!$C$3,0)),"") | AP12: Verified registered area | AQ12: condos.ca registered area | AS12: condos.ca per-unit registered area; used in $/SF. (template row)
A13: =IF(AND(ISNUMBER(B13),B13>0,ISNUMBER(AB13),AB13>0,J13>=Data_Summary!$C$1),1,0) | B13: 788 | C13: =IF(ISNUMBER(AB13),AB13,"") | D13: =IF(ISNUMBER(C13),C13-U13*Data_Summary!$C$2,"") | E13: =IFERROR(C13/B13,"") | F13: =IFERROR(D13/B13,"") | G13: =Q13 | H13: =IFERROR(LEFT(G13,1),"") | I13: =IF(LEN(G13)>1,1,0) | J13: 45959 | K13: The Humber | L13: 10 Wilby Crescent | M13: Toronto (Weston) | N13: Options for Homes | O13: 405 | P13: 405 - 10 Wilby Crescent | Q13: 2 | R13: 2 | S13: 788 | T13: 700-799 sqft | U13: 1 | V13: Yes | W13: Owned | X13: Balcony, Patio | Y13: NE | Z13: Built 2023 (3 yrs) | AA13: Gym, Party Room, Rooftop Deck, Visitor Parking, BBQ, Bike Storage, Concierge, Coin Laundry | AB13: 2600 | AC13: 2600 | AD13: =IFERROR(AB13/B13,"") | AE13: =IFERROR(AC13/B13,"") | AF13: No | AG13: No | AH13: No | AI13: 2025-10-29 | AJ13: W12432828 | AK13: https://condos.ca/toronto/the-humber-10-wilby-crescent-10-wilby-cres/unit-405-W12432828 | AL13: Leased comp. SF: Verified (condos.ca per-unit). | AM13: Condo | AN13: =IFERROR(E13*(1+IF(AM13="Apartment",Data_Summary!$C$3,0)),"") | AP13: Verified registered area | AQ13: condos.ca registered area | AS13: condos.ca per-unit registered area; used in $/SF. (template row)
... A26: =IF(AND(ISNUMBER(B26),B26>0,ISNUMBER(AB26),AB26>0,J26>=Data_Summary!$C$1),1,0) | B26: 694 | C26: =IF(ISNUMBER(AB26),AB26,"") | D26: =IF(ISNUMBER(C26),C26-U26*Data_Summary!$C$2,"") | E26: =IFERROR(C26/B26,"") | F26: =IFERROR(D26/B26,"") | G26: =Q26 | H26: =IFERROR(LEFT(G26,1),"") | I26: =IF(LEN(G26)>1,1,0) | J26: 45758 | K26: The Humber | L26: 10 Wilby Crescent | M26: Toronto (Weston) | N26: Options for Homes | O26: 309 | P26: 309 - 10 Wilby Crescent | Q26: 1+1 | R26: 1 | S26: 694 | T26: 600-699 sqft | U26: 0 | V26: No | W26: None | X26: Balcony, Patio | Y26: SW | Z26: Built 2023 (3 yrs) | AA26: Gym, Party Room, Rooftop Deck, Visitor Parking, BBQ, Bike Storage, Concierge, Coin Laundry | AB26: 2150 | AC26: 2150 | AD26: =IFERROR(AB26/B26,"") | AE26: =IFERROR(AC26/B26,"") | AF26: No | AG26: No | AH26: No | AI26: 2025-04-11 | AJ26: W12051780 | AK26: https://condos.ca/toronto/the-humber-10-wilby-crescent-10-wilby-cres/unit-309-W12051780 | AL26: Leased comp. SF: Verified (condos.ca per-unit). | AM26: Condo | AN26: =IFERROR(E26*(1+IF(AM26="Apartment",Data_Summary!$C$3,0)),"") | AP26: Verified registered area | AQ26: condos.ca registered area | AS26: condos.ca per-unit registered area; used in $/SF. (template row)
A27: =IF(AND(ISNUMBER(B27),B27>0,ISNUMBER(AB27),AB27>0,J27>=Data_Summary!$C$1),1,0) | B27: 715 | C27: =IF(ISNUMBER(AB27),AB27,"") | D27: =IF(ISNUMBER(C27),C27-U27*Data_Summary!$C$2,"") | E27: =IFERROR(C27/B27,"") | F27: =IFERROR(D27/B27,"") | G27: =Q27 | H27: =IFERROR(LEFT(G27,1),"") | I27: =IF(LEN(G27)>1,1,0) | J27: 46162 | K27: The Humber | L27: 10 Wilby Crescent | M27: Toronto (Weston) | N27: Options for Homes | O27: 907 | P27: 907 - 10 Wilby Crescent | Q27: 2 | R27: 2 | S27: 715 | T27: 700-799 sqft | U27: 1 | V27: Yes | W27: None | X27: Balcony, Patio | Y27: NE | Z27: Built 2023 (3 yrs) | AA27: Gym, Party Room, Rooftop Deck, Visitor Parking, BBQ, Bike Storage, Concierge, Coin Laundry | AC27: 2400 | AD27: =IFERROR(AB27/B27,"") | AE27: =IFERROR(AC27/B27,"") | AF27: No | AG27: No | AH27: No | AI27: 2026-05-20 | AJ27: W13150160 | AK27: https://condos.ca/toronto/the-humber-10-wilby-crescent-10-wilby-cres/unit-907-W13150160 | AL27: ACTIVE asking rent (not a closed lease). SF verified. | AM27: Condo | AN27: =IFERROR(E27*(1+IF(AM27="Apartment",Data_Summary!$C$3,0)),"") | AP27: Verified registered area | AQ27: condos.ca registered area | AS27: condos.ca per-unit registered area; used in $/SF. (template row)
A28: =IF(AND(ISNUMBER(B28),B28>0,ISNUMBER(AB28),AB28>0,J28>=Data_Summary!$C$1),1,0) | B28: 715 | C28: =IF(ISNUMBER(AB28),AB28,"") | D28: =IF(ISNUMBER(C28),C28-U28*Data_Summary!$C$2,"") | E28: =IFERROR(C28/B28,"") | F28: =IFERROR(D28/B28,"") | G28: =Q28 | H28: =IFERROR(LEFT(G28,1),"") | I28: =IF(LEN(G28)>1,1,0) | J28: 46164 | K28: The Humber | L28: 10 Wilby Crescent | M28: Toronto (Weston) | N28: Options for Homes | O28: 1407 | P28: 1407 - 10 Wilby Crescent | Q28: 2 | R28: 2 | S28: 715 | T28: 700-799 sqft | U28: 0 | V28: No | W28: None | X28: Balcony, Patio | Y28: NE | Z28: Built 2023 (3 yrs) | AA28: Gym, Party Room, Rooftop Deck, Visitor Parking, BBQ, Bike Storage, Concierge, Coin Laundry | AC28: 2500 | AD28: =IFERROR(AB28/B28,"") | AE28: =IFERROR(AC28/B28,"") | AF28: Part | AG28: No | AH28: No | AI28: 2026-05-22 | AJ28: W13159224 | AK28: https://condos.ca/toronto/the-humber-10-wilby-crescent-10-wilby-cres/unit-1407-W13159224 | AL28: ACTIVE asking rent (not a closed lease). SF verified. | AM28: Condo | AN28: =IFERROR(E28*(1+IF(AM28="Apartment",Data_Summary!$C$3,0)),"") | AP28: Verified registered area | AQ28: condos.ca registered area | AS28: condos.ca per-unit registered area; used in $/SF. (template row)
A29: =IF(AND(ISNUMBER(B29),B29>0,ISNUMBER(AB29),AB29>0,J29>=Data_Summary!$C$1),1,0) | B29: 715 | C29: =IF(ISNUMBER(AB29),AB29,"") | D29: =IF(ISNUMBER(C29),C29-U29*Data_Summary!$C$2,"") | E29: =IFERROR(C29/B29,"") | F29: =IFERROR(D29/B29,"") | G29: =Q29 | H29: =IFERROR(LEFT(G29,1),"") | I29: =IF(LEN(G29)>1,1,0) | J29: 46084 | K29: The Humber | L29: 10 Wilby Crescent | M29: Toronto (Weston) | N29: Options for Homes | O29: 1907 | P29: 1907 - 10 Wilby Crescent | Q29: 2 | R29: 2 | S29: 715 | T29: 700-799 sqft | U29: 1 | V29: Yes | W29: None | X29: Balcony, Patio | Y29: N | Z29: Built 2023 (3 yrs) | AA29: Gym, Party Room, Rooftop Deck, Visitor Parking, BBQ, Bike Storage, Concierge, Coin Laundry | AC29: 2500 | AD29: =IFERROR(AB29/B29,"") | AE29: =IFERROR(AC29/B29,"") | AF29: No | AG29: No | AH29: No | AI29: 2026-03-03 | AJ29: W12841668 | AK29: https://condos.ca/toronto/the-humber-10-wilby-crescent-10-wilby-cres/unit-1907-W12841668 | AL29: ACTIVE asking rent (not a closed lease). SF verified. | AM29: Condo | AN29: =IFERROR(E29*(1+IF(AM29="Apartment",Data_Summary!$C$3,0)),"") | AP29: Verified registered area | AQ29: condos.ca registered area | AS29: condos.ca per-unit registered area; used in $/SF. (template row)
A30: =IF(AND(ISNUMBER(B30),B30>0,ISNUMBER(AB30),AB30>0,J30>=Data_Summary!$C$1),1,0) | C30: =IF(ISNUMBER(AB30),AB30,"") | D30: =IF(ISNUMBER(C30),C30-U30*Data_Summary!$C$2,"") | E30: =IFERROR(C30/B30,"") | F30: =IFERROR(D30/B30,"") | G30: =Q30 | H30: =IFERROR(LEFT(G30,1),"") | I30: =IF(LEN(G30)>1,1,0) | J30: 46118 | K30: The Humber | L30: 10 Wilby Crescent | M30: Toronto (Weston) | N30: Options for Homes | O30: 1801-P | P30: 1801-P - 10 Wilby Crescent | Q30: 1 | R30: 1 | U30: 0 | V30: No | W30: None | X30: Balcony, Patio | Z30: Built 2023 (3 yrs) | AA30: Gym, Party Room, Rooftop Deck, Visitor Parking, BBQ, Bike Storage, Concierge, Coin Laundry | AB30: 1560 | AC30: 1480 | AD30: =IFERROR(AB30/B30,"") | AE30: =IFERROR(AC30/B30,"") | AF30: No | AG30: No | AH30: No | AI30: 2026-04-06 | AJ30: W12905894 | AK30: https://condos.ca/toronto/the-humber-10-wilby-crescent-10-wilby-cres/unit-1801-P-W12905894 | AL30: Room rental of unit 1801 (P/S) - excluded from PSF. | AM30: Condo | AN30: =IFERROR(E30*(1+IF(AM30="Apartment",Data_Summary!$C$3,0)),"") | AP30: Unresolved | AQ30: none | AS30: No exact verified SF → Include=0, excluded from $/SF. (template row)
A31: =IF(AND(ISNUMBER(B31),B31>0,ISNUMBER(AB31),AB31>0,J31>=Data_Summary!$C$1),1,0) | C31: =IF(ISNUMBER(AB31),AB31,"") | D31: =IF(ISNUMBER(C31),C31-U31*Data_Summary!$C$2,"") | E31: =IFERROR(C31/B31,"") | F31: =IFERROR(D31/B31,"") | G31: =Q31 | H31: =IFERROR(LEFT(G31,1),"") | I31: =IF(LEN(G31)>1,1,0) | J31: 45860 | K31: The Humber | L31: 10 Wilby Crescent | M31: Toronto (Weston) | N31: Options for Homes | O31: 1801-S | P31: 1801-S - 10 Wilby Crescent | Q31: 1 | R31: 1 | U31: 0 | V31: No | W31: None | X31: Balcony, Patio | Z31: Built 2023 (3 yrs) | AA31: Gym, Party Room, Rooftop Deck, Visitor Parking, BBQ, Bike Storage, Concierge, Coin Laundry | AB31: 1280 | AC31: 1280 | AD31: =IFERROR(AB31/B31,"") | AE31: =IFERROR(AC31/B31,"") | AF31: No | AG31: No | AH31: No | AI31: 2025-07-22 | AJ31: W11968666 | AK31: https://condos.ca/toronto/the-humber-10-wilby-crescent-10-wilby-cres/unit-1801-S-W11968666 | AL31: Room rental of unit 1801 (P/S) - excluded from PSF. | AM31: Condo | AN31: =IFERROR(E31*(1+IF(AM31="Apartment",Data_Summary!$C$3,0)),"") | AP31: Unresolved | AQ31: none | AS31: No exact verified SF → Include=0, excluded from $/SF. (template row)

Sheet RD Apartments
A1: Include | B1: Sq Ft. | C1: Rent | D1: Adj. Rent | E1: $/sq ft | F1: Adj. $/sq ft | G1: Adj BD | H1: Beds Number | I1: Den | J1: Date | K1: Building Name | L1: Building Address | M1: Building City | N1: Developer | O1: Unit # | P1: Unit Address | Q1: Beds | R1: Baths | S1: Sqft (Condos.ca) | T1: MLS Size Range | U1: # Parking | V1: Parking Included | W1: Locker | X1: Outdoor Space | Y1: Exposure | Z1: Building Age | AA1: Building Amenities | AB1: Leased Rent ($) | AC1: Listed Rent ($) | AD1: PSF (Calculated) | AE1: PSF (Listing) | AF1: Furnished | AG1: Hydro Included | AH1: Water Included | AI1: Lease Date | AJ1: MLS# | AK1: Listing URL | AL1: Description | AM1: Product Type | AN1: $/SF (Product-Adj) | AO1: Date Scraped | AP1: SF Verification Status | AQ1: SF Source Type | AR1: SF Source / URL | AS1: SF Explanation / Not Validated Reason
A2: =IF(AND(ISNUMBER(B2),B2>0,ISNUMBER(AB2),AB2>0,J2>=Data_Summary!$C$1),1,0) | B2: 694 | C2: =IF(ISNUMBER(AB2),AB2,"") | D2: =IF(ISNUMBER(C2),C2-U2*Data_Summary!$C$2,"") | E2: =IFERROR(C2/B2,"") | F2: =IFERROR(D2/B2,"") | G2: =Q2 | H2: =IFERROR(LEFT(G2,1),"") | I2: =IF(LEN(G2)>1,1,0) | J2: 46136 | K2: The Humber | L2: 10 Wilby Crescent | M2: Toronto (Weston) | N2: Options for Homes | O2: 1602 | P2: 1602 - 10 Wilby Crescent | Q2: 2 | R2: 2 | S2: 694 | T2: 600-699 sqft | U2: 1 | V2: Yes | W2: Ensuite | X2: Balcony, Patio | Y2: W | Z2: Built 2023 (3 yrs) | AA2: Gym, Party Room, Rooftop Deck, Visitor Parking, BBQ, Bike Storage, Concierge, Coin Laundry | AB2: 2450 | AC2: 2450 | AD2: =IFERROR(AB2/B2,"") | AE2: =IFERROR(AC2/B2,"") | AF2: No | AG2: No | AH2: No | AI2: 2026-04-24 | AJ2: W12626670 | AK2: https://condos.ca/toronto/the-humber-10-wilby-crescent-10-wilby-cres/unit-1602-W12626670 | AL2: Leased comp. SF: Verified (condos.ca per-unit). | AM2: Condo | AN2: =IFERROR(E2*(1+IF(AM2="Apartment",Data_Summary!$C$3,0)),"")

Sheet Floor Plans
A1: Building Name | B1: Building Address | C1: Building City | D1: Subject/Comp | E1: Source Site | F1: Source URL | G1: Date Read | H1: Suite / Plan Name | I1: Beds | J1: Baths | K1: Interior SF | L1: Exposure | M1: Floor Band | N1: Stack / Line | O1: Balcony/Terrace | P1: Notes | Q1: Used For Unit(s) | R1: Verification Tier
A2: The Humber | B2: 10 Wilby Crescent | C2: Toronto (Weston) | D2: comp | E2: vipcondostoronto.net | F2: searched on-page (never guessed) — building plan page | H2: 1B | I2: 1 | J2: 1 | K2: 556 | L2: NW | R2: plate-verified
A3: The Humber | B3: 10 Wilby Crescent | C3: Toronto (Weston) | D3: comp | E3: vipcondostoronto.net | F3: searched on-page (never guessed) — building plan page | H3: 1A | I3: 1 | J3: 1 | K3: 617 | L3: E | R3: plate-verified
A4: The Humber | B4: 10 Wilby Crescent | C4: Toronto (Weston) | D4: comp | E4: vipcondostoronto.net | F4: searched on-page (never guessed) — building plan page | H4: 1D-583 | I4: 1 | J4: 1 | K4: 583 | L4: S | R4: plate-verified
A5: The Humber | B5: 10 Wilby Crescent | C5: Toronto (Weston) | D5: comp | E5: vipcondostoronto.net | F5: searched on-page (never guessed) — building plan page | H5: 1D-588 | I5: 1 | J5: 1 | K5: 588 | L5: SW | R5: plate-verified
A6: The Humber | B6: 10 Wilby Crescent | C6: Toronto (Weston) | D6: comp | E6: vipcondostoronto.net | F6: searched on-page (never guessed) — building plan page | H6: 1D-663 | I6: 1 | J6: 1 | K6: 663 | L6: NE | R6: plate-verified
A7: The Humber | B7: 10 Wilby Crescent | C7: Toronto (Weston) | D7: comp | E7: vipcondostoronto.net | F7: searched on-page (never guessed) — building plan page | H7: 1D-694 | I7: 1 | J7: 1 | K7: 694 | L7: S | R7: plate-verified
A8: The Humber | B8: 10 Wilby Crescent | C8: Toronto (Weston) | D8: comp | E8: vipcondostoronto.net | F8: searched on-page (never guessed) — building plan page | H8: 1DX-751 | I8: 1 | J8: 2 | K8: 751 | L8: NE | R8: plate-verified
A9: The Humber | B9: 10 Wilby Crescent | C9: Toronto (Weston) | D9: comp | E9: vipcondostoronto.net | F9: searched on-page (never guessed) — building plan page | H9: 2A-694 | I9: 2 | J9: 2 | K9: 694 | L9: S/W/NE | R9: plate-verified
A10: The Humber | B10: 10 Wilby Crescent | C10: Toronto (Weston) | D10: comp | E10: vipcondostoronto.net | F10: searched on-page (never guessed) — building plan page | H10: 2B-715 | I10: 2 | J10: 2 | K10: 715 | L10: N/NE | R10: plate-verified
A11: The Humber | B11: 10 Wilby Crescent | C11: Toronto (Weston) | D11: comp | E11: vipcondostoronto.net | F11: searched on-page (never guessed) — building plan page | H11: 2C-788 | I11: 2 | J11: 2 | K11: 788 | L11: NE | R11: plate-verified
A12: The Humber | B12: 10 Wilby Crescent | C12: Toronto (Weston) | D12: comp | E12: vipcondostoronto.net | F12: searched on-page (never guessed) — building plan page | H12: 2D-797 | I12: 2 | J12: 2 | K12: 797 | L12: NE | R12: plate-verified
A13: The Humber | B13: 10 Wilby Crescent | C13: Toronto (Weston) | D13: comp | E13: vipcondostoronto.net | F13: searched on-page (never guessed) — building plan page | H13: 2E-816 | I13: 2 | J13: 2 | K13: 816 | L13: E | R13: plate-verified
A14: The Humber | B14: 10 Wilby Crescent | C14: Toronto (Weston) | D14: comp | E14: vipcondostoronto.net | F14: searched on-page (never guessed) — building plan page | H14: 3A-988 | I14: 3 | J14: 2 | K14: 988 | L14: SW | R14: plate-verified
A15: NOTE — log every VIPcondos plan opened during a session here, one row per distinct plan (subject plans tagged '(SUBJECT)' in Building Name). If only condos.ca registered areas were used and no VIPcondos plans were opened, do not invent plan rows.
